Workbook

Sheet Board & Executives
A1: Company | B1: Board | C1: Exec | D1: Employer | E1: Fname | F1: MI | G1: Lname | H1: Gender | I1: State | J1: Age | K1: DOB | L1: Dem | M1: Rep | N1: Neu | O1: Reg | P1: Address
A2: BankofAmerica | B2: Y | C2: Y | D2: BOA CHAIRMAN & CEO | E2: Brian | F2: T. | G2: Moynihan | H2: M | I2: NC | J2: 61 | N2: =+'Brian Moynihan'!AJ2 -> 5000 | P2: 100 N TRYON ST CHARLOTTE NC 28255 | Q2: =+E2&F2&G2 -> Brian T. Moynihan
A3: BankofAmerica | B3: Y | C3: N | D3: LEAD INDEPENDENT DIRECTOR, former COO HCA, BOD Duke U, | E3: Jack | F3: O. | G3: Bovender, Jr. | H3: M | I3: TN | J3: 75 | M3: =+GETPIVOTDATA("contribution_receipt_amount",'Jack O. Bovender'!$A$14) -> 139900 | P3: 620 BELLE MEADE BLVD NASHVILLE TN 372053878 | Q3: =+E3&F3&G3 -> Jack O. Bovender, Jr.
A4: BankofAmerica | B4: Y | C4: N | D4: LEAD INDEPENDENT DIRECTOR SUCCESSOR, former Treasurer Pepsico, CFO & Controller | E4: Lionel | F4: L. | G4: Nowell III | H4: M | J4: 66 | Q4: =+E4&F4&G4 -> Lionel L. Nowell III | R4: No FEC Data
A5: BankofAmerica | B5: Y | C5: N | D5: Director, former chairman of Deloitte, former directory Albertsons | E5: Sharon | F5: L. | G5: Allen | H5: F | J5: 69 | K5: 18908 | Q5: =+E5&F5&G5 -> Sharon L. Allen | R5: No FEC Data
A6: BankofAmerica | B6: Y | C6: N | D6: Director,Former Member, Federal Reserve Board of Governors | E6: Susan | F6: S. | G6: Bies | H6: F | J6: 73 | K6: 17292 | Q6: =+E6&F6&G6 -> Susan S. Bies | R6: No FEC Data
A7: BankofAmerica | B7: Y | C7: N | D7: Director,Former Executive Vice Chairman, MBNA Corporation | E7: Frank | F7: P. | G7: Bramble, Sr. | H7: M | J7: 72 | Q7: =+E7&F7&G7 -> Frank P. Bramble, Sr. | R7: No FEC Data
A8: BankofAmerica | B8: Y | C8: N | D8: Director, Former Chairman and Global Head of Private Wealth Management, Deutsche Bank | E8: Pierre | F8: J.P. | G8: de Weck | H8: M | J8: 70 | Q8: =+E8&F8&G8 -> Pierre J.P. de Weck | R8: No FEC Data
A9: BankofAmerica | B9: Y | C9: N | D9: Director,President and Chief Executive Officer, Carnival | E9: Arnold | F9: W. | G9: Donald | H9: M | I9: MO | J9: 66 | K9: 1954 | P9: St Louis MO | Q9: =+E9&F9&G9 -> Arnold W. Donald | R9: No FEC Data
A10: BankofAmerica | B10: Y | C10: N | D10: Director,Former Chairman and Chief Executive Officer, The Cardea Group, LLC; Former President and Chief Executive Officer, BAE | E10: Linda | F10: P. | G10: Hudson | H10: F | I10: NC | J10: 70 | K10: 18497 | L10: =+'Linda Hudson'!AJ5 -> 2500 | P10: 15611 BALLANTYNE COUNTRY CLUB DR CHARLOTTE NC 282771406 | Q10: =+E10&F10&G10 -> Linda P. Hudson
A11: BankofAmerica | B11: Y | C11: N | D11: Director, Chief Executive Officer, College Futures Foundation; Former Chairman, US Hispanic Media Inc. | E11: Monica | F11: C. | G11: Lozano | H11: F | J11: 65 | K11: 20657 | L11: =+GETPIVOTDATA("contribution_receipt_amount",'Monica Lozano'!$A$39) -> 105036.66 | P11: 5610 GOLDEN GATE AVENUE OAKLAND CA 94618 | Q11: =+E11&F11&G11 -> Monica C. Lozano
A12: BankofAmerica | B12: Y | C12: N | D12: Director,Former Chairman, President, and Chief Executive Officer, Eversource Energy | E12: Thomas | F12: J. | G12: May | H12: M | J12: 74 | Q12: =+E12&F12&G12 -> Thomas J. May | R12: No FEC Data
A13: BankofAmerica | B13: Y | C13: N | D13: Director, Former Chief Executive Officer and President, ITT Inc. | E13: Denise | F13: L. | G13: Ramos | H13: F | J13: 64 | Q13: =+E13&F13&G13 -> Denise L. Ramos | R13: No FEC Data
A14: BankofAmerica | B14: Y | C14: N | D14: Director, President, Bowdoin College | E14: Clayton | F14: S. | G14: Rose | H14: M | I14: MA | J14: 62 | L14: =+GETPIVOTDATA("contribution_receipt_amount",'Clayton Rose'!$A$18) -> 174766.64 | O14: D | P14: 100 FEDERAL STREET BOSTON MA 21101802 | Q14: =+E14&F14&G14 -> Clayton S. Rose
A15: BankofAmerica | B15: Y | C15: N | D15: Director, Former Chairman, President, and Chief Executive Officer, DIRECTV; Lead Director, Kimberly-Clark Corporation | E15: Michael | F15: D. | G15: White | H15: M | J15: 69 | Q15: =+E15&F15&G15 -> Michael D. White | R15: No FEC Data
A16: BankofAmerica | B16: Y | C16: N | D16: Director, Former Vice Chairman and Senior Executive Vice President of CIBC; Former Chairman, Hydro One Limited | E16: Thomas | F16: D. | G16: Woods | H16: M | J16: 68 | Q16: =+E16&F16&G16 -> Thomas D. Woods | R16: No FEC Data
A17: BankofAmerica | B17: Y | C17: N | D17: Director, Former Chief Executive Officer, AmerisourceBergen | E17: R. | F17: David | G17: Yost | H17: M | J17: 73 | M17: =+'R David Yost'!AJ5 -> 2000 | P17: 502 GLENVIEW ROAD BRYN MAWR PA19010 | Q17: =+E17&F17&G17 -> R. David Yost
A18: BankofAmerica | B18: Y | C18: N | D18: Director, Vice President for Research and E. A. Griswold Professor of Geophysics, MIT | E18: Maria | F18: T. | G18: Zuber | H18: F | J18: 62 | K18: 21363 | Q18: =+E18&F18&G18 -> Maria T. Zuber | R18: No FEC Data
A19: BankofAmerica | B19: N | C19: Y | D19: President of Business Banking | E19: Raul | F19: A. | G19: Anaya | H19: M | I19: LA CA | Q19: =+E19&F19&G19 -> Raul A. Anaya | R19: No FEC Data
A20: BankofAmerica | B20: N | C20: Y | D20: Chief Operations and Technology Officer | E20: Catherine | F20: P. | G20: Bessant | H20: F | I20: Charlotte NC | N20: =+GETPIVOTDATA("contribution_receipt_amount",'Catherine Bessant'!$A$52) -> 5060 | P20: 100 N TRYON ST CHARLOTTE NC 28255 | Q20: =+E20&F20&G20 -> Catherine P. Bessant
A21: BankofAmerica | B21: N | C21: Y | D21: Chief Human Resources Officer | E21: Sheri | F21: B | G21: Bronstein | H21: F | I21: NY | N21: =+GETPIVOTDATA("contribution_receipt_amount",'Sheri Bronstein'!$A$46,"committee_name","BANK OF AMERICA CORPORATION FEDERAL PAC") -> 2000 | P21: ONE BRYANT PARK NEW YORK NY 10036 | Q21: Sheri B Bronstein | T21: Sheri B Bronstein
A22: BankofAmerica | B22: N | C22: Y | D22: Chief Financial Officer | E22: Paul | G22: Donofrio | H22: M | I22: NY | N22: =+GETPIVOTDATA("contribution_receipt_amount",'Paul Donofrio'!$A$34) -> 560 | P22: ONE BRYANT PARK NEW YORK NY 10037 | Q22: =+E22&F22&G22 -> Paul Donofrio
A23: BankofAmerica | B23: N | C23: Y | D23: Chief Operating Officer | E23: Thomas | F23: K. | G23: Montag | H23: M | M23: =+GETPIVOTDATA("contribution_receipt_amount",'Thomas Montag'!$A$91) -> 1147497.6 | P23: 127 E 73RD ST NEW YORK NY 100213502 | Q23: =+E23&F23&G23 -> Thomas K. Montag
A24: BankofAmerica | B24: N | C24: Y | D24: Chief Administrative Officer | E24: Andrea | F24: B. | G24: Smith | H24: F | N24: =+GETPIVOTDATA("contribution_receipt_amount",'Andrea Smith'!$A$51,"committee_name","BANK OF AMERICA CORPORATION FEDERAL PAC") -> 9357.88 | P24: 100 N TRYON ST CHARLOTTE NC 28255 | Q24: =+E24&F24&G24 -> Andrea B. Smith
A25: BankofAmerica | B25: N | C25: Y | D25: President, Merrill Lynch Wealth Management | E25: Andy | G25: Sieg | H25: M | I25: Greenwich Conn | Q25: =+E25&F25&G25 -> Andy Sieg | R25: No FEC Data
N29: Note: | P29: Many of the Board and Executives did not appear in the Aristotle DB

Sheet Andrea Smith
A1: committee_id | B1: committee_name | C1: report_year | D1: report_type | E1: image_number | F1: line_number | G1: transaction_id | H1: file_number | I1: committee_name | J1: entity_type | K1: entity_type_desc | L1: unused_contbr_id | M1: contributor_prefix | N1: contributor_name | O1: recipient_committee_type | P1: recipient_committee_org_type | Q1: recipient_committee_designation | R1: contributor_first_name | S1: contributor_middle_name | T1: contributor_last_name | U1: contributor_suffix | V1: contributor_street_1 | W1: contributor_street_2 | X1: contributor_city | Y1: contributor_state | Z1: contributor_zip | AA1: contributor_employer | AB1: contributor_occupation | AC1: contributor_id | AD1: receipt_type | AE1: receipt_type_desc | AF1: receipt_type_full | AG1: memo_code | AH1: memo_code_full | AI1: contribution_receipt_date | AJ1: contribution_receipt_amount | AK1: contributor_aggregate_ytd | AL1: candidate_id | AM1: candidate_name | AN1: candidate_first_name | AO1: candidate_last_name | AP1: candidate_middle_name | AQ1: candidate_prefix | AR1: candidate_suffix | AS1: candidate_office | AT1: candidate_office_full | AU1: candidate_office_state | AV1: candidate_office_state_full | AW1: candidate_office_district | AX1: conduit_committee_id | AY1: conduit_committee_name | AZ1: conduit_committee_street1 | BA1: conduit_committee_street2 | BB1: conduit_committee_city | BC1: conduit_committee_state | BD1: conduit_committee_zip | BE1: donor_committee_name | BF1: national_committee_nonfederal_account | BG1: election_type | BH1: election_type_full | BI1: fec_election_type_desc | BJ1: fec_election_year | BK1: amendment_indicator | BL1: amendment_indicator_desc | BM1: schedule_type_full | BN1: load_date | BO1: original_sub_id | BP1: back_reference_transaction_id | BQ1: back_reference_schedule_name | BR1: filing_form | BS1: link_id | BT1: is_individual | BU1: memo_text | BV1: two_year_transaction_period | BW1: schedule_type | BX1: increased_limit | BY1: sub_id | BZ1: pdf_url | CA1: line_number_label
A2: C00364778 | B2: BANK OF AMERICA CORPORATION FEDERAL PAC | C2: 2019 | D2: M4 | E2: 2.0190413e+17 | F2: 11AI | G2: A2019-517160 | H2: 1324297 | J2: IND | K2: INDIVIDUAL | N2: SMITH, ANDREA B | O2: Q | P2: C | Q2: B | R2: ANDREA | S2: B | T2: SMITH | V2: 100 N TRYON ST | X2: CHARLOTTE | Y2: NC | Z2: 28255 | AA2: BANK OF AMERICA | AB2: CHIEF ADMINISTRATIVE OFFICER | AD2: 15 | AE2: CONTRIBUTION | AI2: 43539 | AJ2: 175 | AK2: 875 | BG2: P | BI2: PRIMARY | BK2: A | BL2: ADD | BM2: ITEMIZED RECEIPTS | BN2: 43568.111 | BR2: F3X | BS2: 4.0412202e+18 | BT2: t | BV2: 2020 | BW2: SA | BY2: 4.0412202e+18 | BZ2: http://docquery.fec.gov/cgi-bin/fecimg/?201904129146103886 | CA2: Contributions From Individuals/Persons Other Than Political Committees
A3: C00364778 | B3: BANK OF AMERICA CORPORATION FEDERAL PAC | C3: 2019 | D3: M3 | E3: 2.0190316e+17 | F3: 11AI | G3: A2019-298508 | H3: 1319532 | J3: IND | K3: INDIVIDUAL | N3: SMITH, ANDREA B | O3: Q | P3: C | Q3: B | R3: ANDREA | S3: B | T3: SMITH | V3: 100 N TRYON ST | X3: CHARLOTTE | Y3: NC | Z3: 28255 | AA3: BANK OF AMERICA | AB3: CHIEF ADMINISTRATIVE OFFICER | AD3: 15 | AE3: CONTRIBUTION | AI3: 43511 | AJ3: 175 | AK3: 525 | BG3: P | BI3: PRIMARY | BK3: A | BL3: ADD | BM3: ITEMIZED RECEIPTS | BN3: 43543.128 | BR3: F3X | BS3: 4.0315202e+18 | BT3: t | BV3: 2020 | BW3: SA | BY3: 4.0318202e+18 | BZ3: http://docquery.fec.gov/cgi-bin/fecimg/?201903159145712554 | CA3: Contributions From Individuals/Persons Other Than Political Committees
A4: C00364778 | B4: BANK OF AMERICA CORPORATION FEDERAL PAC | C4: 2019 | D4: M2 | E4: 2.0190216e+17 | F4: 11AI | G4: A2019-82224 | H4: 1316134 | J4: IND | K4: INDIVIDUAL | N4: SMITH, ANDREA B | O4: Q | P4: C | Q4: B | R4: ANDREA | S4: B | T4: SMITH | V4: 100 N TRYON ST | X4: CHARLOTTE | Y4: NC | Z4: 28255 | AA4: BANK OF AMERICA | AB4: CHIEF ADMINISTRATIVE OFFICER | AD4: 15 | AE4: CONTRIBUTION | AI4: 43496 | AJ4: 175 | AK4: 350 | BG4: P | BI4: PRIMARY | BK4: A | BL4: ADD | BM4: ITEMIZED RECEIPTS | BN4: 43525.144 | BR4: F3X | BS4: 4.0215202e+18 | BT4: t | BV4: 2020 | BW4: SA | BY4: 4.0228202e+18 | BZ4: http://docquery.fec.gov/cgi-bin/fecimg/?201902159145519680 | CA4: Contributions From Individuals/Persons Other Than Political Committees
A5: C00364778 | B5: BANK OF AMERICA CORPORATION FEDERAL PAC | C5: 2019 | D5: M3 | E5: 2.0190316e+17 | F5: 11AI | G5: A2019-339759 | H5: 1319532 | J5: IND | K5: INDIVIDUAL | N5: SMITH, ANDREA B | O5: Q | P5: C | Q5: B | R5: ANDREA | S5: B | T5: SMITH | V5: 100 N TRYON ST | X5: CHARLOTTE | Y5: NC | Z5: 28255 | AA5: BANK OF AMERICA | AB5: CHIEF ADMINISTRATIVE OFFICER | AD5: 15 | AE5: CONTRIBUTION | AI5: 43524 | AJ5: 175 | AK5: 700 | BG5: P | BI5: PRIMARY | BK5: A | BL5: ADD | BM5: ITEMIZED RECEIPTS | BN5: 43543.128 | BR5: F3X | BS5: 4.0315202e+18 | BT5: t | BV5: 2020 | BW5: SA | BY5: 4.0318202e+18 | BZ5: http://docquery.fec.gov/cgi-bin/fecimg/?201903159145712554 | CA5: Contributions From Individuals/Persons Other Than Political Committees
A6: C00364778 | B6: BANK OF AMERICA CORPORATION FEDERAL PAC | C6: 2019 | D6: M4 | E6: 2.0190413e+17 | F6: 11AI | G6: A2019-547990 | H6: 1324297 | J6: IND | K6: INDIVIDUAL | N6: SMITH, ANDREA B | O6: Q | P6: C | Q6: B | R6: ANDREA | S6: B | T6: SMITH | V6: 100 N TRYON ST | X6: CHARLOTTE | Y6: NC | Z6: 28255 | AA6: BANK OF AMERICA | AB6: CHIEF ADMINISTRATIVE OFFICER | AD6: 15 | AE6: CONTRIBUTION | AI6: 43555 | AJ6: 175 | AK6: 1050 | BG6: P | BI6: PRIMARY | BK6: A | BL6: ADD | BM6: ITEMIZED RECEIPTS | BN6: 43568.111 | BR6: F3X | BS6: 4.0412202e+18 | BT6: t | BV6: 2020 | BW6: SA | BY6: 4.0412202e+18 | BZ6: http://docquery.fec.gov/cgi-bin/fecimg/?201904129146103887 | CA6: Contributions From Individuals/Persons Other Than Political Committees
A7: C00364778 | B7: BANK OF AMERICA CORPORATION FEDERAL PAC | C7: 2019 | D7: M5 | E7: 2.0190515e+17 | F7: 11AI | G7: A2019-792099 | H7: 1330608 | J7: IND | K7: INDIVIDUAL | N7: SMITH, ANDREA B | O7: Q | P7: C | Q7: B | R7: ANDREA | S7: B | T7: SMITH | V7: 100 N TRYON ST | X7: CHARLOTTE | Y7: NC | Z7: 28255 | AA7: BANK OF AMERICA | AB7: CHIEF ADMINISTRATIVE OFFICER | AD7: 15 | AE7: CONTRIBUTION | AI7: 43570 | AJ7: 175 | AK7: 1225 | BG7: P | BI7: PRIMARY | BK7: A | BL7: ADD | BM7: ITEMIZED RECEIPTS | BN7: 43600.358 | BR7: F3X | BS7: 4.0514202e+18 | BT7: t | BV7: 2020 | BW7: SA | BY7: 4.0514202e+18 | BZ7: http://docquery.fec.gov/cgi-bin/fecimg/?201905149149695965 | CA7: Contributions From Individuals/Persons Other Than Political Committees
A8: C00364778 | B8: BANK OF AMERICA CORPORATION FEDERAL PAC | C8: 2019 | D8: M5 | E8: 2.0190515e+17 | F8: 11AI | G8: A2019-844091 | H8: 1330608 | J8: IND | K8: INDIVIDUAL | N8: SMITH, ANDREA B | O8: Q | P8: C | Q8: B | R8: ANDREA | S8: B | T8: SMITH | V8: 100 N TRYON ST | X8: CHARLOTTE | Y8: NC | Z8: 28255 | AA8: BANK OF AMERICA | AB8: CHIEF ADMINISTRATIVE OFFICER | AD8: 15 | AE8: CONTRIBUTION | AI8: 43585 | AJ8: 175 | AK8: 1400 | BG8: P | BI8: PRIMARY | BK8: A | BL8: ADD | BM8: ITEMIZED RECEIPTS | BN8: 43600.358 | BR8: F3X | BS8: 4.0514202e+18 | BT8: t | BV8: 2020 | BW8: SA | BY8: 4.0514202e+18 | BZ8: http://docquery.fec.gov/cgi-bin/fecimg/?201905149149695965 | CA8: Contributions From Individuals/Persons Other Than Political Committees
A9: C00364778 | B9: BANK OF AMERICA CORPORATION FEDERAL PAC | C9: 2019 | D9: YE | E9: 2.0200121e+17 | F9: 11AI | G9: A2019-2944190 | H9: 1371432 | J9: IND | K9: INDIVIDUAL | N9: SMITH, ANDREA B | O9: Q | P9: C | Q9: B | R9: ANDREA | S9: B | T9: SMITH | V9: 100 N TRYON ST | X9: CHARLOTTE | Y9: NC | Z9: 28255 | AA9: BANK OF AMERICA | AB9: CHIEF ADMINISTRATIVE OFFICER | AD9: 15 | AE9: CONTRIBUTION | AI9: 43814 | AJ9: 208.32 | AK9: 4324.88 | BG9: P | BI9: PRIMARY | BK9: A | BL9: ADD | BM9: ITEMIZED RECEIPTS | BN9: 43852.068 | BR9: F3X | BS9: 4.0120202e+18 | BT9: t | BV9: 2020 | BW9: SA | BY9: 4.0121202e+18 | BZ9: http://docquery.fec.gov/cgi-bin/fecimg/?202001209167275401 | CA9: Contributions From Individuals/Persons Other Than Political Committees
A10: C00364778 | B10: BANK OF AMERICA CORPORATION FEDERAL PAC | C10: 2019 | D10: M8 | E10: 2.0190817e+17 | F10: 11AI | G10: A2019-1511501 | H10: 1348081 | J10: IND | K10: INDIVIDUAL | N10: SMITH, ANDREA B | O10: Q | P10: C | Q10: B | R10: ANDREA | S10: B | T10: SMITH | V10: 100 N TRYON ST | X10: CHARLOTTE | Y10: NC | Z10: 28255 | AA10: BANK OF AMERICA | AB10: CHIEF ADMINISTRATIVE OFFICER | AD10: 15 | AE10: CONTRIBUTION | AI10: 43661 | AJ10: 175 | AK10: 2275 | BG10: P | BI10: PRIMARY | BK10: A | BL10: ADD | BM10: ITEMIZED RECEIPTS | BN10: 43694.11 | BR10: F3X | BS10: 4.0816202e+18 | BT10: t | BV10: 2020 | BW10: SA | BY10: 4.0816202e+18 | BZ10: http://docquery.fec.gov/cgi-bin/fecimg/?201908169162884688 | CA10: Contributions From Individuals/Persons Other Than Political Committees
A11: C00364778 | B11: BANK OF AMERICA CORPORATION FEDERAL PAC | C11: 2019 | D11: M8 | E11: 2.0190817e+17 | F11: 11AI | G11: A2019-1688431 | H11: 1348081 | J11: IND | K11: INDIVIDUAL | N11: SMITH, ANDREA B | O11: Q | P11: C | Q11: B | R11: ANDREA | S11: B | T11: SMITH | V11: 100 N TRYON ST | X11: CHARLOTTE | Y11: NC | Z11: 28255 | AA11: BANK OF AMERICA | AB11: CHIEF ADMINISTRATIVE OFFICER | AD11: 15 | AE11: CONTRIBUTION | AI11: 43677 | AJ11: 175 | AK11: 2450 | BG11: P | BI11: PRIMARY | BK11: A | BL11: ADD | BM11: ITEMIZED RECEIPTS | BN11: 43694.11 | BR11: F3X | BS11: 4.0816202e+18 | BT11: t | BV11: 2020 | BW11: SA | BY11: 4.0816202e+18 | BZ11: http://docquery.fec.gov/cgi-bin/fecimg/?201908169162884688 | CA11: Contributions From Individuals/Persons Other Than Political Committees
A12: C00364778 | B12: BANK OF AMERICA CORPORATION FEDERAL PAC | C12: 2019 | D12: YE | E12: 2.0200121e+17 | F12: 11AI | G12: A2019-2985172 | H12: 1371432 | J12: IND | K12: INDIVIDUAL | N12: SMITH, ANDREA B | O12: Q | P12: C | Q12: B | R12: ANDREA | S12: B | T12: SMITH | V12: 100 N TRYON ST | X12: CHARLOTTE | Y12: NC | Z12: 28255 | AA12: BANK OF AMERICA | AB12: CHIEF ADMINISTRATIVE OFFICER | AD12: 15 | AE12: CONTRIBUTION | AI12: 43830 | AJ12: 208.32 | AK12: 4533.2 | BG12: P | BI12: PRIMARY | BK12: A | BL12: ADD | BM12: ITEMIZED RECEIPTS | BN12: 43852.068 | BR12: F3X | BS12: 4.0120202e+18 | BT12: t | BV12: 2020 | BW12: SA | BY12: 4.0121202e+18 | BZ12: http://docquery.fec.gov/cgi-bin/fecimg/?202001209167275401 | CA12: Contributions From Individuals/Persons Other Than Political Committees
A13: C00364778 | B13: BANK OF AMERICA CORPORATION FEDERAL PAC | C13: 2019 | D13: M7 | E13: 2.0190803e+17 | F13: 11AI | G13: A2019-1195547 | H13: 1346685 | J13: IND | K13: INDIVIDUAL | N13: SMITH, ANDREA B | O13: Q | P13: C | Q13: B | R13: ANDREA | S13: B | T13: SMITH | V13: 100 N TRYON ST | X13: CHARLOTTE | Y13: NC | Z13: 28255 | AA13: BANK OF AMERICA | AB13: CHIEF ADMINISTRATIVE OFFICER | AD13: 15 | AE13: CONTRIBUTION | AI13: 43631 | AJ13: 175 | AK13: 1925 | BG13: P | BI13: PRIMARY | BK13: N | BL13: NO CHANGE | BM13: ITEMIZED RECEIPTS | BN13: 43680.113 | BR13: F3X | BS13: 4.0802202e+18 | BT13: t | BV13: 2020 | BW13: SA | BY13: 4.0802202e+18 | BZ13: http://docquery.fec.gov/cgi-bin/fecimg/?201908029161351312 | CA13: Contributions From Individuals/Persons Other Than Political Committees
... A48: C00364778 | B48: BANK OF AMERICA CORPORATION FEDERAL PAC | C48: 2020 | D48: YE | E48: 2.0210126e+17 | F48: 11AI | G48: A2020-2739131 | H48: 1490358 | J48: IND | K48: INDIVIDUAL | N48: SMITH, ANDREA B | O48: Q | P48: C | Q48: B | R48: ANDREA | S48: B | T48: SMITH | V48: 100 N TRYON ST | X48: CHARLOTTE | Y48: NC | Z48: 28255 | AA48: BANK OF AMERICA | AB48: CHIEF ADMINISTRATIVE OFFICER | AD48: 15 | AE48: CONTRIBUTION | AI48: 44196 | AJ48: 208.32 | AK48: 4999.68 | BG48: P | BI48: PRIMARY | BK48: A | BL48: ADD | BM48: ITEMIZED RECEIPTS | BN48: 44223.151 | BR48: F3X | BS48: 4.0125202e+18 | BT48: t | BV48: 2020 | BW48: SA | BY48: 4.0127202e+18 | BZ48: https://docquery.fec.gov/cgi-bin/fecimg/?202101259405395219 | CA48: Contributions From Individuals/Persons Other Than Political Committees
V50: =+V48&X48&Y48&Z48 -> 100 N TRYON STCHARLOTTENC28255
A51: Row Labels | B51: Sum of contribution_receipt_amount
A52: BANK OF AMERICA CORPORATION FEDERAL PAC | B52: 9357.88
A53: Grand Total | B53: 9357.88

Sheet Thomas Montag
A1: committee_id | B1: committee_name | C1: report_year | D1: report_type | E1: image_number | F1: line_number | G1: transaction_id | H1: file_number | I1: committee_name | J1: entity_type | K1: entity_type_desc | L1: unused_contbr_id | M1: contributor_prefix | N1: contributor_name | O1: recipient_committee_type | P1: recipient_committee_org_type | Q1: recipient_committee_designation | R1: contributor_first_name | S1: contributor_middle_name | T1: contributor_last_name | U1: contributor_suffix | V1: contributor_street_1 | W1: contributor_street_2 | X1: contributor_city | Y1: contributor_state | Z1: contributor_zip | AA1: contributor_employer | AB1: contributor_occupation | AC1: contributor_id | AD1: receipt_type | AE1: receipt_type_desc | AF1: receipt_type_full | AG1: memo_code | AH1: memo_code_full | AI1: contribution_receipt_date | AJ1: contribution_receipt_amount | AK1: contributor_aggregate_ytd | AL1: candidate_id | AM1: candidate_name | AN1: candidate_first_name | AO1: candidate_last_name | AP1: candidate_middle_name | AQ1: candidate_prefix | AR1: candidate_suffix | AS1: candidate_office | AT1: candidate_office_full | AU1: candidate_office_state | AV1: candidate_office_state_full | AW1: candidate_office_district | AX1: conduit_committee_id | AY1: conduit_committee_name | AZ1: conduit_committee_street1 | BA1: conduit_committee_street2 | BB1: conduit_committee_city | BC1: conduit_committee_state | BD1: conduit_committee_zip | BE1: donor_committee_name | BF1: national_committee_nonfederal_account | BG1: election_type | BH1: election_type_full | BI1: fec_election_type_desc | BJ1: fec_election_year | BK1: amendment_indicator | BL1: amendment_indicator_desc | BM1: schedule_type_full | BN1: load_date | BO1: original_sub_id | BP1: back_reference_transaction_id | BQ1: back_reference_schedule_name | BR1: filing_form | BS1: link_id | BT1: is_individual | BU1: memo_text | BV1: two_year_transaction_period | BW1: schedule_type | BX1: increased_limit | BY1: sub_id | BZ1: pdf_url | CA1: line_number_label
A2: C00370056 | B2: DEVIN NUNES CAMPAIGN COMMITTEE | C2: 2019 | D2: Q1 | E2: 2.0190716e+17 | F2: 12 | G2: A8A06EDE5B6524991B6F | H2: 1339265 | J2: IND | K2: INDIVIDUAL | N2: MONTAG, THOMAS | O2: H | Q2: P | R2: THOMAS | T2: MONTAG | V2: 127 E 73RD ST | X2: NEW YORK | Y2: NY | Z2: 100213502 | AA2: BANK OF AMERICA | AB2: COO | AD2: 15J | AE2: MEMO (FILER'S % OF CONTRIBUTION GIVEN TO JOIN | AG2: X | AI2: 43552 | AJ2: 2800 | AK2: 5600 | BG2: G2020 | BI2: GENERAL | BJ2: 2020 | BK2: N | BL2: NO CHANGE | BM2: ITEMIZED RECEIPTS | BN2: 43662.174 | BP2: AF978B0A2FE2B4C5B9C8 | BQ2: SA12 | BR2: F3 | BS2: 4.0715202e+18 | BT2: t | BV2: 2020 | BW2: SA | BY2: 4.0715202e+18 | BZ2: http://docquery.fec.gov/cgi-bin/fecimg/?201907159150604201 | CA2: Transfers from authorized committees
A3: C00370056 | B3: DEVIN NUNES CAMPAIGN COMMITTEE | C3: 2019 | D3: Q1 | E3: 2.0190716e+17 | F3: 12 | G3: AE8CA03E4223B41728D1 | H3: 1339265 | J3: IND | K3: INDIVIDUAL | N3: MONTAG, THOMAS | O3: H | Q3: P | R3: THOMAS | T3: MONTAG | V3: 127 E 73RD ST | X3: NEW YORK | Y3: NY | Z3: 100213502 | AA3: BANK OF AMERICA | AB3: COO | AD3: 15J | AE3: MEMO (FILER'S % OF CONTRIBUTION GIVEN TO JOIN | AG3: X | AI3: 43552 | AJ3: 2800 | AK3: 5600 | BG3: P2020 | BI3: PRIMARY | BJ3: 2020 | BK3: N | BL3: NO CHANGE | BM3: ITEMIZED RECEIPTS | BN3: 43662.174 | BP3: A0AB6B94AEA1F4BC2AAB | BQ3: SA12 | BR3: F3 | BS3: 4.0715202e+18 | BT3: t | BV3: 2020 | BW3: SA | BY3: 4.0715202e+18 | BZ3: http://docquery.fec.gov/cgi-bin/fecimg/?201907159150604212 | CA3: Transfers from authorized committees
A4: C00551275 | B4: FRENCH HILL FOR ARKANSAS | C4: 2019 | D4: Q1 | E4: 2.0190824e+17 | F4: 12 | G4: SA12.10212 | H4: 1349484 | J4: IND | K4: INDIVIDUAL | M4: MR. | N4: MONTAG, THOMAS MR. | O4: H | Q4: P | R4: THOMAS | T4: MONTAG | V4: 127 EAST 73RD STREET | X4: NEW YORK | Y4: NY | Z4: 100213502 | AA4: BANK OF AMERICA | AB4: COO | AD4: 15J | AE4: MEMO (FILER'S % OF CONTRIBUTION GIVEN TO JOIN | AF4: TRANSFER | AG4: X | AI4: 43539 | AJ4: 2800 | AK4: 5600 | BG4: G2020 | BI4: GENERAL | BJ4: 2020 | BK4: N | BL4: NO CHANGE | BM4: ITEMIZED RECEIPTS | BN4: 43702.107 | BP4: SA12.10143 | BQ4: SA12 | BR4: F3 | BS4: 4.0823202e+18 | BT4: t | BU4: JFC ATTRIB: TAKE BACK THE HOUSE 2020 | BV4: 2020 | BW4: SA | BY4: 4.0824202e+18 | BZ4: http://docquery.fec.gov/cgi-bin/fecimg/?201908239163101342 | CA4: Transfers from authorized committees
A5: C00551275 | B5: FRENCH HILL FOR ARKANSAS | C5: 2019 | D5: Q1 | E5: 2.0190824e+17 | F5: 12 | G5: SA12.10210 | H5: 1349484 | J5: IND | K5: INDIVIDUAL | M5: MR. | N5: MONTAG, THOMAS MR. | O5: H | Q5: P | R5: THOMAS | T5: MONTAG | V5: 127 EAST 73RD STREET | X5: NEW YORK | Y5: NY | Z5: 100213502 | AA5: BANK OF AMERICA | AB5: COO | AD5: 15J | AE5: MEMO (FILER'S % OF CONTRIBUTION GIVEN TO JOIN | AF5: TRANSFER | AG5: X | AI5: 43539 | AJ5: 2800 | AK5: 5600 | BG5: P2020 | BI5: PRIMARY | BJ5: 2020 | BK5: N | BL5: NO CHANGE | BM5: ITEMIZED RECEIPTS | BN5: 43702.107 | BP5: SA12.10144 | BQ5: SA12 | BR5: F3 | BS5: 4.0823202e+18 | BT5: t | BU5: JFC ATTRIB: TAKE BACK THE HOUSE 2020 | BV5: 2020 | BW5: SA | BY5: 4.0824202e+18 | BZ5: http://docquery.fec.gov/cgi-bin/fecimg/?201908239163101357 | CA5: Transfers from authorized committees
A6: C00662650 | B6: BALDERSON FOR CONGRESS | C6: 2019 | D6: Q1 | E6: 2.0190827e+17 | F6: 12 | G6: AF98594688AEF4D63847 | H6: 1349830 | J6: IND | K6: INDIVIDUAL | N6: MONTAG, THOMAS | O6: H | Q6: P | R6: THOMAS | T6: MONTAG | V6: 127 E 73RD ST | X6: NEW YORK | Y6: NY | Z6: 10021 | AA6: BANK OF AMERICA | AB6: COO | AD6: 15J | AE6: MEMO (FILER'S % OF CONTRIBUTION GIVEN TO JOIN | AG6: X | AI6: 43539 | AJ6: 2651.22 | AK6: 2651.22 | BG6: P2020 | BI6: PRIMARY | BJ6: 2020 | BK6: N | BL6: NO CHANGE | BM6: ITEMIZED RECEIPTS | BN6: 43705.109 | BP6: AEC113F4AED7542E1A2E | BQ6: SA12 | BR6: F3 | BS6: 4.0826202e+18 | BT6: t | BV6: 2020 | BW6: SA | BY6: 4.0827202e+18 | BZ6: http://docquery.fec.gov/cgi-bin/fecimg/?201908269163104886 | CA6: Transfers from authorized committees
A7: C00629949 | B7: ALEX MOONEY FOR CONGRESS | C7: 2019 | D7: Q1 | E7: 2.0210405e+17 | F7: 12 | G7: SA12.22557 | H7: 1507515 | J7: IND | K7: INDIVIDUAL | N7: MONTAG, THOMAS | O7: H | Q7: P | R7: THOMAS | T7: MONTAG | V7: 127 E 73RD ST. | W7: NEW YORK | X7: NY | Y7: NY | Z7: 100213502 | AA7: BANK OF AMERICA | AB7: COO | AD7: 15J | AE7: MEMO (FILER'S % OF CONTRIBUTION GIVEN TO JOIN | AF7: TRANSFER | AG7: X | AI7: 43539 | AJ7: 2651.22 | AK7: 2651.22 | BG7: P2020 | BI7: PRIMARY | BJ7: 2020 | BK7: N | BL7: NO CHANGE | BM7: ITEMIZED RECEIPTS | BN7: 44292.174 | BP7: SA12.22462 | BQ7: SA12 | BR7: F3 | BS7: 4.0405202e+18 | BT7: t | BU7: JFC ATTRIB: TAKE BACK THE HOUSE 2020 | BV7: 2020 | BW7: SA | BY7: 4.0406202e+18 | BZ7: https://docquery.fec.gov/cgi-bin/fecimg/?202104049443062349 | CA7: Transfers from authorized committees
A8: C00499236 | B8: GEORGE HOLDING FOR CONGRESS INC. | C8: 2019 | D8: Q1 | E8: 2.0190416e+17 | F8: 12 | G8: SA12-TI68-12 | H8: 1325376 | J8: IND | K8: INDIVIDUAL | N8: MONTAG, THOMAS | O8: H | Q8: P | R8: THOMAS | T8: MONTAG | V8: 127 E 73RD ST | X8: NEW YORK | Y8: NY | Z8: 10021 | AA8: BANK OF AMERICA | AB8: COO | AD8: 15J | AE8: MEMO (FILER'S % OF CONTRIBUTION GIVEN TO JOIN | AF8: TRANSFER IN AFFILIATED | AG8: X | AI8: 43539 | AJ8: 2800 | AK8: 5600 | BG8: G2020 | BI8: GENERAL | BJ8: 2020 | BK8: A | BL8: ADD | BM8: ITEMIZED RECEIPTS | BN8: 43576.149 | BR8: F3 | BS8: 4.0415202e+18 | BT8: t | BU8: TAKE BACK THE HOUSE 2020 | BV8: 2020 | BW8: SA | BY8: 4.0420202e+18 | BZ8: http://docquery.fec.gov/cgi-bin/fecimg/?201904159146156641 | CA8: Transfers from authorized committees
A9: C00200584 | B9: UPTON FOR ALL OF US | C9: 2019 | D9: Q1 | E9: 2.0190416e+17 | F9: 12 | G9: A0F26B28663C24330B76 | H9: 1325998 | J9: IND | K9: INDIVIDUAL | N9: MONTAG, THOMAS | O9: H | Q9: P | R9: THOMAS | T9: MONTAG | V9: 127 E 73RD ST | X9: NEW YORK | Y9: NY | Z9: 100213502 | AA9: BANK OF AMERICA | AB9: COO | AD9: 15J | AE9: MEMO (FILER'S % OF CONTRIBUTION GIVEN TO JOIN | AG9: X | AI9: 43539 | AJ9: 2651.22 | AK9: 2651.22 | BG9: P2020 | BI9: PRIMARY | BJ9: 2020 | BK9: A | BL9: ADD | BM9: ITEMIZED RECEIPTS | BN9: 43576.15 | BP9: A01D3BDD21E974F85ACC | BQ9: SA12 | BR9: F3 | BS9: 4.0415202e+18 | BT9: t | BV9: 2020 | BW9: SA | BY9: 4.0420202e+18 | BZ9: http://docquery.fec.gov/cgi-bin/fecimg/?201904159146201998 | CA9: Transfers from authorized committees
A10: C00509422 | B10: DOUG LAMALFA COMMITTEE | C10: 2019 | D10: Q1 | E10: 2.0190606e+17 | F10: 12 | G10: IDTA382 | H10: 1333095 | J10: IND | K10: INDIVIDUAL | N10: MONTAG, THOMAS | O10: H | Q10: P | R10: THOMAS | T10: MONTAG | V10: 127 E 73RD ST. | X10: NEW YORK | Y10: NY | Z10: 10021 | AA10: BANK OF AMERICA | AB10: COO | AD10: 15J | AE10: MEMO (FILER'S % OF CONTRIBUTION GIVEN TO JOIN | AG10: X | AI10: 43539 | AJ10: 2651.22 | AK10: 2651.22 | AY10: TAKE BACK THE HOUSE 2020 | AZ10: P.O. BOX 30844 | BB10: BETHESDA | BC10: MD | BD10: 20824 | BG10: P2020 | BI10: PRIMARY | BJ10: 2020 | BK10: C | BL10: CHANGE | BM10: ITEMIZED RECEIPTS | BN10: 43623.113 | BP10: INCA6250 | BQ10: SA12 | BR10: F3 | BS10: 4.0605202e+18 | BT10: t | BV10: 2020 | BW10: SA | BY10: 4.0606202e+18 | BZ10: http://docquery.fec.gov/cgi-bin/fecimg/?201906059149930841 | CA10: Transfers from authorized committees
A11: C00660795 | B11: DAN CRENSHAW FOR CONGRESS | C11: 2019 | D11: Q1 | E11: 2.0190416e+17 | F11: 12 | G11: A3FC01698873245299B8 | H11: 1326297 | J11: IND | K11: INDIVIDUAL | N11: MONTAG, THOMAS | O11: H | Q11: P | R11: THOMAS | T11: MONTAG | V11: 127 E 73RD ST | X11: NEW YORK | Y11: NY | Z11: 100213502 | AA11: BANK OF AMERICA | AB11: COO | AD11: 15J | AE11: MEMO (FILER'S % OF CONTRIBUTION GIVEN TO JOIN | AG11: X | AI11: 43539 | AJ11: 2651.22 | AK11: 2651.22 | BG11: P2020 | BI11: PRIMARY | BJ11: 2020 | BK11: A | BL11: ADD | BM11: ITEMIZED RECEIPTS | BN11: 43574.205 | BP11: A1AA4651CF89B4DF0B62 | BQ11: SA12 | BR11: F3 | BS11: 4.0416202e+18 | BT11: t | BV11: 2020 | BW11: SA | BY11: 4.0418202e+18 | BZ11: http://docquery.fec.gov/cgi-bin/fecimg/?201904159146346790 | CA11: Transfers from authorized committees
A12: C00662767 | B12: CHIP ROY FOR CONGRESS | C12: 2019 | D12: Q1 | E12: 2.0190416e+17 | F12: 12 | G12: SA12.12525 | H12: 1325616 | J12: IND | K12: INDIVIDUAL | N12: MONTAG, THOMAS | O12: H | Q12: P | R12: THOMAS | T12: MONTAG | V12: 127 E 73RD ST | X12: NEW YORK | Y12: NY | Z12: 100213502 | AA12: BANK OF AMERICA | AB12: COO | AD12: 15J | AE12: MEMO (FILER'S % OF CONTRIBUTION GIVEN TO JOIN | AF12: TRANSFER | AG12: X | AI12: 43539 | AJ12: 2651.22 | AK12: 2651.22 | BG12: P2020 | BI12: PRIMARY | BJ12: 2020 | BK12: A | BL12: ADD | BM12: ITEMIZED RECEIPTS | BN12: 43574.202 | BP12: SA12.12492 | BQ12: SA12 | BR12: F3 | BS12: 4.0415202e+18 | BT12: t | BU12: JFC ATTRIB: TAKE BACK THE HOUSE 2020 | BV12: 2020 | BW12: SA | BY12: 4.0418202e+18 | BZ12: http://docquery.fec.gov/cgi-bin/fecimg/?201904159146170808 | CA12: Transfers from authorized committees
A13: C00373001 | B13: CITIZENS FOR TURNER | C13: 2019 | D13: Q1 | E13: 2.0190416e+17 | F13: 12 | G13: A90980EB059D34DF08C5 | H13: 1326357 | J13: IND | K13: INDIVIDUAL | N13: MONTAG, THOMAS | O13: H | Q13: P | R13: THOMAS | T13: MONTAG | V13: 127 E 73RD ST | X13: NEW YORK | Y13: NY | Z13: 10021 | AA13: BANK OF AMERICA | AB13: COO | AD13: 15J | AE13: MEMO (FILER'S % OF CONTRIBUTION GIVEN TO JOIN | AG13: X | AI13: 43539 | AJ13: 2651.22 | AK13: 2651.22 | BG13: P2020 | BI13: PRIMARY | BJ13: 2020 | BK13: A | BL13: ADD | BM13: ITEMIZED RECEIPTS | BN13: 43576.15 | BP13: AA5FE2A2980CC458099A | BQ13: SA12 | BR13: F3 | BS13: 4.0416202e+18 | BT13: t | BV13: 2020 | BW13: SA | BY13: 4.0420202e+18 | BZ13: http://docquery.fec.gov/cgi-bin/fecimg/?201904159146360044 | CA13: Transfers from authorized committees
A14: C00527457 | B14: FRIENDS OF DAVE JOYCE | C14: 2019 | D14: Q1 | E14: 2.0190416e+17 | F14: 12 | G14: A786728708555463AA95 | H14: 1325638 | J14: IND | K14: INDIVIDUAL | N14: MONTAG, THOMAS | O14: H | Q14: P | R14: THOMAS | T14: MONTAG | V14: 127 E 73RD ST | X14: NEW YORK | Y14: NY | Z14: 100213502 | AA14: BANK OF AMERICA | AB14: COO | AD14: 15J | AE14: MEMO (FILER'S % OF CONTRIBUTION GIVEN TO JOIN | AG14: X | AI14: 43539 | AJ14: 2800 | AK14: 5600 | BG14: P2020 | BI14: PRIMARY | BJ14: 2020 | BK14: A | BL14: ADD | BM14: ITEMIZED RECEIPTS | BN14: 43576.149 | BP14: A5069661D0E914823955 | BQ14: SA12 | BR14: F3 | BS14: 4.0415202e+18 | BT14: t | BV14: 2020 | BW14: SA | BY14: 4.0420202e+18 | BZ14: http://docquery.fec.gov/cgi-bin/fecimg/?201904159146171979 | CA14: Transfers from authorized committees
A15: C00527457 | B15: FRIENDS OF DAVE JOYCE | C15: 2019 | D15: Q1 | E15: 2.0190416e+17 | F15: 12 | G15: A2B62F90B2B3F42D4985 | H15: 1325638 | J15: IND | K15: INDIVIDUAL | N15: MONTAG, THOMAS | O15: H | Q15: P | R15: THOMAS | T15: MONTAG | V15: 127 E 73RD ST | X15: NEW YORK | Y15: NY | Z15: 100213502 | AA15: BANK OF AMERICA | AB15: COO | AD15: 15J | AE15: MEMO (FILER'S % OF CONTRIBUTION GIVEN TO JOIN | AG15: X | AI15: 43539 | AJ15: 2800 | AK15: 5600 | BG15: G2020 | BI15: GENERAL | BJ15: 2020 | BK15: A | BL15: ADD | BM15: ITEMIZED RECEIPTS | BN15: 43576.149 | BP15: A45D20F100A22429E904 | BQ15: SA12 | BR15: F3 | BS15: 4.0415202e+18 | BT15: t | BV15: 2020 | BW15: SA | BY15: 4.0420202e+18 | BZ15: http://docquery.fec.gov/cgi-bin/fecimg/?201904159146171992 | CA15: Transfers from authorized committees
A16: C00575167 | B16: DON BACON FOR CONGRESS | C16: 2019 | D16: Q1 | E16: 2.0190714e+17 | F16: 12 | G16: AD29701CC3CB140DD8F6 | H16: 1338851 | J16: IND | K16: INDIVIDUAL | N16: MONTAG, THOMAS | O16: H | Q16: P | R16: THOMAS | T16: MONTAG | V16: 127 E 73RD ST | X16: NEW YORK | Y16: NY | Z16: 100213502 | AA16: BANK OF AMERICA | AB16: COO | AD16: 15J | AE16: MEMO (FILER'S % OF CONTRIBUTION GIVEN TO JOIN | AG16: X | AI16: 43553 | AJ16: 2651.22 | AK16: 2651.22 | BG16: P2020 | BI16: PRIMARY | BJ16: 2020 | BK16: N | BL16: NO CHANGE | BM16: ITEMIZED RECEIPTS | BN16: 43673.11 | BP16: AB5ED80FB6E554FF3AC6 | BQ16: SA12 | BR16: F3 | BS16: 4.0713202e+18 | BT16: t | BU16: TAKE BACK THE HOUSE TRANSFER MEMO | BV16: 2020 | BW16: SA | BY16: 4.0726202e+18 | BZ16: http://docquery.fec.gov/cgi-bin/fecimg/?201907139150587553 | CA16: Transfers from authorized committees
A17: C00545467 | B17: HURD FOR CONGRESS | C17: 2019 | D17: Q1 | E17: 2.0190723e+17 | F17: 12 | G17: SA12.58942 | H17: 1343250 | J17: IND | K17: INDIVIDUAL | N17: MONTAG, THOMAS | O17: H | Q17: P | R17: THOMAS | T17: MONTAG | V17: 127 E 73RD ST | X17: NEW YORK | Y17: NY | Z17: 10021 | AA17: BANK OF AMERICA | AB17: COO | AD17: 15J | AE17: MEMO (FILER'S % OF CONTRIBUTION GIVEN TO JOIN | AF17: JFC TRANSFER: TAKE BACK THE HOUSE [SA12.54376] | AG17: X | AI17: 43539 | AJ17: 2651.22 | AK17: 2651.22 | BG17: P2020 | BI17: PRIMARY | BJ17: 2020 | BK17: A | BL17: ADD | BM17: ITEMIZED RECEIPTS | BN17: 43673.11 | BR17: F3 | BS17: 4.0722202e+18 | BT17: t | BV17: 2020 | BW17: SA | BY17: 4.0726202e+18 | BZ17: http://docquery.fec.gov/cgi-bin/fecimg/?201907229151614283 | CA17: Transfers from authorized committees
A18: C00677286 | B18: STEIL FOR WISCONSIN, INC. | C18: 2019 | D18: Q1 | E18: 2.0190716e+17 | F18: 12 | G18: AA92E907DBFFC4575B1D | H18: 1340871 | J18: IND | K18: INDIVIDUAL | N18: MONTAG, THOMAS | O18: H | Q18: P | R18: THOMAS | T18: MONTAG | V18: 127 EAST 73RD STREET | X18: NEW YORK | Y18: NY | Z18: 10021 | AA18: BANK OF AMERICA | AB18: COO | AD18: 15J | AE18: MEMO (FILER'S % OF CONTRIBUTION GIVEN TO JOIN | AG18: X | AI18: 43539 | AJ18: 2800 | AK18: 5600 | BG18: G2020 | BI18: GENERAL | BJ18: 2020 | BK18: N | BL18: NO CHANGE | BM18: ITEMIZED RECEIPTS | BN18: 43673.11 | BP18: A0294E4D1449B4699B4D | BQ18: SA12 | BR18: F3 | BS18: 4.0716202e+18 | BT18: t | BV18: 2020 | BW18: SA | BY18: 4.0726202e+18 | BZ18: http://docquery.fec.gov/cgi-bin/fecimg/?201907159150998463 | CA18: Transfers from authorized committees
A19: C00677286 | B19: STEIL FOR WISCONSIN, INC. | C19: 2019 | D19: Q1 | E19: 2.0190716e+17 | F19: 12 | G19: A0F28D5E6F24245DF908 | H19: 1340871 | J19: IND | K19: INDIVIDUAL | N19: MONTAG, THOMAS | O19: H | Q19: P | R19: THOMAS | T19: MONTAG | V19: 127 EAST 73RD STREET | X19: NEW YORK | Y19: NY | Z19: 10021 | AA19: BANK OF AMERICA | AB19: COO | AD19: 15J | AE19: MEMO (FILER'S % OF CONTRIBUTION GIVEN TO JOIN | AG19: X | AI19: 43539 | AJ19: 2800 | AK19: 5600 | BG19: P2020 | BI19: PRIMARY | BJ19: 2020 | BK19: N | BL19: NO CHANGE | BM19: ITEMIZED RECEIPTS | BN19: 43673.11 | BP19: A325F370CFE854A9D9E8 | BQ19: SA12 | BR19: F3 | BS19: 4.0716202e+18 | BT19: t | BV19: 2020 | BW19: SA | BY19: 4.0726202e+18 | BZ19: http://docquery.fec.gov/cgi-bin/fecimg/?201907159150998471 | CA19: Transfers from authorized committees
A20: C00660050 | B20: COMMITTEE TO RE-ELECT STEVE WATKINS | C20: 2019 | D20: Q1 | E20: 2.0190716e+17 | F20: 12 | G20: AB3926BF1261640379FE | H20: 1340635 | J20: IND | K20: INDIVIDUAL | N20: MONTAG, THOMAS | O20: H | Q20: P | R20: THOMAS | T20: MONTAG | V20: 127 E 73RD ST | X20: NEW YORK | Y20: NY | Z20: 10021 | AA20: BANK OF AMERICA | AB20: COO | AD20: 15J | AE20: MEMO (FILER'S % OF CONTRIBUTION GIVEN TO JOIN | AG20: X | AI20: 43539 | AJ20: 2651.22 | AK20: 2651.22 | BG20: P2020 | BI20: PRIMARY | BJ20: 2020 | BK20: N | BL20: NO CHANGE | BM20: ITEMIZED RECEIPTS | BN20: 43673.11 | BP20: A8C490F2A64184F05BB0 | BQ20: SA12 | BR20: F3 | BS20: 4.0715202e+18 | BT20: t | BV20: 2020 | BW20: SA | BY20: 4.0726202e+18 | BZ20: http://docquery.fec.gov/cgi-bin/fecimg/?201907159150896218 | CA20: Transfers from authorized committees
A21: C00540617 | B21: FRIENDS OF DAVID SCHWEIKERT | C21: 2019 | D21: Q1 | E21: 2.0190416e+17 | F21: 12 | G21: ABFB61C230FC44118826 | H21: 1326169 | J21: IND | K21: INDIVIDUAL | N21: MONTAG, THOMAS | O21: H | Q21: P | R21: THOMAS | T21: MONTAG | V21: 127 EAST 73RD STREET | X21: NEW YORK | Y21: NY | Z21: 10021 | AA21: BANK OF AMERICA | AB21: COO | AD21: 15J | AE21: MEMO (FILER'S % OF CONTRIBUTION GIVEN TO JOIN | AG21: X | AI21: 43539 | AJ21: 2651.22 | AK21: 2651.22 | BG21: P2020 | BI21: PRIMARY | BJ21: 2020 | BK21: A | BL21: ADD | BM21: ITEMIZED RECEIPTS | BN21: 43572.115 | BP21: A701E59EC73974E42961 | BQ21: SA12 | BR21: F3 | BS21: 4.0415202e+18 | BT21: t | BV21: 2020 | BW21: SA | BY21: 4.0416202e+18 | BZ21: http://docquery.fec.gov/cgi-bin/fecimg/?201904159146333859 | CA21: Transfers from authorized committees
A22: C00663914 | B22: DEBBIE LESKO FOR CONGRESS | C22: 2019 | D22: Q1 | E22: 2.0190416e+17 | F22: 12 | G22: ADE9417B3DE9F43F5A55 | H22: 1325492 | J22: IND | K22: INDIVIDUAL | N22: MONTAG, THOMAS | O22: H | Q22: P | R22: THOMAS | T22: MONTAG | V22: 127 E. 73RD STREET | X22: NEW YORK | Y22: NY | Z22: 100213502 | AA22: BANK OF AMERICA | AB22: COO | AD22: 15J | AE22: MEMO (FILER'S % OF CONTRIBUTION GIVEN TO JOIN | AG22: X | AI22: 43552 | AJ22: 2651.22 | AK22: 2651.22 | BG22: P2020 | BI22: PRIMARY | BJ22: 2020 | BK22: A | BL22: ADD | BM22: ITEMIZED RECEIPTS | BN22: 43571.118 | BP22: AEB33E23199684E29A6C | BQ22: SA12 | BR22: F3 | BS22: 4.0415202e+18 | BT22: t | BV22: 2020 | BW22: SA | BY22: 4.0415202e+18 | BZ22: http://docquery.fec.gov/cgi-bin/fecimg/?201904159146162354 | CA22: Transfers from authorized committees
A23: C00096412 | B23: FRIENDS OF CHRIS SMITH | C23: 2019 | D23: Q1 | E23: 2.0190416e+17 | F23: 12 | G23: ACA8ADE04DD5E4AF79D9 | H23: 1326500 | J23: IND | K23: INDIVIDUAL | M23: MR. | N23: MONTAG, THOMAS MR. | O23: H | Q23: P | R23: THOMAS | T23: MONTAG | V23: 127 E 73RD ST. | X23: NEW YORK | Y23: NY | Z23: 100213502 | AA23: BANK OF AMERICA | AB23: COO | AD23: 15J | AE23: MEMO (FILER'S % OF CONTRIBUTION GIVEN TO JOIN | AG23: X | AI23: 43539 | AJ23: 2651.21 | AK23: 2651.21 | BG23: P2020 | BI23: PRIMARY | BJ23: 2020 | BK23: A | BL23: ADD | BM23: ITEMIZED RECEIPTS | BN23: 43576.15 | BP23: A25EB3FD32F174DE4A44 | BQ23: SA12 | BR23: F3 | BS23: 4.0416202e+18 | BT23: t | BV23: 2020 | BW23: SA | BY23: 4.0420202e+18 | BZ23: http://docquery.fec.gov/cgi-bin/fecimg/?201904159146386427 | CA23: Transfers from authorized committees
A24: C00012229 | B24: ALASKANS FOR DON YOUNG | C24: 2019 | D24: Q1 | E24: 2.0200121e+17 | F24: 12 | G24: AB7E50C6ACC224477ADF | H24: 1371459 | J24: IND | K24: INDIVIDUAL | N24: MONTAG, THOMAS | O24: H | Q24: P | R24: THOMAS | T24: MONTAG | V24: 127 E 73RD ST | X24: NEW YORK | Y24: NY | Z24: 100213502 | AA24: BANK OF AMERICA | AB24: COO | AD24: 15J | AE24: MEMO (FILER'S % OF CONTRIBUTION GIVEN TO JOIN | AG24: X | AI24: 43555 | AJ24: 2651.21 | AK24: 2651.21 | BG24: P2020 | BI24: PRIMARY | BJ24: 2020 | BK24: A | BL24: ADD | BM24: ITEMIZED RECEIPTS | BN24: 43852.068 | BP24: A628151178B6E42448F2 | BQ24: SA12 | BR24: F3 | BS24: 4.0120202e+18 | BT24: t | BV24: 2020 | BW24: SA | BY24: 4.0121202e+18 | BZ24: http://docquery.fec.gov/cgi-bin/fecimg/?202001209167277812 | CA24: Transfers from authorized committees
A25: C00546499 | B25: MIKE BOST FOR CONGRESS COMMITTEE | C25: 2019 | D25: Q1 | E25: 2.0190416e+17 | F25: 12 | G25: A10890455726749A3B80 | H25: 1325974 | J25: IND | K25: INDIVIDUAL | N25: MONTAG, THOMAS | O25: H | Q25: P | R25: THOMAS | T25: MONTAG | V25: 127 E 73RD ST | X25: NEW YORK | Y25: NY | Z25: 100213502 | AA25: BANK OF AMERICA | AB25: COO | AD25: 15J | AE25: MEMO (FILER'S % OF CONTRIBUTION GIVEN TO JOIN | AG25: X | AI25: 43539 | AJ25: 2651.22 | AK25: 2651.22 | BG25: P2020 | BI25: PRIMARY | BJ25: 2020 | BK25: A | BL25: ADD | BM25: ITEMIZED RECEIPTS | BN25: 43574.193 | BP25: AEC02A7CB062A491599E | BQ25: SA12 | BR25: F3 | BS25: 4.0415202e+18 | BT25: t | BV25: 2020 | BW25: SA | BY25: 4.0418202e+18 | BZ25: http://docquery.fec.gov/cgi-bin/fecimg/?201904159146199971 | CA25: Transfers from authorized committees
A26: C00547893 | B26: ELISE FOR CONGRESS | C26: 2019 | D26: Q1 | E26: 2.0190416e+17 | F26: 12 | G26: SA12.17706 | H26: 1325632 | J26: IND | K26: INDIVIDUAL | N26: MONTAG, THOMAS | O26: H | Q26: P | R26: THOMAS | T26: MONTAG | V26: 127 E 73RD ST | X26: NEW YORK | Y26: NY | Z26: 100213502 | AA26: BANK OF AMERICA | AB26: COO | AD26: 15J | AE26: MEMO (FILER'S % OF CONTRIBUTION GIVEN TO JOIN | AF26: TRANSFER | AG26: X | AI26: 43539 | AJ26: 2651.22 | AK26: 2651.22 | BG26: P2020 | BI26: PRIMARY | BJ26: 2020 | BK26: A | BL26: ADD | BM26: ITEMIZED RECEIPTS | BN26: 43574.202 | BP26: SA12.17672 | BQ26: SA12 | BR26: F3 | BS26: 4.0415202e+18 | BT26: t | BU26: JFC ATTRIB: TAKE BACK THE HOUSE 2020 | BV26: 2020 | BW26: SA | BY26: 4.0418202e+18 | BZ26: http://docquery.fec.gov/cgi-bin/fecimg/?201904159146171777 | CA26: Transfers from authorized committees
A27: C00390476 | B27: CATHY MCMORRIS RODGERS FOR CONGRESS | C27: 2019 | D27: Q1 | E27: 2.0190416e+17 | F27: 12 | G27: SA12.103478 | H27: 1325593 | J27: IND | K27: INDIVIDUAL | N27: MONTAG, THOMAS | O27: H | Q27: P | R27: THOMAS | T27: MONTAG | V27: 127 E 73RD ST | X27: NEW YORK | Y27: NY | Z27: 100213502 | AA27: BANK OF AMERICA | AB27: COO | AD27: 15J | AE27: MEMO (FILER'S % OF CONTRIBUTION GIVEN TO JOIN | AF27: TRANSFER | AG27: X | AI27: 43539 | AJ27: 2651.22 | AK27: 2651.22 | BG27: P2020 | BI27: PRIMARY | BJ27: 2020 | BK27: A | BL27: ADD | BM27: ITEMIZED RECEIPTS | BN27: 43574.191 | BP27: SA12.103434 | BQ27: SA12 | BR27: F3 | BS27: 4.0415202e+18 | BT27: t | BU27: JFC ATTRIB: TAKE BACK THE HOUSE 2020 | BV27: 2020 | BW27: SA | BY27: 4.0418202e+18 | BZ27: http://docquery.fec.gov/cgi-bin/fecimg/?201904159146170059 | CA27: Transfers from authorized committees
A28: C00390724 | B28: WALBERG FOR CONGRESS | C28: 2019 | D28: Q1 | E28: 2.0190416e+17 | F28: 12 | G28: AB46B891E20634B52831 | H28: 1326263 | J28: IND | K28: INDIVIDUAL | N28: MONTAG, THOMAS | O28: H | Q28: P | R28: THOMAS | T28: MONTAG | V28: 127 E 73RD ST | X28: NEW YORK | Y28: NY | Z28: 100213502 | AA28: BANK OF AMERICA | AB28: COO | AD28: 15J | AE28: MEMO (FILER'S % OF CONTRIBUTION GIVEN TO JOIN | AG28: X | AI28: 43539 | AJ28: 2651.22 | AK28: 2651.22 | BG28: P2020 | BI28: PRIMARY | BJ28: 2020 | BK28: A | BL28: ADD | BM28: ITEMIZED RECEIPTS | BN28: 43574.209 | BP28: A38B2ADE61B754826B93 | BQ28: SA12 | BR28: F3 | BS28: 4.0415202e+18 | BT28: t | BU28: TRANSFER OF JOINT FUNDRAISING PROCEEDS | BV28: 2020 | BW28: SA | BY28: 4.0418202e+18 | BZ28: http://docquery.fec.gov/cgi-bin/fecimg/?201904159146345618 | CA28: Transfers from authorized committees
A29: C00550707 | B29: FRIENDS OF HAGEDORN | C29: 2019 | D29: Q1 | E29: 2.0190412e+17 | F29: 12 | G29: A31DBC6D0AE994E1C8B0 | H29: 1323781 | J29: IND | K29: INDIVIDUAL | N29: MONTAG, THOMAS | O29: H | Q29: P | R29: THOMAS | T29: MONTAG | V29: 127 E 73RD ST | X29: NEW YORK | Y29: NY | Z29: 100213502 | AA29: BANK OF AMERICA | AB29: COO | AD29: 15J | AE29: MEMO (FILER'S % OF CONTRIBUTION GIVEN TO JOIN | AG29: X | AI29: 43539 | AJ29: 2651.22 | AK29: 2651.22 | BG29: P2020 | BI29: PRIMARY | BJ29: 2020 | BK29: A | BL29: ADD | BM29: ITEMIZED RECEIPTS | BN29: 43567.131 | BP29: A29208D256E3F4E7B84E | BQ29: SA12 | BR29: F3 | BS29: 4.0411202e+18 | BT29: t | BV29: 2020 | BW29: SA | BY29: 4.0411202e+18 | BZ29: http://docquery.fec.gov/cgi-bin/fecimg/?201904119146072449 | CA29: Transfers from authorized committees
A30: C00552547 | B30: ZELDIN FOR CONGRESS | C30: 2019 | D30: Q1 | E30: 2.0190416e+17 | F30: 12 | G30: SA12.94023.41 | H30: 1326459 | J30: IND | K30: INDIVIDUAL | N30: MONTAG, THOMAS | O30: H | Q30: P | R30: THOMAS | T30: MONTAG | V30: 127 EAST 73RD STREET | X30: NEW YORK | Y30: NY | Z30: 10021 | AA30: BANK OF AMERICA | AB30: COO | AD30: 15J | AE30: MEMO (FILER'S % OF CONTRIBUTION GIVEN TO JOIN | AF30: JFC-TBTH | AG30: X | AI30: 43551 | AJ30: 2800 | AK30: 2800 | BG30: P2020 | BI30: PRIMARY | BJ30: 2020 | BK30: A | BL30: ADD | BM30: ITEMIZED RECEIPTS | BN30: 43574.197 | BP30: SA12.94023 | BQ30: SA12 | BR30: F3 | BS30: 4.0416202e+18 | BT30: t | BV30: 2020 | BW30: SA | BY30: 4.0418202e+18 | BZ30: http://docquery.fec.gov/cgi-bin/fecimg/?201904159146369644 | CA30: Transfers from authorized committees
A31: C00552547 | B31: ZELDIN FOR CONGRESS | C31: 2019 | D31: Q1 | E31: 2.0190416e+17 | F31: 12 | G31: SA12.94118.18 | H31: 1326459 | J31: IND | K31: INDIVIDUAL | N31: MONTAG, THOMAS | O31: H | Q31: P | R31: THOMAS | T31: MONTAG | V31: 127 EAST 73RD STREET | X31: NEW YORK | Y31: NY | Z31: 10021 | AA31: BANK OF AMERICA | AB31: COO | AD31: 15J | AE31: MEMO (FILER'S % OF CONTRIBUTION GIVEN TO JOIN | AF31: JFC-TBTH | AG31: X | AI31: 43551 | AJ31: 2800 | AK31: 5600 | BG31: G2020 | BI31: GENERAL | BJ31: 2020 | BK31: A | BL31: ADD | BM31: ITEMIZED RECEIPTS | BN31: 43574.197 | BP31: SA12.94118 | BQ31: SA12 | BR31: F3 | BS31: 4.0416202e+18 | BT31: t | BV31: 2020 | BW31: SA | BY31: 4.0418202e+18 | BZ31: http://docquery.fec.gov/cgi-bin/fecimg/?201904159146369653 | CA31: Transfers from authorized committees
A32: C00556365 | B32: KATKO FOR CONGRESS | C32: 2019 | D32: Q1 | E32: 2.0190416e+17 | F32: 12 | G32: AE88D56BC0AF4439E8CD | H32: 1325406 | J32: IND | K32: INDIVIDUAL | N32: MONTAG, THOMAS | O32: H | Q32: P | R32: THOMAS | T32: MONTAG | V32: 127 E 73RD ST. | X32: NEW YORK | Y32: NY | Z32: 100213502 | AA32: BANK OF AMERICA | AB32: COO | AD32: 15J | AE32: MEMO (FILER'S % OF CONTRIBUTION GIVEN TO JOIN | AG32: X | AI32: 43553 | AJ32: 2800 | AK32: 5600 | BG32: G2020 | BI32: GENERAL | BJ32: 2020 | BK32: A | BL32: ADD | BM32: ITEMIZED RECEIPTS | BN32: 43576.149 | BP32: A55B7F7F06EA54E6F8C8 | BQ32: SA12 | BR32: F3 | BS32: 4.0415202e+18 | BT32: t | BU32: TAKE BACK THE HOUSE TRANSFER MEMO | BV32: 2020 | BW32: SA | BY32: 4.0420202e+18 | BZ32: http://docquery.fec.gov/cgi-bin/fecimg/?201904159146157854 | CA32: Transfers from authorized committees
A33: C00556365 | B33: KATKO FOR CONGRESS | C33: 2019 | D33: Q1 | E33: 2.0190416e+17 | F33: 12 | G33: AB7FD990C65E7473AA31 | H33: 1325406 | J33: IND | K33: INDIVIDUAL | N33: MONTAG, THOMAS | O33: H | Q33: P | R33: THOMAS | T33: MONTAG | V33: 127 E 73RD ST. | X33: NEW YORK | Y33: NY | Z33: 100213502 | AA33: BANK OF AMERICA | AB33: COO | AD33: 15J | AE33: MEMO (FILER'S % OF CONTRIBUTION GIVEN TO JOIN | AG33: X | AI33: 43553 | AJ33: 2800 | AK33: 5600 | BG33: P2020 | BI33: PRIMARY | BJ33: 2020 | BK33: A | BL33: ADD | BM33: ITEMIZED RECEIPTS | BN33: 43576.149 | BP33: A4D9FC3FFFA2B442B947 | BQ33: SA12 | BR33: F3 | BS33: 4.0415202e+18 | BT33: t | BU33: TAKE BACK THE HOUSE TRANSFER MEMO | BV33: 2020 | BW33: SA | BY33: 4.0420202e+18 | BZ33: http://docquery.fec.gov/cgi-bin/fecimg/?201904159146157865 | CA33: Transfers from authorized committees
A34: C00392688 | B34: MCCAUL FOR CONGRESS, INC | C34: 2019 | D34: Q1 | E34: 2.0190415e+17 | F34: 12 | G34: SA1958 | H34: 1324776 | J34: IND | K34: INDIVIDUAL | N34: MONTAG, THOMAS | O34: H | Q34: P | R34: THOMAS | T34: MONTAG | V34: 127 E 73RD ST | X34: NEW YORK | Y34: NY | Z34: 10021 | AA34: BANK OF AMERICA | AB34: COO | AD34: 15J | AE34: MEMO (FILER'S % OF CONTRIBUTION GIVEN TO JOIN | AF34: JFC ALLOCATION | AG34: X | AI34: 43539 | AJ34: 2651.22 | AK34: 2651.22 | BG34: P2020 | BI34: PRIMARY | BJ34: 2020 | BK34: A | BL34: ADD | BM34: ITEMIZED RECEIPTS | BN34: 43571.116 | BR34: F3 | BS34: 4.0415202e+18 | BT34: t | BV34: 2020 | BW34: SA | BY34: 4.0415202e+18 | BZ34: http://docquery.fec.gov/cgi-bin/fecimg/?201904149146122893 | CA34: Transfers from authorized committees
A35: C00393348 | B35: KENNY MARCHANT FOR CONGRESS | C35: 2019 | D35: Q1 | E35: 2.0190414e+17 | F35: 12 | G35: AF9F535BBB3B143F9958 | H35: 1324574 | J35: IND | K35: INDIVIDUAL | N35: MONTAG, THOMAS | O35: H | Q35: P | R35: THOMAS | T35: MONTAG | V35: 127 E 73RD ST | X35: NEW YORK | Y35: NY | Z35: 100213502 | AA35: BANK OF AMERICA | AB35: COO | AD35: 15J | AE35: MEMO (FILER'S % OF CONTRIBUTION GIVEN TO JOIN | AG35: X | AI35: 43539 | AJ35: 2651.22 | AK35: 2651.22 | BG35: P2020 | BI35: PRIMARY | BJ35: 2020 | BK35: A | BL35: ADD | BM35: ITEMIZED RECEIPTS | BN35: 43569.114 | BP35: AA8AD42EC02CF413AA9E | BQ35: SA12 | BR35: F3 | BS35: 4.0413202e+18 | BT35: t | BV35: 2020 | BW35: SA | BY35: 4.0413202e+18 | BZ35: http://docquery.fec.gov/cgi-bin/fecimg/?201904139146114506 | CA35: Transfers from authorized committees
A36: C00561597 | B36: GLENN GROTHMAN FOR CONGRESS | C36: 2019 | D36: Q1 | E36: 2.0190416e+17 | F36: 12 | G36: SA12.14817 | H36: 1326246 | J36: IND | K36: INDIVIDUAL | N36: MONTAG, THOMAS | O36: H | Q36: P | R36: THOMAS | T36: MONTAG | V36: 127 E 73RD ST | X36: NEW YORK | Y36: NY | Z36: 100213502 | AA36: BANK OF AMERICA | AB36: COO | AD36: 15J | AE36: MEMO (FILER'S % OF CONTRIBUTION GIVEN TO JOIN | AF36: TRANSFER | AG36: X | AI36: 43539 | AJ36: 2651.22 | AK36: 2651.22 | BG36: P2020 | BI36: PRIMARY | BJ36: 2020 | BK36: A | BL36: ADD | BM36: ITEMIZED RECEIPTS | BN36: 43574.196 | BP36: SA12.14714 | BQ36: SA12 | BR36: F3 | BS36: 4.0415202e+18 | BT36: t | BU36: JFC ATTRIB: TAKE BACK THE HOUSE 2020 | BV36: 2020 | BW36: SA | BY36: 4.0418202e+18 | BZ36: http://docquery.fec.gov/cgi-bin/fecimg/?201904159146344587 | CA36: Transfers from authorized committees
A37: C00412759 | B37: VERN BUCHANAN FOR CONGRESS | C37: 2019 | D37: Q1 | E37: 2.0190416e+17 | F37: 12 | G37: A70C1F47F26594AA48DA | H37: 1326058 | J37: IND | K37: INDIVIDUAL | N37: MONTAG, THOMAS | O37: H | Q37: P | R37: THOMAS | T37: MONTAG | V37: 127 E 73RD ST | X37: NEW YORK | Y37: NY | Z37: 100213502 | AA37: BANK OF AMERICA | AB37: COO | AD37: 15J | AE37: MEMO (FILER'S % OF CONTRIBUTION GIVEN TO JOIN | AG37: X | AI37: 43539 | AJ37: 2651.22 | AK37: 2651.22 | BG37: P2020 | BI37: PRIMARY | BJ37: 2020 | BK37: A | BL37: ADD | BM37: ITEMIZED RECEIPTS | BN37: 43573.117 | BP37: A500C34880A4E4CBC887 | BQ37: SA12 | BR37: F3 | BS37: 4.0415202e+18 | BT37: t | BV37: 2020 | BW37: SA | BY37: 4.0417202e+18 | BZ37: http://docquery.fec.gov/cgi-bin/fecimg/?201904159146217694 | CA37: Transfers from authorized committees
A38: C00420935 | B38: KEVIN MCCARTHY FOR CONGRESS | C38: 2019 | D38: Q1 | E38: 2.0190416e+17 | F38: 12 | G38: ABF69BABA713F406B863 | H38: 1325330 | J38: IND | K38: INDIVIDUAL | N38: MONTAG, THOMAS | O38: H | Q38: P | R38: THOMAS | T38: MONTAG | V38: 127 EAST 73RD STREET | X38: NEW YORK | Y38: NY | Z38: 100213502 | AA38: BANK OF AMERICA | AB38: CHIEF OPERATING OFFICER | AD38: 15J | AE38: MEMO (FILER'S % OF CONTRIBUTION GIVEN TO JOIN | AG38: X | AI38: 43539 | AJ38: 2800 | AK38: 5600 | BG38: P2020 | BI38: PRIMARY | BJ38: 2020 | BK38: A | BL38: ADD | BM38: ITEMIZED RECEIPTS | BN38: 43571.117 | BP38: A3270D63DB83C426399C | BQ38: SA12 | BR38: F3 | BS38: 4.0415202e+18 | BT38: t | BV38: 2020 | BW38: SA | BY38: 4.0415202e+18 | BZ38: http://docquery.fec.gov/cgi-bin/fecimg/?201904159146153334 | CA38: Transfers from authorized committees
A39: C00420935 | B39: KEVIN MCCARTHY FOR CONGRESS | C39: 2019 | D39: Q1 | E39: 2.0190416e+17 | F39: 12 | G39: A063DB580FA8A46FEA02 | H39: 1325330 | J39: IND | K39: INDIVIDUAL | N39: MONTAG, THOMAS | O39: H | Q39: P | R39: THOMAS | T39: MONTAG | V39: 127 EAST 73RD STREET | X39: NEW YORK | Y39: NY | Z39: 100213502 | AA39: BANK OF AMERICA | AB39: CHIEF OPERATING OFFICER | AD39: 15J | AE39: MEMO (FILER'S % OF CONTRIBUTION GIVEN TO JOIN | AG39: X | AI39: 43539 | AJ39: 2800 | AK39: 5600 | BG39: G2020 | BI39: GENERAL | BJ39: 2020 | BK39: A | BL39: ADD | BM39: ITEMIZED RECEIPTS | BN39: 43571.117 | BP39: A145338C3F3664A04BD9 | BQ39: SA12 | BR39: F3 | BS39: 4.0415202e+18 | BT39: t | BV39: 2020 | BW39: SA | BY39: 4.0415202e+18 | BZ39: http://docquery.fec.gov/cgi-bin/fecimg/?201904159146153403 | CA39: Transfers from authorized committees
A40: C00428052 | B40: MAJORITY COMMITTEE PAC--MC PAC | C40: 2019 | D40: M4 | E40: 2.0190419e+17 | F40: 12 | G40: A74F88E3483094E1DACA | H40: 1327356 | J40: IND | K40: INDIVIDUAL | N40: MONTAG, THOMAS | O40: Q | Q40: D | R40: THOMAS | T40: MONTAG | V40: 127 E 73RD ST | X40: NEW YORK | Y40: NY | Z40: 100213502 | AA40: CO-CHIEF OPERATING OFFICER | AB40: BANK OF AMERICA CORPORATION | AD40: 15J | AE40: MEMO (FILER'S % OF CONTRIBUTION GIVEN TO JOIN | AG40: X | AI40: 43539 | AJ40: 5000 | AK40: 5000 | BG40: P | BI40: PRIMARY | BK40: A | BL40: ADD | BM40: ITEMIZED RECEIPTS | BN40: 43574.209 | BP40: A177DC506B74B45869CE | BQ40: SA12 | BR40: F3X | BS40: 4.0418202e+18 | BT40: t | BV40: 2020 | BW40: SA | BY40: 4.0418202e+18 | BZ40: http://docquery.fec.gov/cgi-bin/fecimg/?201904189149494895 | CA40: Transfers from Authorized Committees
...

Sheet Paul Donofrio
A1: committee_id | B1: committee_name | C1: report_year | D1: report_type | E1: image_number | F1: line_number | G1: transaction_id | H1: file_number | I1: committee_name | J1: entity_type | K1: entity_type_desc | L1: unused_contbr_id | M1: contributor_prefix | N1: contributor_name | O1: recipient_committee_type | P1: recipient_committee_org_type | Q1: recipient_committee_designation | R1: contributor_first_name | S1: contributor_middle_name | T1: contributor_last_name | U1: contributor_suffix | V1: contributor_street_1 | W1: contributor_street_2 | X1: contributor_city | Y1: contributor_state | Z1: contributor_zip | AA1: contributor_employer | AB1: contributor_occupation | AC1: contributor_id | AD1: receipt_type | AE1: receipt_type_desc | AF1: receipt_type_full | AG1: memo_code | AH1: memo_code_full | AI1: contribution_receipt_date | AJ1: contribution_receipt_amount | AK1: contributor_aggregate_ytd | AL1: candidate_id | AM1: candidate_name | AN1: candidate_first_name | AO1: candidate_last_name | AP1: candidate_middle_name | AQ1: candidate_prefix | AR1: candidate_suffix | AS1: candidate_office | AT1: candidate_office_full | AU1: candidate_office_state | AV1: candidate_office_state_full | AW1: candidate_office_district | AX1: conduit_committee_id | AY1: conduit_committee_name | AZ1: conduit_committee_street1 | BA1: conduit_committee_street2 | BB1: conduit_committee_city | BC1: conduit_committee_state | BD1: conduit_committee_zip | BE1: donor_committee_name | BF1: national_committee_nonfederal_account | BG1: election_type | BH1: election_type_full | BI1: fec_election_type_desc | BJ1: fec_election_year | BK1: amendment_indicator | BL1: amendment_indicator_desc | BM1: schedule_type_full | BN1: load_date | BO1: original_sub_id | BP1: back_reference_transaction_id | BQ1: back_reference_schedule_name | BR1: filing_form | BS1: link_id | BT1: is_individual | BU1: memo_text | BV1: two_year_transaction_period | BW1: schedule_type | BX1: increased_limit | BY1: sub_id | BZ1: pdf_url | CA1: line_number_label
A2: C00364778 | B2: BANK OF AMERICA CORPORATION FEDERAL PAC | C2: 2019 | D2: M8 | E2: 2.0190817e+17 | F2: 11AI | G2: A2019-1508788 | H2: 1348081 | J2: IND | K2: INDIVIDUAL | N2: DONOFRIO, PAUL M | O2: Q | P2: C | Q2: B | R2: PAUL | S2: M | T2: DONOFRIO | V2: ONE BRYANT PARK | X2: NEW YORK | Y2: NY | Z2: 10036 | AA2: BANK OF AMERICA | AB2: CHIEF FINANCIAL OFFICER | AD2: 15 | AE2: CONTRIBUTION | AI2: 43661 | AJ2: 20 | AK2: 260 | BG2: P | BI2: PRIMARY | BK2: A | BL2: ADD | BM2: ITEMIZED RECEIPTS | BN2: 43694.11 | BR2: F3X | BS2: 4.0816202e+18 | BT2: t | BV2: 2020 | BW2: SA | BY2: 4.0816202e+18 | BZ2: http://docquery.fec.gov/cgi-bin/fecimg/?201908169162884507 | CA2: Contributions From Individuals/Persons Other Than Political Committees
A3: C00364778 | B3: BANK OF AMERICA CORPORATION FEDERAL PAC | C3: 2019 | D3: M8 | E3: 2.0190817e+17 | F3: 11AI | G3: A2019-1685727 | H3: 1348081 | J3: IND | K3: INDIVIDUAL | N3: DONOFRIO, PAUL M | O3: Q | P3: C | Q3: B | R3: PAUL | S3: M | T3: DONOFRIO | V3: ONE BRYANT PARK | X3: NEW YORK | Y3: NY | Z3: 10036 | AA3: BANK OF AMERICA | AB3: CHIEF FINANCIAL OFFICER | AD3: 15 | AE3: CONTRIBUTION | AI3: 43677 | AJ3: 20 | AK3: 280 | BG3: P | BI3: PRIMARY | BK3: A | BL3: ADD | BM3: ITEMIZED RECEIPTS | BN3: 43694.11 | BR3: F3X | BS3: 4.0816202e+18 | BT3: t | BV3: 2020 | BW3: SA | BY3: 4.0816202e+18 | BZ3: http://docquery.fec.gov/cgi-bin/fecimg/?201908169162884508 | CA3: Contributions From Individuals/Persons Other Than Political Committees
A4: C00364778 | B4: BANK OF AMERICA CORPORATION FEDERAL PAC | C4: 2019 | D4: YE | E4: 2.0200121e+17 | F4: 11AI | G4: A2019-2943870 | H4: 1371432 | J4: IND | K4: INDIVIDUAL | N4: DONOFRIO, PAUL M | O4: Q | P4: C | Q4: B | R4: PAUL | S4: M | T4: DONOFRIO | V4: ONE BRYANT PARK | X4: NEW YORK | Y4: NY | Z4: 10036 | AA4: BANK OF AMERICA | AB4: CHIEF FINANCIAL OFFICER | AD4: 15 | AE4: CONTRIBUTION | AI4: 43814 | AJ4: 20 | AK4: 460 | BG4: P | BI4: PRIMARY | BK4: A | BL4: ADD | BM4: ITEMIZED RECEIPTS | BN4: 43852.068 | BR4: F3X | BS4: 4.0120202e+18 | BT4: t | BV4: 2020 | BW4: SA | BY4: 4.0121202e+18 | BZ4: http://docquery.fec.gov/cgi-bin/fecimg/?202001209167275125 | CA4: Contributions From Individuals/Persons Other Than Political Committees
A5: C00364778 | B5: BANK OF AMERICA CORPORATION FEDERAL PAC | C5: 2019 | D5: YE | E5: 2.0200121e+17 | F5: 11AI | G5: A2019-2984852 | H5: 1371432 | J5: IND | K5: INDIVIDUAL | N5: DONOFRIO, PAUL M | O5: Q | P5: C | Q5: B | R5: PAUL | S5: M | T5: DONOFRIO | V5: ONE BRYANT PARK | X5: NEW YORK | Y5: NY | Z5: 10036 | AA5: BANK OF AMERICA | AB5: CHIEF FINANCIAL OFFICER | AD5: 15 | AE5: CONTRIBUTION | AI5: 43830 | AJ5: 20 | AK5: 480 | BG5: P | BI5: PRIMARY | BK5: A | BL5: ADD | BM5: ITEMIZED RECEIPTS | BN5: 43852.068 | BR5: F3X | BS5: 4.0120202e+18 | BT5: t | BV5: 2020 | BW5: SA | BY5: 4.0121202e+18 | BZ5: http://docquery.fec.gov/cgi-bin/fecimg/?202001209167275126 | CA5: Contributions From Individuals/Persons Other Than Political Committees
A6: C00364778 | B6: BANK OF AMERICA CORPORATION FEDERAL PAC | C6: 2019 | D6: M7 | E6: 2.0190803e+17 | F6: 11AI | G6: A2019-1192810 | H6: 1346685 | J6: IND | K6: INDIVIDUAL | N6: DONOFRIO, PAUL M | O6: Q | P6: C | Q6: B | R6: PAUL | S6: M | T6: DONOFRIO | V6: ONE BRYANT PARK | X6: NEW YORK | Y6: NY | Z6: 10036 | AA6: BANK OF AMERICA | AB6: CHIEF FINANCIAL OFFICER | AD6: 15 | AE6: CONTRIBUTION | AI6: 43631 | AJ6: 20 | AK6: 220 | BG6: P | BI6: PRIMARY | BK6: N | BL6: NO CHANGE | BM6: ITEMIZED RECEIPTS | BN6: 43680.113 | BR6: F3X | BS6: 4.0802202e+18 | BT6: t | BV6: 2020 | BW6: SA | BY6: 4.0802202e+18 | BZ6: http://docquery.fec.gov/cgi-bin/fecimg/?201908029161351150 | CA6: Contributions From Individuals/Persons Other Than Political Committees
A7: C00364778 | B7: BANK OF AMERICA CORPORATION FEDERAL PAC | C7: 2019 | D7: M7 | E7: 2.0190803e+17 | F7: 11AI | G7: A2019-1380201 | H7: 1346685 | J7: IND | K7: INDIVIDUAL | N7: DONOFRIO, PAUL M | O7: Q | P7: C | Q7: B | R7: PAUL | S7: M | T7: DONOFRIO | V7: ONE BRYANT PARK | X7: NEW YORK | Y7: NY | Z7: 10036 | AA7: BANK OF AMERICA | AB7: CHIEF FINANCIAL OFFICER | AD7: 15 | AE7: CONTRIBUTION | AI7: 43646 | AJ7: 20 | AK7: 240 | BG7: P | BI7: PRIMARY | BK7: N | BL7: NO CHANGE | BM7: ITEMIZED RECEIPTS | BN7: 43680.113 | BR7: F3X | BS7: 4.0802202e+18 | BT7: t | BV7: 2020 | BW7: SA | BY7: 4.0802202e+18 | BZ7: http://docquery.fec.gov/cgi-bin/fecimg/?201908029161351150 | CA7: Contributions From Individuals/Persons Other Than Political Committees
