Workbook

Sheet Board & Executives
A1: Company | B1: Board | C1: Exec | D1: Employer | E1: Fname | F1: MI | G1: Lname | H1: Gender | I1: State | J1: Age | K1: DOB | L1: Dem | M1: Rep | N1: Neu | O1: Reg | P1: Address
A3: Citigroup | B3: Y | C3: N | D3: Former President and Chief Executive Officer, BMO Financial Corporation, and Former U.S. Country Head, BMO Financial Group, Director Diebold Nixdorf, Inc | E3: Ellen | F3: M. | G3: Costello | H3: F | I3: IL? | J3: 66 | O3: D | Q3: =+E3&F3&G3 -> Ellen M. Costello | R3: No FEC Data
A4: Citigroup | B4: Y | C4: N | D4: Former Senior Deputy Comptroller for Bank Supervision Policy and Chief National Bank Examiner, Office of the Comptroller of the Currency | E4: Grace | F4: E. | G4: Dailey | H4: F | I4: DC? | J4: 60 | Q4: =+E4&F4&G4 -> Grace E. Dailey | R4: No FEC Data
A5: Citigroup | B5: Y | C5: N | D5: Chair | E5: Barbara | F5: J. | G5: Desoer | H5: F | I5: NY | J5: 68 | K5: 1953 | N5: =+GETPIVOTDATA("contribution_receipt_amount",'Barbara Desoer'!$A$9) -> 15000 | O5: R | P5: 300 E 56TH ST NEW YORK NY 100224146 | Q5: =+E5&F5&G5 -> Barbara J. Desoer
A6: Citigroup | B6: Y | C6: N | D6: Chair | E6: John | F6: C. | G6: Dugan | H6: M | I6: DC? | J6: 65 | K6: 20243 | Q6: =+E6&F6&G6 -> John C. Dugan | R6: No FEC Data
A7: Citigroup | B7: Y | C7: Y | D7: Chief Executive Officer | E7: Jane | F7: N. | G7: Fraser | H7: F | I7: FL | J7: 53 | L7: =+'JANE FRASER'!D250 -> 5831.5 | M7: =+'JANE FRASER'!D251 -> 1568.5 | N7: =+'JANE FRASER'!D252 -> 9422.7 | O7: D | P7: 201 S. BISCAYNE BLVD. MIAMI FL 33131 | Q7: =+E7&F7&G7 -> Jane N. Fraser
A8: Citigroup | B8: Y | C8: N | D8: Co-Founder and Partner Atrevida Partners, LLC | E8: Duncan | F8: P. | G8: Hennes | H8: M | I8: NY | J8: 64 | O8: R | P8: 170 Stuyvesant Ave, Rye NY 10580 | Q8: =+E8&F8&G8 -> Duncan P. Hennes | R8: No FEC Data
A9: Citigroup | B9: Y | C9: N | D9: Dean Emeritus and W. R. Berkley Professor of Economics and Finance, New York University, Leonard N. Stern School of Business | E9: Peter | F9: B. | G9: Henry | H9: M | I9: NY | J9: 51 | O9: D | P9: 14 Washington Mews,NY,NY 10003 | Q9: =+E9&F9&G9 -> Peter B. Henry | R9: No FEC Data
A10: Citigroup | B10: Y | C10: N | D10: Former Assistant Secretary for Intelligence and Analysis, U.S. Department of the Treasury, and National Intelligence Manager for Threat Finance, Office of the Director of National Intelligence | E10: S. | F10: Leslie | G10: Ireland | H10: F | I10: NY | J10: 61 | K10: 1959 | Q10: =+E10&F10&G10 -> S. Leslie Ireland | R10: No FEC Data
A11: Citigroup | B11: Y | C11: N | D11: Former President and Managing Director, Pacific Investment Management Company LLC (PIMCO) | E11: Lew | F11: W. (Jay) | G11: Jacobs, IV | H11: M | I11: MO | J11: 50 | Q11: =+E11&F11&G11 -> Lew W. (Jay) Jacobs, IV | R11: No FEC Data
A12: Citigroup | B12: Y | C12: N | D12: Founder, Chairman and CEO, Ampere Computing | E12: Renée | F12: J. | G12: James | H12: F | I12: OR | J12: 56 | K12: 1964 | O12: D | P12: 4422 SW Carl Pl, Portland 97239 | Q12: =+E12&F12&G12 -> Renée J. James | R12: No FEC Data
A13: Citigroup | B13: Y | C13: N | D13: Operating Partner General Atlantic LLC | E13: Gary | F13: M. | G13: Reiner | H13: M | I13: NY | J13: 66 | K13: 1954 | Q13: =+E13&F13&G13 -> Gary M. Reiner | R13: No FEC Data
A14: Citigroup | B14: Y | C14: N | D14: Former Superintendent of Banks, State of New York | E14: Diana | F14: L. | G14: Taylor | H14: F | I14: MA | J14: 66 | L14: =+GETPIVOTDATA("contribution_receipt_amount",'Diana Taylor'!$A$454) -> 15919.78 | O14: D | P14: 75 CAMBRIDGE PKWY CAMBRIDGE MA 21421229 | Q14: =+E14&F14&G14 -> Diana L. Taylor
A15: Citigroup | B15: Y | C15: N | D15: Former Chairman and CEO Ernst & Young | E15: James | F15: S. | G15: Turley | H15: M | I15: MO | J15: 65 | O15: R | P15: 9 Muirfield Ln, Saint Louis MO 63141 | Q15: =+E15&F15&G15 -> James S. Turley | R15: No FEC Data
A16: Citigroup | B16: Y | C16: N | D16: Former Chairman Carver Bancorp, Inc. | E16: Deborah | F16: C. | G16: Wright | H16: F | I16: NY | J16: 63 | L16: =+GETPIVOTDATA("contribution_receipt_amount",'Deborah Wright'!$A$15) -> 1364.78 | O16: D | P16: 285 W 110TH ST NEW YORK NY 100264299 | Q16: =+E16&F16&G16 -> Deborah C. Wright
A17: Citigroup | B17: Y | C17: N | D17: Former Chief Executive Officer and Chairman of the Executive Board Aegon NV | E17: Alexander | F17: R. | G17: Wynaendts | H17: M | I17: Hague Nethrelands | J17: 60 | Q17: =+E17&F17&G17 -> Alexander R. Wynaendts | R17: No FEC Data
A18: Citigroup | B18: Y | C18: N | D18: Director, Center for the Study of Globalization and Professor in the Field of International Economics and Politics, Yale University | E18: Ernesto Zedillo | G18: Ponce de Leon | H18: M | I18: Mexico | J18: 69 | Q18: =+E18&F18&G18 -> Ernesto Zedillo Ponce de Leon | R18: No FEC Data
A19: Citigroup | B19: N | C19: Y | D19: Former chief executive officer of Citigroup | E19: Michael | G19: Corbat | H19: M | I19: NY | J19: 61 | K19: 22038 | N19: =+GETPIVOTDATA("contribution_receipt_amount",'Michael Corbat'!$A$6) -> 10000 | P19: 388 GREENWICH STREET NEW YORK NY 10013 | Q19: =+E19&F19&G19 -> Michael Corbat
A20: Citigroup | B20: N | C20: Y | D20: Chief Financial Officer | E20: Mark | G20: Mason | H20: M | I20: NJ | N20: =+GETPIVOTDATA("contribution_receipt_amount",'Mark Mason'!$A$54) -> 9615 | O20: D | P20: 235 Tillou Rd, South Orange NJ 07079 | Q20: =+E20&F20&G20 -> Mark Mason
A21: Citigroup | B21: N | C21: Y | D21: Chief Executive Officer Institutional Clients Group | E21: Paco | G21: Ybarra | H21: M | I21: London England | Q21: =+E21&F21&G21 -> Paco Ybarra | R21: No FEC Data
A22: Citigroup | B22: N | C22: Y | D22: Head of Enterprise Operations & Technology | E22: Michael | G22: Whitaker | H22: M | I22: London England | Q22: =+E22&F22&G22 -> Michael Whitaker | R22: No FEC Data

Sheet Mark Mason
A1: committee_id | B1: committee_name | C1: report_year | D1: report_type | E1: image_number | F1: line_number | G1: transaction_id | H1: file_number | I1: committee_name | J1: entity_type | K1: entity_type_desc | L1: unused_contbr_id | M1: contributor_prefix | N1: contributor_name | O1: recipient_committee_type | P1: recipient_committee_org_type | Q1: recipient_committee_designation | R1: contributor_first_name | S1: contributor_middle_name | T1: contributor_last_name | U1: contributor_suffix | V1: contributor_street_1 | W1: contributor_street_2 | X1: contributor_city | Y1: contributor_state | Z1: contributor_zip | AA1: contributor_employer | AB1: contributor_occupation | AC1: contributor_id | AD1: receipt_type | AE1: receipt_type_desc | AF1: receipt_type_full | AG1: memo_code | AH1: memo_code_full | AI1: contribution_receipt_date | AJ1: contribution_receipt_amount | AK1: contributor_aggregate_ytd | AL1: candidate_id | AM1: candidate_name | AN1: candidate_first_name | AO1: candidate_last_name | AP1: candidate_middle_name | AQ1: candidate_prefix | AR1: candidate_suffix | AS1: candidate_office | AT1: candidate_office_full | AU1: candidate_office_state | AV1: candidate_office_state_full | AW1: candidate_office_district | AX1: conduit_committee_id | AY1: conduit_committee_name | AZ1: conduit_committee_street1 | BA1: conduit_committee_street2 | BB1: conduit_committee_city | BC1: conduit_committee_state | BD1: conduit_committee_zip | BE1: donor_committee_name | BF1: national_committee_nonfederal_account | BG1: election_type | BH1: election_type_full | BI1: fec_election_type_desc | BJ1: fec_election_year | BK1: amendment_indicator | BL1: amendment_indicator_desc | BM1: schedule_type_full | BN1: load_date | BO1: original_sub_id | BP1: back_reference_transaction_id | BQ1: back_reference_schedule_name | BR1: filing_form | BS1: link_id | BT1: is_individual | BU1: memo_text | BV1: two_year_transaction_period | BW1: schedule_type | BX1: increased_limit | BY1: sub_id | BZ1: pdf_url | CA1: line_number_label
A2: C00008474 | B2: CITIGROUP INC. POLITICAL ACTION COMMITTEE - FEDERAL (CITIGROUP PAC-FEDERAL) | C2: 2019 | D2: M2 | E2: 2.0191121e+17 | F2: 11AI | G2: A2019-26284 | H2: 1364266 | J2: IND | K2: INDIVIDUAL | N2: MASON, MARK | O2: Q | P2: C | Q2: B | R2: MARK | T2: MASON | V2: 388 GREENWICH ST | X2: NEW YORK | Y2: NY | Z2: 100132375 | AA2: CITIGROUP MANAGEMENT CORP | AB2: MANAGING DIRECTOR | AD2: 15 | AE2: CONTRIBUTION | AI2: 43483 | AJ2: 192.3 | AK2: 384.6 | BG2: P | BI2: PRIMARY | BK2: N | BL2: NO CHANGE | BM2: ITEMIZED RECEIPTS | BN2: 43792.075 | BR2: F3X | BS2: 4.1120202e+18 | BT2: t | BV2: 2020 | BW2: SA | BY2: 4.1122202e+18 | BZ2: http://docquery.fec.gov/cgi-bin/fecimg/?201911209165881175 | CA2: Contributions From Individuals/Persons Other Than Political Committees
A3: C00008474 | B3: CITIGROUP INC. POLITICAL ACTION COMMITTEE - FEDERAL (CITIGROUP PAC-FEDERAL) | C3: 2019 | D3: M11 | E3: 2.0191121e+17 | F3: 11AI | G3: A2019-2461445 | H3: 1364299 | J3: IND | K3: INDIVIDUAL | N3: MASON, MARK | O3: Q | P3: C | Q3: B | R3: MARK | T3: MASON | V3: 388 GREENWICH STREET | X3: NEW YORK | Y3: NY | Z3: 10013 | AA3: CITIBANK N.A. | AB3: MANAGING DIRECTOR | AD3: 15 | AE3: CONTRIBUTION | AI3: 43756 | AJ3: 192.3 | AK3: 4038.3 | BG3: P | BI3: PRIMARY | BK3: A | BL3: ADD | BM3: ITEMIZED RECEIPTS | BN3: 43793.08 | BR3: F3X | BS3: 4.1122202e+18 | BT3: t | BV3: 2020 | BW3: SA | BY3: 4.1123202e+18 | BZ3: http://docquery.fec.gov/cgi-bin/fecimg/?201911209165926308 | CA3: Contributions From Individuals/Persons Other Than Political Committees
A4: C00008474 | B4: CITIGROUP INC. POLITICAL ACTION COMMITTEE - FEDERAL (CITIGROUP PAC-FEDERAL) | C4: 2019 | D4: M4 | E4: 2.0191122e+17 | F4: 11AI | G4: A2019-377666 | H4: 1364444 | J4: IND | K4: INDIVIDUAL | N4: MASON, MARK | O4: Q | P4: C | Q4: B | R4: MARK | T4: MASON | V4: 388 GREENWICH ST | X4: NEW YORK | Y4: NY | Z4: 100132375 | AA4: CITIGROUP MANAGEMENT CORP | AB4: MANAGING DIRECTOR | AD4: 15 | AE4: CONTRIBUTION | AI4: 43525 | AJ4: 192.3 | AK4: 961.5 | BG4: P | BI4: PRIMARY | BK4: N | BL4: NO CHANGE | BM4: ITEMIZED RECEIPTS | BN4: 43793.082 | BR4: F3X | BS4: 4.1123202e+18 | BT4: t | BV4: 2020 | BW4: SA | BY4: 4.1123202e+18 | BZ4: http://docquery.fec.gov/cgi-bin/fecimg/?201911219166031799 | CA4: Contributions From Individuals/Persons Other Than Political Committees
A5: C00008474 | B5: CITIGROUP INC. POLITICAL ACTION COMMITTEE - FEDERAL (CITIGROUP PAC-FEDERAL) | C5: 2019 | D5: M11 | E5: 2.0191121e+17 | F5: 11AI | G5: A2019-2289143 | H5: 1364299 | J5: IND | K5: INDIVIDUAL | N5: MASON, MARK | O5: Q | P5: C | Q5: B | R5: MARK | T5: MASON | V5: 388 GREENWICH STREET | X5: NEW YORK | Y5: NY | Z5: 10013 | AA5: CITIBANK N.A. | AB5: MANAGING DIRECTOR | AD5: 15 | AE5: CONTRIBUTION | AI5: 43742 | AJ5: 192.3 | AK5: 3846 | BG5: P | BI5: PRIMARY | BK5: A | BL5: ADD | BM5: ITEMIZED RECEIPTS | BN5: 43793.08 | BR5: F3X | BS5: 4.1122202e+18 | BT5: t | BV5: 2020 | BW5: SA | BY5: 4.1123202e+18 | BZ5: http://docquery.fec.gov/cgi-bin/fecimg/?201911209165926308 | CA5: Contributions From Individuals/Persons Other Than Political Committees
A6: C00008474 | B6: CITIGROUP INC. POLITICAL ACTION COMMITTEE - FEDERAL (CITIGROUP PAC-FEDERAL) | C6: 2019 | D6: M3 | E6: 2.0191122e+17 | F6: 11AI | G6: A2019-93129 | H6: 1364440 | J6: IND | K6: INDIVIDUAL | N6: MASON, MARK | O6: Q | P6: C | Q6: B | R6: MARK | T6: MASON | V6: 388 GREENWICH ST | X6: NEW YORK | Y6: NY | Z6: 100132375 | AA6: CITIGROUP MANAGEMENT CORP | AB6: MANAGING DIRECTOR | AD6: 15 | AE6: CONTRIBUTION | AI6: 43497 | AJ6: 192.3 | AK6: 576.9 | BG6: P | BI6: PRIMARY | BK6: N | BL6: NO CHANGE | BM6: ITEMIZED RECEIPTS | BN6: 43793.082 | BR6: F3X | BS6: 4.1123202e+18 | BT6: t | BV6: 2020 | BW6: SA | BY6: 4.1123202e+18 | BZ6: http://docquery.fec.gov/cgi-bin/fecimg/?201911219166031597 | CA6: Contributions From Individuals/Persons Other Than Political Committees
A7: C00008474 | B7: CITIGROUP INC. POLITICAL ACTION COMMITTEE - FEDERAL (CITIGROUP PAC-FEDERAL) | C7: 2019 | D7: M3 | E7: 2.0191122e+17 | F7: 11AI | G7: A2019-271750 | H7: 1364440 | J7: IND | K7: INDIVIDUAL | N7: MASON, MARK | O7: Q | P7: C | Q7: B | R7: MARK | T7: MASON | V7: 388 GREENWICH ST | X7: NEW YORK | Y7: NY | Z7: 100132375 | AA7: CITIGROUP MANAGEMENT CORP | AB7: MANAGING DIRECTOR | AD7: 15 | AE7: CONTRIBUTION | AI7: 43511 | AJ7: 192.3 | AK7: 769.2 | BG7: P | BI7: PRIMARY | BK7: N | BL7: NO CHANGE | BM7: ITEMIZED RECEIPTS | BN7: 43793.082 | BR7: F3X | BS7: 4.1123202e+18 | BT7: t | BV7: 2020 | BW7: SA | BY7: 4.1123202e+18 | BZ7: http://docquery.fec.gov/cgi-bin/fecimg/?201911219166031598 | CA7: Contributions From Individuals/Persons Other Than Political Committees
A8: C00008474 | B8: CITIGROUP INC. POLITICAL ACTION COMMITTEE - FEDERAL (CITIGROUP PAC-FEDERAL) | C8: 2019 | D8: M4 | E8: 2.0191122e+17 | F8: 11AI | G8: A2019-523875 | H8: 1364444 | J8: IND | K8: INDIVIDUAL | N8: MASON, MARK | O8: Q | P8: C | Q8: B | R8: MARK | T8: MASON | V8: 388 GREENWICH ST | X8: NEW YORK | Y8: NY | Z8: 100132375 | AA8: CITIGROUP MANAGEMENT CORP | AB8: MANAGING DIRECTOR | AD8: 15 | AE8: CONTRIBUTION | AI8: 43539 | AJ8: 192.3 | AK8: 1153.8 | BG8: P | BI8: PRIMARY | BK8: N | BL8: NO CHANGE | BM8: ITEMIZED RECEIPTS | BN8: 43793.082 | BR8: F3X | BS8: 4.1123202e+18 | BT8: t | BV8: 2020 | BW8: SA | BY8: 4.1123202e+18 | BZ8: http://docquery.fec.gov/cgi-bin/fecimg/?201911219166031799 | CA8: Contributions From Individuals/Persons Other Than Political Committees
A9: C00008474 | B9: CITIGROUP INC. POLITICAL ACTION COMMITTEE - FEDERAL (CITIGROUP PAC-FEDERAL) | C9: 2019 | D9: M5 | E9: 2.0191122e+17 | F9: 11AI | G9: A2019-591861 | H9: 1364454 | J9: IND | K9: INDIVIDUAL | N9: MASON, MARK | O9: Q | P9: C | Q9: B | R9: MARK | T9: MASON | V9: 388 GREENWICH STREET | X9: NEW YORK | Y9: NY | Z9: 10013 | AA9: CITIBANK N.A. | AB9: MANAGING DIRECTOR | AD9: 15 | AE9: CONTRIBUTION | AI9: 43560 | AJ9: 192.3 | AK9: 1346.1 | BG9: P | BI9: PRIMARY | BK9: N | BL9: NO CHANGE | BM9: ITEMIZED RECEIPTS | BN9: 43793.086 | BR9: F3X | BS9: 4.1123202e+18 | BT9: t | BV9: 2020 | BW9: SA | BY9: 4.1123202e+18 | BZ9: http://docquery.fec.gov/cgi-bin/fecimg/?201911219166069822 | CA9: Contributions From Individuals/Persons Other Than Political Committees
A10: C00008474 | B10: CITIGROUP INC. POLITICAL ACTION COMMITTEE - FEDERAL (CITIGROUP PAC-FEDERAL) | C10: 2019 | D10: M5 | E10: 2.0191122e+17 | F10: 11AI | G10: A2019-804441 | H10: 1364454 | J10: IND | K10: INDIVIDUAL | N10: MASON, MARK | O10: Q | P10: C | Q10: B | R10: MARK | T10: MASON | V10: 388 GREENWICH STREET | X10: NEW YORK | Y10: NY | Z10: 10013 | AA10: CITIBANK N.A. | AB10: MANAGING DIRECTOR | AD10: 15 | AE10: CONTRIBUTION | AI10: 43574 | AJ10: 192.3 | AK10: 1538.4 | BG10: P | BI10: PRIMARY | BK10: N | BL10: NO CHANGE | BM10: ITEMIZED RECEIPTS | BN10: 43793.086 | BR10: F3X | BS10: 4.1123202e+18 | BT10: t | BV10: 2020 | BW10: SA | BY10: 4.1123202e+18 | BZ10: http://docquery.fec.gov/cgi-bin/fecimg/?201911219166069823 | CA10: Contributions From Individuals/Persons Other Than Political Committees
A11: C00008474 | B11: CITIGROUP INC. POLITICAL ACTION COMMITTEE - FEDERAL (CITIGROUP PAC-FEDERAL) | C11: 2019 | D11: M7 | E11: 2.0191122e+17 | F11: 11AI | G11: A2019-1264055 | H11: 1364461 | J11: IND | K11: INDIVIDUAL | N11: MASON, MARK | O11: Q | P11: C | Q11: B | R11: MARK | T11: MASON | V11: 388 GREENWICH STREET | X11: NEW YORK | Y11: NY | Z11: 10013 | AA11: CITIBANK N.A. | AB11: MANAGING DIRECTOR | AD11: 15 | AE11: CONTRIBUTION | AI11: 43630 | AJ11: 192.3 | AK11: 2307.6 | BG11: P | BI11: PRIMARY | BK11: N | BL11: NO CHANGE | BM11: ITEMIZED RECEIPTS | BN11: 43793.086 | BR11: F3X | BS11: 4.1123202e+18 | BT11: t | BV11: 2020 | BW11: SA | BY11: 4.1123202e+18 | BZ11: http://docquery.fec.gov/cgi-bin/fecimg/?201911219166070440 | CA11: Contributions From Individuals/Persons Other Than Political Committees
A12: C00008474 | B12: CITIGROUP INC. POLITICAL ACTION COMMITTEE - FEDERAL (CITIGROUP PAC-FEDERAL) | C12: 2019 | D12: M7 | E12: 2.0191122e+17 | F12: 11AI | G12: A2019-1404079 | H12: 1364461 | J12: IND | K12: INDIVIDUAL | N12: MASON, MARK | O12: Q | P12: C | Q12: B | R12: MARK | T12: MASON | V12: 388 GREENWICH STREET | X12: NEW YORK | Y12: NY | Z12: 10013 | AA12: CITIBANK N.A. | AB12: MANAGING DIRECTOR | AD12: 15 | AE12: CONTRIBUTION | AI12: 43644 | AJ12: 192.3 | AK12: 2499.9 | BG12: P | BI12: PRIMARY | BK12: N | BL12: NO CHANGE | BM12: ITEMIZED RECEIPTS | BN12: 43793.086 | BR12: F3X | BS12: 4.1123202e+18 | BT12: t | BV12: 2020 | BW12: SA | BY12: 4.1123202e+18 | BZ12: http://docquery.fec.gov/cgi-bin/fecimg/?201911219166070440 | CA12: Contributions From Individuals/Persons Other Than Political Committees
A13: C00008474 | B13: CITIGROUP INC. POLITICAL ACTION COMMITTEE - FEDERAL (CITIGROUP PAC-FEDERAL) | C13: 2019 | D13: M10 | E13: 2.0191122e+17 | F13: 11AI | G13: A2019-1996396 | H13: 1364475 | J13: IND | K13: INDIVIDUAL | N13: MASON, MARK | O13: Q | P13: C | Q13: B | R13: MARK | T13: MASON | V13: 388 GREENWICH STREET | X13: NEW YORK | Y13: NY | Z13: 10013 | AA13: CITIBANK N.A. | AB13: MANAGING DIRECTOR | AD13: 15 | AE13: CONTRIBUTION | AI13: 43714 | AJ13: 192.3 | AK13: 3461.4 | BG13: P | BI13: PRIMARY | BK13: N | BL13: NO CHANGE | BM13: ITEMIZED RECEIPTS | BN13: 43793.087 | BR13: F3X | BS13: 4.1123202e+18 | BT13: t | BV13: 2020 | BW13: SA | BY13: 4.1123202e+18 | BZ13: http://docquery.fec.gov/cgi-bin/fecimg/?201911219166072938 | CA13: Contributions From Individuals/Persons Other Than Political Committees
... A51: C00008474 | B51: CITIGROUP INC. POLITICAL ACTION COMMITTEE - FEDERAL (CITIGROUP PAC-FEDERAL) | C51: 2020 | D51: 12G | E51: 2.0201023e+17 | F51: 11AI | G51: A2020-2154184 | H51: 1462787 | J51: IND | K51: INDIVIDUAL | N51: MASON, MARK | O51: Q | P51: C | Q51: B | R51: MARK | T51: MASON | V51: 388 GREENWICH STREET | X51: NEW YORK | Y51: NY | Z51: 10013 | AA51: CITIBANK N.A. | AB51: MANAGING DIRECTOR | AD51: 15 | AE51: CONTRIBUTION | AI51: 44106 | AJ51: 192.3 | AK51: 3846 | BG51: P | BI51: PRIMARY | BK51: A | BL51: ADD | BM51: ITEMIZED RECEIPTS | BN51: 44169.187 | BR51: F3X | BS51: 4.1023202e+18 | BT51: t | BV51: 2020 | BW51: SA | BY51: 4.1204202e+18 | BZ51: http://docquery.fec.gov/cgi-bin/fecimg/?202010229333029497 | CA51: Contributions From Individuals/Persons Other Than Political Committees
V53: =+V51&X51&Y51&Z51 -> 388 GREENWICH STREETNEW YORKNY10013
A54: Row Labels | B54: Sum of contribution_receipt_amount
A55: CITIGROUP INC. POLITICAL ACTION COMMITTEE - FEDERAL (CITIGROUP PAC-FEDERAL) | B55: 9615
A56: Grand Total | B56: 9615

Sheet Michael Corbat
A1: committee_id | B1: committee_name | C1: report_year | D1: report_type | E1: image_number | F1: line_number | G1: transaction_id | H1: file_number | I1: committee_name | J1: entity_type | K1: entity_type_desc | L1: unused_contbr_id | M1: contributor_prefix | N1: contributor_name | O1: recipient_committee_type | P1: recipient_committee_org_type | Q1: recipient_committee_designation | R1: contributor_first_name | S1: contributor_middle_name | T1: contributor_last_name | U1: contributor_suffix | V1: contributor_street_1 | W1: contributor_street_2 | X1: contributor_city | Y1: contributor_state | Z1: contributor_zip | AA1: contributor_employer | AB1: contributor_occupation | AC1: contributor_id | AD1: receipt_type | AE1: receipt_type_desc | AF1: receipt_type_full | AG1: memo_code | AH1: memo_code_full | AI1: contribution_receipt_date | AJ1: contribution_receipt_amount | AK1: contributor_aggregate_ytd | AL1: candidate_id | AM1: candidate_name | AN1: candidate_first_name | AO1: candidate_last_name | AP1: candidate_middle_name | AQ1: candidate_prefix | AR1: candidate_suffix | AS1: candidate_office | AT1: candidate_office_full | AU1: candidate_office_state | AV1: candidate_office_state_full | AW1: candidate_office_district | AX1: conduit_committee_id | AY1: conduit_committee_name | AZ1: conduit_committee_street1 | BA1: conduit_committee_street2 | BB1: conduit_committee_city | BC1: conduit_committee_state | BD1: conduit_committee_zip | BE1: donor_committee_name | BF1: national_committee_nonfederal_account | BG1: election_type | BH1: election_type_full | BI1: fec_election_type_desc | BJ1: fec_election_year | BK1: amendment_indicator | BL1: amendment_indicator_desc | BM1: schedule_type_full | BN1: load_date | BO1: original_sub_id | BP1: back_reference_transaction_id | BQ1: back_reference_schedule_name | BR1: filing_form | BS1: link_id | BT1: is_individual | BU1: memo_text | BV1: two_year_transaction_period | BW1: schedule_type | BX1: increased_limit | BY1: sub_id | BZ1: pdf_url | CA1: line_number_label
A2: C00008474 | B2: CITIGROUP INC. POLITICAL ACTION COMMITTEE - FEDERAL (CITIGROUP PAC-FEDERAL) | C2: 2019 | D2: M5 | E2: 2.0191122e+17 | F2: 11AI | G2: A2019-841516 | H2: 1364454 | J2: IND | K2: INDIVIDUAL | N2: CORBAT, MICHAEL L | O2: Q | P2: C | Q2: B | R2: MICHAEL | S2: L | T2: CORBAT | V2: 388 GREENWICH STREET | X2: NEW YORK | Y2: NY | Z2: 10013 | AA2: CITIBANK N.A. | AB2: MANAGING DIRECTOR | AD2: 15 | AE2: CONTRIBUTION | AI2: 43566 | AJ2: 5000 | AK2: 5000 | BG2: P | BI2: PRIMARY | BK2: N | BL2: NO CHANGE | BM2: ITEMIZED RECEIPTS | BN2: 43793.086 | BR2: F3X | BS2: 4.1123202e+18 | BT2: t | BV2: 2020 | BW2: SA | BY2: 4.1123202e+18 | BZ2: http://docquery.fec.gov/cgi-bin/fecimg/?201911219166069773 | CA2: Contributions From Individuals/Persons Other Than Political Committees
A3: C00008474 | B3: CITIGROUP INC. POLITICAL ACTION COMMITTEE - FEDERAL (CITIGROUP PAC-FEDERAL) | C3: 2020 | D3: YE | E3: 2.021013e+17 | F3: 11AI | G3: A2020-2624038 | H3: 1494727 | J3: IND | K3: INDIVIDUAL | N3: CORBAT, MICHAEL L | O3: Q | P3: C | Q3: B | R3: MICHAEL | S3: L | T3: CORBAT | V3: 388 GREENWICH STREET | X3: NEW YORK | Y3: NY | Z3: 10013 | AA3: CITIBANK N.A. | AB3: MANAGING DIRECTOR | AD3: 15 | AE3: CONTRIBUTION | AI3: 44160 | AJ3: 5000 | AK3: 5000 | BG3: P | BI3: PRIMARY | BK3: A | BL3: ADD | BM3: ITEMIZED RECEIPTS | BN3: 44230.156 | BR3: F3X | BS3: 4.0130202e+18 | BT3: t | BV3: 2020 | BW3: SA | BY3: 4.0203202e+18 | BZ3: https://docquery.fec.gov/cgi-bin/fecimg/?202101299418056947 | CA3: Contributions From Individuals/Persons Other Than Political Committees
A6: Row Labels | B6: Sum of contribution_receipt_amount | D6: D | E6: R | V6: =+V3&X3&Y3&Z3 -> 388 GREENWICH STREETNEW YORKNY10013
A7: CITIGROUP INC. POLITICAL ACTION COMMITTEE - FEDERAL (CITIGROUP PAC-FEDERAL) | B7: 10000 | C7: N | D7: 0.4381 | E7: 0.5619
A8: Grand Total | B8: 10000

Sheet Deborah Wright
A1: committee_id | B1: committee_name | C1: report_year | D1: report_type | E1: image_number | F1: line_number | G1: transaction_id | H1: file_number | I1: committee_name | J1: entity_type | K1: entity_type_desc | L1: unused_contbr_id | M1: contributor_prefix | N1: contributor_name | O1: recipient_committee_type | P1: recipient_committee_org_type | Q1: recipient_committee_designation | R1: contributor_first_name | S1: contributor_middle_name | T1: contributor_last_name | U1: contributor_suffix | V1: contributor_street_1 | W1: contributor_street_2 | X1: contributor_city | Y1: contributor_state | Z1: contributor_zip | AA1: contributor_employer | AB1: contributor_occupation | AC1: contributor_id | AD1: receipt_type | AE1: receipt_type_desc | AF1: receipt_type_full | AG1: memo_code | AH1: memo_code_full | AI1: contribution_receipt_date | AJ1: contribution_receipt_amount | AK1: contributor_aggregate_ytd | AL1: candidate_id | AM1: candidate_name | AN1: candidate_first_name | AO1: candidate_last_name | AP1: candidate_middle_name | AQ1: candidate_prefix | AR1: candidate_suffix | AS1: candidate_office | AT1: candidate_office_full | AU1: candidate_office_state | AV1: candidate_office_state_full | AW1: candidate_office_district | AX1: conduit_committee_id | AY1: conduit_committee_name | AZ1: conduit_committee_street1 | BA1: conduit_committee_street2 | BB1: conduit_committee_city | BC1: conduit_committee_state | BD1: conduit_committee_zip | BE1: donor_committee_name | BF1: national_committee_nonfederal_account | BG1: election_type | BH1: election_type_full | BI1: fec_election_type_desc | BJ1: fec_election_year | BK1: amendment_indicator | BL1: amendment_indicator_desc | BM1: schedule_type_full | BN1: load_date | BO1: original_sub_id | BP1: back_reference_transaction_id | BQ1: back_reference_schedule_name | BR1: filing_form | BS1: link_id | BT1: is_individual | BU1: memo_text | BV1: two_year_transaction_period | BW1: schedule_type | BX1: increased_limit | BY1: sub_id | BZ1: pdf_url | CA1: line_number_label
A2: C00744946 | B2: BIDEN VICTORY FUND | C2: 2020 | D2: 12G | E2: 2.0210309e+17 | F2: 11AI | G2: 20405806 | H2: 1503262 | J2: IND | K2: INDIVIDUAL | N2: WRIGHT, DEBORAH | O2: N | Q2: J | R2: DEBORAH | T2: WRIGHT | V2: 285 W 110TH ST | X2: NEW YORK | Y2: NY | Z2: 100264299 | AA2: CITIGROUP | AB2: BOARD MEMBER | AD2: 15 | AE2: CONTRIBUTION | AI2: 44111 | AJ2: 14.56 | AK2: 932.39 | BG2: P | BI2: PRIMARY | BK2: A | BL2: ADD | BM2: ITEMIZED RECEIPTS | BN2: 44329.167 | BR2: F3X | BS2: 4.0309202e+18 | BT2: t | BV2: 2020 | BW2: SA | BY2: 4.0309202e+18 | BZ2: https://docquery.fec.gov/cgi-bin/fecimg/?202103089440336576 | CA2: Contributions From Individuals/Persons Other Than Political Committees
A3: C00703975 | B3: BIDEN FOR PRESIDENT | C3: 2020 | E3: 2.0201022e+17 | F3: 18 | G3: 21887143 | H3: 1458940 | J3: IND | K3: INDIVIDUAL | N3: WRIGHT, DEBORAH | O3: P | Q3: P | R3: DEBORAH | T3: WRIGHT | V3: 285 W 110TH ST | W3: APT 7F | X3: NEW YORK | Y3: NY | Z3: 100264299 | AA3: CITIGROUP | AB3: BOARD MEMBER | AD3: 15J | AE3: MEMO (FILER'S % OF CONTRIBUTION GIVEN TO JOIN | AG3: X | AI3: 44089 | AJ3: 250 | AK3: 917.83 | BG3: G2020 | BI3: GENERAL | BJ3: 2020 | BK3: A | BL3: ADD | BM3: ITEMIZED RECEIPTS | BN3: 44140.217 | BP3: 20811179 | BQ3: SA18 | BR3: F3P | BS3: 4.1022202e+18 | BT3: t | BU3: * BIDEN VICTORY FUND | BV3: 2020 | BW3: SA | BY3: 4.1023202e+18 | BZ3: http://docquery.fec.gov/cgi-bin/fecimg/?202010219326733310 | CA3: Transfers From Other Authorized Committees
A4: C00703975 | B4: BIDEN FOR PRESIDENT | C4: 2020 | D4: 12G | E4: 2.0201023e+17 | F4: 18 | G4: 24798128 | H4: 1463690 | J4: IND | K4: INDIVIDUAL | N4: WRIGHT, DEBORAH | O4: P | Q4: P | R4: DEBORAH | T4: WRIGHT | V4: 285 W 110TH ST | W4: APT 7F | X4: NEW YORK | Y4: NY | Z4: 100264299 | AA4: CITIGROUP | AB4: BOARD MEMBER | AD4: 15J | AE4: MEMO (FILER'S % OF CONTRIBUTION GIVEN TO JOIN | AG4: X | AI4: 44111 | AJ4: 14.56 | AK4: 932.39 | BG4: G2020 | BI4: GENERAL | BJ4: 2020 | BK4: A | BL4: ADD | BM4: ITEMIZED RECEIPTS | BN4: 44132.2 | BP4: 20811384 | BQ4: SA18 | BR4: F3P | BS4: 4.1024202e+18 | BT4: t | BU4: * BIDEN VICTORY FUND | BV4: 2020 | BW4: SA | BY4: 4.1028202e+18 | BZ4: http://docquery.fec.gov/cgi-bin/fecimg/?202010229336171829 | CA4: Transfers From Other Authorized Committees
A5: C00703975 | B5: BIDEN FOR PRESIDENT | C5: 2020 | E5: 2.0201022e+17 | F5: 18 | G5: 17056815 | H5: 1458940 | J5: IND | K5: INDIVIDUAL | N5: WRIGHT, DEBORAH | O5: P | Q5: P | R5: DEBORAH | T5: WRIGHT | V5: 285 W 110TH ST | W5: APT 7F | X5: NEW YORK | Y5: NY | Z5: 100264299 | AA5: CITIGROUP | AB5: BOARD MEMBER | AD5: 15J | AE5: MEMO (FILER'S % OF CONTRIBUTION GIVEN TO JOIN | AG5: X | AI5: 44055 | AJ5: 124.58 | AK5: 624.58 | BG5: P2020 | BI5: PRIMARY | BJ5: 2020 | BK5: A | BL5: ADD | BM5: ITEMIZED RECEIPTS | BN5: 44140.244 | BP5: 13794280 | BQ5: SA18 | BR5: F3P | BS5: 4.1022202e+18 | BT5: t | BU5: * BIDEN VICTORY FUND | BV5: 2020 | BW5: SA | BY5: 4.1023202e+18 | BZ5: http://docquery.fec.gov/cgi-bin/fecimg/?202010219326620824 | CA5: Transfers From Other Authorized Committees
A6: C00703975 | B6: BIDEN FOR PRESIDENT | C6: 2020 | E6: 2.0201022e+17 | F6: 18 | G6: 21210207 | H6: 1458940 | J6: IND | K6: INDIVIDUAL | N6: WRIGHT, DEBORAH | O6: P | Q6: P | R6: DEBORAH | T6: WRIGHT | V6: 285 W 110TH ST | W6: APT 7F | X6: NEW YORK | Y6: NY | Z6: 100264299 | AA6: CITIGROUP | AB6: BOARD MEMBER | AD6: 15J | AE6: MEMO (FILER'S % OF CONTRIBUTION GIVEN TO JOIN | AG6: X | AI6: 44066 | AJ6: 43.25 | AK6: 667.83 | BG6: G2020 | BI6: GENERAL | BJ6: 2020 | BK6: A | BL6: ADD | BM6: ITEMIZED RECEIPTS | BN6: 44140.247 | BP6: 16969473 | BQ6: SA18 | BR6: F3P | BS6: 4.1022202e+18 | BT6: t | BU6: * BIDEN VICTORY FUND | BV6: 2020 | BW6: SA | BY6: 4.1023202e+18 | BZ6: http://docquery.fec.gov/cgi-bin/fecimg/?202010219326640672 | CA6: Transfers From Other Authorized Committees
A7: C00744946 | B7: BIDEN VICTORY FUND | C7: 2020 | D7: Q3 | E7: 2.0210115e+17 | F7: 11AI | G7: 14967170 | H7: 1487959 | J7: IND | K7: INDIVIDUAL | N7: WRIGHT, DEBORAH | O7: N | Q7: J | R7: DEBORAH | T7: WRIGHT | V7: 285 W 110TH ST | X7: NEW YORK | Y7: NY | Z7: 100264299 | AA7: CITIGROUP | AB7: BOARD MEMBER | AD7: 15 | AE7: CONTRIBUTION | AI7: 44089 | AJ7: 250 | AK7: 917.83 | BG7: P | BI7: PRIMARY | BK7: A | BL7: ADD | BM7: ITEMIZED RECEIPTS | BN7: 44231.432 | BR7: F3X | BS7: 4.0115202e+18 | BT7: t | BV7: 2020 | BW7: SA | BY7: 4.0203202e+18 | BZ7: https://docquery.fec.gov/cgi-bin/fecimg/?202101149404582160 | CA7: Contributions From Individuals/Persons Other Than Political Committees
A8: C00744946 | B8: BIDEN VICTORY FUND | C8: 2020 | D8: Q3 | E8: 2.0210115e+17 | F8: 11AI | G8: 7449648 | H8: 1487959 | J8: IND | K8: INDIVIDUAL | N8: WRIGHT, DEBORAH | O8: N | Q8: J | R8: DEBORAH | T8: WRIGHT | V8: 285 W 110TH ST | X8: NEW YORK | Y8: NY | Z8: 100264299 | AA8: CITIGROUP | AB8: BOARD MEMBER | AD8: 15 | AE8: CONTRIBUTION | AI8: 44018 | AJ8: 500 | AK8: 500 | BG8: P | BI8: PRIMARY | BK8: A | BL8: ADD | BM8: ITEMIZED RECEIPTS | BN8: 44231.445 | BR8: F3X | BS8: 4.0115202e+18 | BT8: t | BV8: 2020 | BW8: SA | BY8: 4.0203202e+18 | BZ8: https://docquery.fec.gov/cgi-bin/fecimg/?202101149404682569 | CA8: Contributions From Individuals/Persons Other Than Political Committees
A9: C00744946 | B9: BIDEN VICTORY FUND | C9: 2020 | D9: Q3 | E9: 2.0210115e+17 | F9: 11AI | G9: 11856823 | H9: 1487959 | J9: IND | K9: INDIVIDUAL | N9: WRIGHT, DEBORAH | O9: N | Q9: J | R9: DEBORAH | T9: WRIGHT | V9: 285 W 110TH ST | X9: NEW YORK | Y9: NY | Z9: 100264299 | AA9: CITIGROUP | AB9: BOARD MEMBER | AD9: 15 | AE9: CONTRIBUTION | AI9: 44066 | AJ9: 43.25 | AK9: 667.83 | BG9: P | BI9: PRIMARY | BK9: A | BL9: ADD | BM9: ITEMIZED RECEIPTS | BN9: 44231.447 | BR9: F3X | BS9: 4.0115202e+18 | BT9: t | BV9: 2020 | BW9: SA | BY9: 4.0203202e+18 | BZ9: https://docquery.fec.gov/cgi-bin/fecimg/?202101149404614421 | CA9: Contributions From Individuals/Persons Other Than Political Committees
A10: C00744946 | B10: BIDEN VICTORY FUND | C10: 2020 | D10: Q3 | E10: 2.0210115e+17 | F10: 11AI | G10: 10238617 | H10: 1487959 | J10: IND | K10: INDIVIDUAL | N10: WRIGHT, DEBORAH | O10: N | Q10: J | R10: DEBORAH | T10: WRIGHT | V10: 285 W 110TH ST | X10: NEW YORK | Y10: NY | Z10: 100264299 | AA10: CITIGROUP | AB10: BOARD MEMBER | AD10: 15 | AE10: CONTRIBUTION | AI10: 44055 | AJ10: 124.58 | AK10: 624.58 | BG10: P | BI10: PRIMARY | BK10: A | BL10: ADD | BM10: ITEMIZED RECEIPTS | BN10: 44231.448 | BR10: F3X | BS10: 4.0115202e+18 | BT10: t | BV10: 2020 | BW10: SA | BY10: 4.0203202e+18 | BZ10: https://docquery.fec.gov/cgi-bin/fecimg/?202101149404665219 | CA10: Contributions From Individuals/Persons Other Than Political Committees
V13: =+V10&X10&Y10&Z10 -> 285 W 110TH STNEW YORKNY100264299
A15: Row Labels | B15: Sum of contribution_receipt_amount
A16: BIDEN FOR PRESIDENT | B16: 432.39
A17: BIDEN VICTORY FUND | B17: 932.39
A18: Grand Total | B18: 1364.78

Sheet Diana Taylor
A1: committee_id | B1: committee_name | C1: report_year | D1: report_type | E1: image_number | F1: line_number | G1: transaction_id | H1: file_number | I1: committee_name | J1: entity_type | K1: entity_type_desc | L1: unused_contbr_id | M1: contributor_prefix | N1: contributor_name | O1: recipient_committee_type | P1: recipient_committee_org_type | Q1: recipient_committee_designation | R1: contributor_first_name | S1: contributor_middle_name | T1: contributor_last_name | U1: contributor_suffix | V1: contributor_street_1 | W1: contributor_street_2 | X1: contributor_city | Y1: contributor_state | Z1: contributor_zip | AA1: contributor_employer | AB1: contributor_occupation | AC1: contributor_id | AD1: receipt_type | AE1: receipt_type_desc | AF1: receipt_type_full | AG1: memo_code | AH1: memo_code_full | AI1: contribution_receipt_date | AJ1: contribution_receipt_amount | AK1: contributor_aggregate_ytd | AL1: candidate_id | AM1: candidate_name | AN1: candidate_first_name | AO1: candidate_last_name | AP1: candidate_middle_name | AQ1: candidate_prefix | AR1: candidate_suffix | AS1: candidate_office | AT1: candidate_office_full | AU1: candidate_office_state | AV1: candidate_office_state_full | AW1: candidate_office_district | AX1: conduit_committee_id | AY1: conduit_committee_name | AZ1: conduit_committee_street1 | BA1: conduit_committee_street2 | BB1: conduit_committee_city | BC1: conduit_committee_state | BD1: conduit_committee_zip | BE1: donor_committee_name | BF1: national_committee_nonfederal_account | BG1: election_type | BH1: election_type_full | BI1: fec_election_type_desc | BJ1: fec_election_year | BK1: amendment_indicator | BL1: amendment_indicator_desc | BM1: schedule_type_full | BN1: load_date | BO1: original_sub_id | BP1: back_reference_transaction_id | BQ1: back_reference_schedule_name | BR1: filing_form | BS1: link_id | BT1: is_individual | BU1: memo_text | BV1: two_year_transaction_period | BW1: schedule_type | BX1: increased_limit | BY1: sub_id | BZ1: pdf_url | CA1: line_number_label
A2: C00693234 | B2: WARREN FOR PRESIDENT, INC. | C2: 2019 | D2: Q3 | E2: 2.0191213e+17 | F2: 17A | G2: 3888874 | H2: 1366132 | J2: IND | K2: INDIVIDUAL | L2: C00401224 | N2: TAYLOR, DIANA | O2: P | Q2: P | R2: DIANA | T2: TAYLOR | V2: 75 CAMBRIDGE PKWY | X2: CAMBRIDGE | Y2: MA | Z2: 21421229 | AA2: NONE | AB2: NOT EMPLOYED | AC2: C00401224 | AD2: 15E | AE2: EARMARKED CONTRIBUTION | AI2: 43692 | AJ2: 50 | AK2: 610 | BG2: P2020 | BI2: PRIMARY | BJ2: 2020 | BK2: N | BL2: NO CHANGE | BM2: ITEMIZED RECEIPTS | BN2: 43822.094 | BP2: 3888874E | BQ2: SA17A | BR2: F3P | BS2: 4.1213202e+18 | BT2: t | BU2: * EARMARKED CONTRIBUTION: SEE BELOW | BV2: 2020 | BW2: SA | BY2: 4.1222202e+18 | BZ2: http://docquery.fec.gov/cgi-bin/fecimg/?201912129166268735 | CA2: Contributions From Individuals/Persons Other Than Political Committees
A3: C00693234 | B3: WARREN FOR PRESIDENT, INC. | C3: 2019 | D3: Q3 | E3: 2.0191213e+17 | F3: 17A | G3: 3636565 | H3: 1366132 | J3: IND | K3: INDIVIDUAL | L3: C00401224 | N3: TAYLOR, DIANA | O3: P | Q3: P | R3: DIANA | T3: TAYLOR | V3: 75 CAMBRIDGE PKWY | X3: CAMBRIDGE | Y3: MA | Z3: 21421229 | AA3: NONE | AB3: NOT EMPLOYED | AC3: C00401224 | AD3: 15E | AE3: EARMARKED CONTRIBUTION | AI3: 43663 | AJ3: 10 | AK3: 610 | BG3: P2020 | BI3: PRIMARY | BJ3: 2020 | BK3: N | BL3: NO CHANGE | BM3: ITEMIZED RECEIPTS | BN3: 43822.094 | BP3: 3636565E | BQ3: SA17A | BR3: F3P | BS3: 4.1213202e+18 | BT3: t | BU3: * EARMARKED CONTRIBUTION: SEE BELOW | BV3: 2020 | BW3: SA | BY3: 4.1222202e+18 | BZ3: http://docquery.fec.gov/cgi-bin/fecimg/?201912129166268733 | CA3: Contributions From Individuals/Persons Other Than Political Committees
A4: C00693234 | B4: WARREN FOR PRESIDENT, INC. | C4: 2019 | D4: Q3 | E4: 2.0191213e+17 | F4: 17A | G4: 3695363 | H4: 1366132 | J4: IND | K4: INDIVIDUAL | L4: C00401224 | N4: TAYLOR, DIANA | O4: P | Q4: P | R4: DIANA | T4: TAYLOR | V4: 75 CAMBRIDGE PKWY | X4: CAMBRIDGE | Y4: MA | Z4: 21421229 | AA4: NONE | AB4: NOT EMPLOYED | AC4: C00401224 | AD4: 15E | AE4: EARMARKED CONTRIBUTION | AI4: 43674 | AJ4: 50 | AK4: 610 | BG4: P2020 | BI4: PRIMARY | BJ4: 2020 | BK4: N | BL4: NO CHANGE | BM4: ITEMIZED RECEIPTS | BN4: 43822.094 | BP4: 3695363E | BQ4: SA17A | BR4: F3P | BS4: 4.1213202e+18 | BT4: t | BU4: * EARMARKED CONTRIBUTION: SEE BELOW | BV4: 2020 | BW4: SA | BY4: 4.1222202e+18 | BZ4: http://docquery.fec.gov/cgi-bin/fecimg/?201912129166268733 | CA4: Contributions From Individuals/Persons Other Than Political Committees
A5: C00693234 | B5: WARREN FOR PRESIDENT, INC. | C5: 2019 | D5: Q3 | E5: 2.0191213e+17 | F5: 17A | G5: 3720103 | H5: 1366132 | J5: IND | K5: INDIVIDUAL | L5: C00401224 | N5: TAYLOR, DIANA | O5: P | Q5: P | R5: DIANA | T5: TAYLOR | V5: 75 CAMBRIDGE PKWY | X5: CAMBRIDGE | Y5: MA | Z5: 21421229 | AA5: NONE | AB5: NOT EMPLOYED | AC5: C00401224 | AD5: 15E | AE5: EARMARKED CONTRIBUTION | AI5: 43675 | AJ5: 50 | AK5: 610 | BG5: P2020 | BI5: PRIMARY | BJ5: 2020 | BK5: N | BL5: NO CHANGE | BM5: ITEMIZED RECEIPTS | BN5: 43822.094 | BP5: 3720103E | BQ5: SA17A | BR5: F3P | BS5: 4.1213202e+18 | BT5: t | BU5: * EARMARKED CONTRIBUTION: SEE BELOW | BV5: 2020 | BW5: SA | BY5: 4.1222202e+18 | BZ5: http://docquery.fec.gov/cgi-bin/fecimg/?201912129166268734 | CA5: Contributions From Individuals/Persons Other Than Political Committees
A6: C00693234 | B6: WARREN FOR PRESIDENT, INC. | C6: 2019 | D6: Q3 | E6: 2.0191213e+17 | F6: 17A | G6: 3738867 | H6: 1366132 | J6: IND | K6: INDIVIDUAL | L6: C00401224 | N6: TAYLOR, DIANA | O6: P | Q6: P | R6: DIANA | T6: TAYLOR | V6: 75 CAMBRIDGE PKWY | X6: CAMBRIDGE | Y6: MA | Z6: 21421229 | AA6: NONE | AB6: NOT EMPLOYED | AC6: C00401224 | AD6: 15E | AE6: EARMARKED CONTRIBUTION | AI6: 43676 | AJ6: 10 | AK6: 610 | BG6: P2020 | BI6: PRIMARY | BJ6: 2020 | BK6: N | BL6: NO CHANGE | BM6: ITEMIZED RECEIPTS | BN6: 43822.094 | BP6: 3738867E | BQ6: SA17A | BR6: F3P | BS6: 4.1213202e+18 | BT6: t | BU6: * EARMARKED CONTRIBUTION: SEE BELOW | BV6: 2020 | BW6: SA | BY6: 4.1222202e+18 | BZ6: http://docquery.fec.gov/cgi-bin/fecimg/?201912129166268735 | CA6: Contributions From Individuals/Persons Other Than Political Committees
A7: C00693234 | B7: WARREN FOR PRESIDENT, INC. | C7: 2019 | D7: Q3 | E7: 2.0191213e+17 | F7: 17A | G7: 4384456 | H7: 1366132 | J7: IND | K7: INDIVIDUAL | L7: C00401224 | N7: TAYLOR, DIANA | O7: P | Q7: P | R7: DIANA | T7: TAYLOR | V7: 75 CAMBRIDGE PKWY | X7: CAMBRIDGE | Y7: MA | Z7: 21421229 | AA7: NONE | AB7: NOT EMPLOYED | AC7: C00401224 | AD7: 15E | AE7: EARMARKED CONTRIBUTION | AI7: 43735 | AJ7: 50 | AK7: 610 | BG7: P2020 | BI7: PRIMARY | BJ7: 2020 | BK7: N | BL7: NO CHANGE | BM7: ITEMIZED RECEIPTS | BN7: 43822.094 | BP7: 4384456E | BQ7: SA17A | BR7: F3P | BS7: 4.1213202e+18 | BT7: t | BU7: * EARMARKED CONTRIBUTION: SEE BELOW | BV7: 2020 | BW7: SA | BY7: 4.1222202e+18 | BZ7: http://docquery.fec.gov/cgi-bin/fecimg/?201912129166268739 | CA7: Contributions From Individuals/Persons Other Than Political Committees
A8: C00693234 | B8: WARREN FOR PRESIDENT, INC. | C8: 2019 | D8: Q3 | E8: 2.0191213e+17 | F8: 17A | G8: 3888875 | H8: 1366132 | J8: IND | K8: INDIVIDUAL | L8: C00401224 | N8: TAYLOR, DIANA | O8: P | Q8: P | R8: DIANA | T8: TAYLOR | V8: 75 CAMBRIDGE PKWY | X8: CAMBRIDGE | Y8: MA | Z8: 21421229 | AA8: NONE | AB8: NOT EMPLOYED | AC8: C00401224 | AD8: 15E | AE8: EARMARKED CONTRIBUTION | AI8: 43692 | AJ8: 50 | AK8: 610 | BG8: P2020 | BI8: PRIMARY | BJ8: 2020 | BK8: N | BL8: NO CHANGE | BM8: ITEMIZED RECEIPTS | BN8: 43822.094 | BP8: 3888875E | BQ8: SA17A | BR8: F3P | BS8: 4.1213202e+18 | BT8: t | BU8: * EARMARKED CONTRIBUTION: SEE BELOW | BV8: 2020 | BW8: SA | BY8: 4.1222202e+18 | BZ8: http://docquery.fec.gov/cgi-bin/fecimg/?201912129166268736 | CA8: Contributions From Individuals/Persons Other Than Political Committees
A9: C00693234 | B9: WARREN FOR PRESIDENT, INC. | C9: 2019 | D9: Q3 | E9: 2.0191213e+17 | F9: 17A | G9: 3911771 | H9: 1366132 | J9: IND | K9: INDIVIDUAL | L9: C00401224 | N9: TAYLOR, DIANA | O9: P | Q9: P | R9: DIANA | T9: TAYLOR | V9: 75 CAMBRIDGE PKWY | X9: CAMBRIDGE | Y9: MA | Z9: 21421229 | AA9: NONE | AB9: NOT EMPLOYED | AC9: C00401224 | AD9: 15E | AE9: EARMARKED CONTRIBUTION | AI9: 43694 | AJ9: 10 | AK9: 610 | BG9: P2020 | BI9: PRIMARY | BJ9: 2020 | BK9: N | BL9: NO CHANGE | BM9: ITEMIZED RECEIPTS | BN9: 43822.094 | BP9: 3911771E | BQ9: SA17A | BR9: F3P | BS9: 4.1213202e+18 | BT9: t | BU9: * EARMARKED CONTRIBUTION: SEE BELOW | BV9: 2020 | BW9: SA | BY9: 4.1222202e+18 | BZ9: http://docquery.fec.gov/cgi-bin/fecimg/?201912129166268737 | CA9: Contributions From Individuals/Persons Other Than Political Committees
A10: C00693234 | B10: WARREN FOR PRESIDENT, INC. | C10: 2019 | D10: Q3 | E10: 2.0191213e+17 | F10: 17A | G10: 3991456 | H10: 1366132 | J10: IND | K10: INDIVIDUAL | L10: C00401224 | N10: TAYLOR, DIANA | O10: P | Q10: P | R10: DIANA | T10: TAYLOR | V10: 75 CAMBRIDGE PKWY | X10: CAMBRIDGE | Y10: MA | Z10: 21421229 | AA10: NONE | AB10: NOT EMPLOYED | AC10: C00401224 | AD10: 15E | AE10: EARMARKED CONTRIBUTION | AI10: 43703 | AJ10: 50 | AK10: 610 | BG10: P2020 | BI10: PRIMARY | BJ10: 2020 | BK10: N | BL10: NO CHANGE | BM10: ITEMIZED RECEIPTS | BN10: 43822.094 | BP10: 3991456E | BQ10: SA17A | BR10: F3P | BS10: 4.1213202e+18 | BT10: t | BU10: * EARMARKED CONTRIBUTION: SEE BELOW | BV10: 2020 | BW10: SA | BY10: 4.1222202e+18 | BZ10: http://docquery.fec.gov/cgi-bin/fecimg/?201912129166268737 | CA10: Contributions From Individuals/Persons Other Than Political Committees
A11: C00693234 | B11: WARREN FOR PRESIDENT, INC. | C11: 2019 | D11: Q3 | E11: 2.0191213e+17 | F11: 17A | G11: 4064227 | H11: 1366132 | J11: IND | K11: INDIVIDUAL | L11: C00401224 | N11: TAYLOR, DIANA | O11: P | Q11: P | R11: DIANA | T11: TAYLOR | V11: 75 CAMBRIDGE PKWY | X11: CAMBRIDGE | Y11: MA | Z11: 21421229 | AA11: NONE | AB11: NOT EMPLOYED | AC11: C00401224 | AD11: 15E | AE11: EARMARKED CONTRIBUTION | AI11: 43707 | AJ11: 10 | AK11: 610 | BG11: P2020 | BI11: PRIMARY | BJ11: 2020 | BK11: N | BL11: NO CHANGE | BM11: ITEMIZED RECEIPTS | BN11: 43822.094 | BP11: 4064227E | BQ11: SA17A | BR11: F3P | BS11: 4.1213202e+18 | BT11: t | BU11: * EARMARKED CONTRIBUTION: SEE BELOW | BV11: 2020 | BW11: SA | BY11: 4.1222202e+18 | BZ11: http://docquery.fec.gov/cgi-bin/fecimg/?201912129166268738 | CA11: Contributions From Individuals/Persons Other Than Political Committees
A12: C00693234 | B12: WARREN FOR PRESIDENT, INC. | C12: 2019 | D12: Q3 | E12: 2.0191213e+17 | F12: 17A | G12: 4222813 | H12: 1366132 | J12: IND | K12: INDIVIDUAL | L12: C00401224 | N12: TAYLOR, DIANA | O12: P | Q12: P | R12: DIANA | T12: TAYLOR | V12: 75 CAMBRIDGE PKWY | X12: CAMBRIDGE | Y12: MA | Z12: 21421229 | AA12: NONE | AB12: NOT EMPLOYED | AC12: C00401224 | AD12: 15E | AE12: EARMARKED CONTRIBUTION | AI12: 43725 | AJ12: 10 | AK12: 610 | BG12: P2020 | BI12: PRIMARY | BJ12: 2020 | BK12: N | BL12: NO CHANGE | BM12: ITEMIZED RECEIPTS | BN12: 43822.094 | BP12: 4222813E | BQ12: SA17A | BR12: F3P | BS12: 4.1213202e+18 | BT12: t | BU12: * EARMARKED CONTRIBUTION: SEE BELOW | BV12: 2020 | BW12: SA | BY12: 4.1222202e+18 | BZ12: http://docquery.fec.gov/cgi-bin/fecimg/?201912129166268739 | CA12: Contributions From Individuals/Persons Other Than Political Committees
A13: C00492645 | B13: FRIENDS OF CHRIS MURPHY | C13: 2020 | D13: Q3 | E13: 2.0201016e+17 | F13: 11AI | G13: VTRAAS2NCM4 | H13: 1452197 | J13: IND | K13: INDIVIDUAL | L13: C00401224 | N13: TAYLOR, DIANA | O13: S | Q13: P | R13: DIANA | T13: TAYLOR | V13: 75 CAMBRIDGE PKWY | X13: CAMBRIDGE | Y13: MA | Z13: 21421229 | AA13: NOT EMPLOYED | AB13: NOT EMPLOYED | AC13: C00401224 | AD13: 15E | AE13: EARMARKED CONTRIBUTION | AI13: 44077 | AJ13: 50 | AK13: 225 | BG13: C2024 | BH13: CONVENTION | BI13: CONVENTION | BJ13: 2024 | BK13: A | BL13: ADD | BM13: ITEMIZED RECEIPTS | BN13: 44143.152 | BP13: VTRAAS2NCM4E | BQ13: SA11AI | BR13: F3 | BS13: 4.1016202e+18 | BT13: t | BU13: * EARMARKED CONTRIBUTION: SEE BELOW | BV13: 2020 | BW13: SA | BY13: 4.1108202e+18 | BZ13: http://docquery.fec.gov/cgi-bin/fecimg/?202010159295321107 | CA13: Contributions From Individuals/Persons Other Than Political Committees
A14: C00492645 | B14: FRIENDS OF CHRIS MURPHY | C14: 2020 | D14: Q3 | E14: 2.0201016e+17 | F14: 11AI | G14: VTRAAVM03N3 | H14: 1452197 | J14: IND | K14: INDIVIDUAL | L14: C00401224 | N14: TAYLOR, DIANA | O14: S | Q14: P | R14: DIANA | T14: TAYLOR | V14: 75 CAMBRIDGE PKWY | X14: CAMBRIDGE | Y14: MA | Z14: 21421229 | AA14: NOT EMPLOYED | AB14: NOT EMPLOYED | AC14: C00401224 | AD14: 15E | AE14: EARMARKED CONTRIBUTION | AI14: 44103 | AJ14: 25 | AK14: 250 | BG14: C2024 | BH14: CONVENTION | BI14: CONVENTION | BJ14: 2024 | BK14: A | BL14: ADD | BM14: ITEMIZED RECEIPTS | BN14: 44143.152 | BP14: VTRAAVM03N3E | BQ14: SA11AI | BR14: F3 | BS14: 4.1016202e+18 | BT14: t | BU14: * EARMARKED CONTRIBUTION: SEE BELOW | BV14: 2020 | BW14: SA | BY14: 4.1108202e+18 | BZ14: http://docquery.fec.gov/cgi-bin/fecimg/?202010159295320940 | CA14: Contributions From Individuals/Persons Other Than Political Committees
A15: C00630012 | B15: IT STARTS TODAY | C15: 2019 | D15: M3 | E15: 2.019081e+17 | F15: 11AI | G15: L22056391 | H15: 1347375 | J15: IND | K15: INDIVIDUAL | N15: TAYLOR, DIANA | O15: N | Q15: U | R15: DIANA | T15: TAYLOR | V15: 75 CAMBRIDGE PARKWAY, UNIT E708 | X15: CAMBRIDGE | Y15: MA | Z15: 2142 | AA15: RETIRED | AB15: RETIRED | AF15: EARMARKED FOR S-ME-02-D NOMINEE FUND 2020 | AI15: 43516 | AJ15: 17.36 | AK15: 19.19 | BG15: O2019 | BH15: NON-CAND COMMITTEE | BJ15: 2019 | BK15: A | BL15: ADD | BM15: ITEMIZED RECEIPTS | BN15: 43701.114 | BR15: F3X | BS15: 4.0811202e+18 | BT15: t | BV15: 2020 | BW15: SA | BY15: 4.0823202e+18 | BZ15: http://docquery.fec.gov/cgi-bin/fecimg/?201908099162759369 | CA15: Contributions From Individuals/Persons Other Than Political Committees
A16: C00630012 | B16: IT STARTS TODAY | C16: 2019 | D16: M3 | E16: 2.019081e+17 | F16: 11AI | G16: L22056392 | H16: 1347375 | J16: IND | K16: INDIVIDUAL | N16: TAYLOR, DIANA | O16: N | Q16: U | R16: DIANA | T16: TAYLOR | V16: 75 CAMBRIDGE PARKWAY, UNIT E708 | X16: CAMBRIDGE | Y16: MA | Z16: 2142 | AA16: RETIRED | AB16: RETIRED | AI16: 43516 | AJ16: 1.83 | AK16: 19.19 | BG16: O2019 | BH16: NON-CAND COMMITTEE | BJ16: 2019 | BK16: A | BL16: ADD | BM16: ITEMIZED RECEIPTS | BN16: 43701.114 | BR16: F3X | BS16: 4.0811202e+18 | BT16: t | BV16: 2020 | BW16: SA | BY16: 4.0823202e+18 | BZ16: http://docquery.fec.gov/cgi-bin/fecimg/?201908099162759369 | CA16: Contributions From Individuals/Persons Other Than Political Committees
A17: C00401224 | B17: ACTBLUE | C17: 2019 | D17: MY | E17: 2.019073e+17 | F17: 11AI | G17: SA11AI_145687594 | H17: 1344765 | J17: IND | K17: INDIVIDUAL | N17: TAYLOR, DIANA | O17: W | Q17: U | R17: DIANA | T17: TAYLOR | V17: 75 CAMBRIDGE PARKWAY | X17: CAMBRIDGE | Y17: MA | Z17: 2142 | AA17: NOT EMPLOYED | AB17: NOT EMPLOYED | AF17: CONTRIBUTION TO ACT BLUE | AI17: 43487 | AJ17: 2.5 | AK17: 69.3 | BK17: A | BL17: ADD | BM17: ITEMIZED RECEIPTS | BN17: 43706.652 | BR17: F3X | BS17: 4.0801202e+18 | BT17: t | BU17: CONTRIBUTION TO ACTBLUE | BV17: 2020 | BW17: SA | BY17: 4.0828202e+18 | BZ17: http://docquery.fec.gov/cgi-bin/fecimg/?201907299156850314 | CA17: Contributions From Individuals/Persons Other Than Political Committees
A18: C00401224 | B18: ACTBLUE | C18: 2019 | D18: MY | E18: 2.019073e+17 | F18: 11AI | G18: SA11AI_145687587 | H18: 1344765 | J18: IND | K18: INDIVIDUAL | N18: TAYLOR, DIANA | O18: W | Q18: U | R18: DIANA | T18: TAYLOR | V18: 75 CAMBRIDGE PARKWAY | X18: CAMBRIDGE | Y18: MA | Z18: 2142 | AA18: NOT EMPLOYED | AB18: NOT EMPLOYED | AF18: EARMARK | AI18: 43487 | AJ18: 25 | AK18: 75 | BK18: A | BL18: ADD | BM18: ITEMIZED RECEIPTS | BN18: 43706.652 | BR18: F3X | BS18: 4.0801202e+18 | BT18: t | BU18: EARMARKED FOR KAMALA HARRIS FOR THE PEOPLE (C00694455) | BV18: 2020 | BW18: SA | BY18: 4.0828202e+18 | BZ18: http://docquery.fec.gov/cgi-bin/fecimg/?201907299156850315 | CA18: Contributions From Individuals/Persons Other Than Political Committees
A19: C00401224 | B19: ACTBLUE | C19: 2019 | D19: MY | E19: 2.019073e+17 | F19: 11AI | G19: SA11AI_146790800 | H19: 1344765 | J19: IND | K19: INDIVIDUAL | N19: TAYLOR, DIANA | O19: W | Q19: U | R19: DIANA | T19: TAYLOR | V19: 75 CAMBRIDGE PARKWAY | X19: CAMBRIDGE | Y19: MA | Z19: 2142 | AA19: NOT EMPLOYED | AB19: NOT EMPLOYED | AF19: CONTRIBUTION TO ACT BLUE | AI19: 43502 | AJ19: 5 | AK19: 69.3 | BK19: A | BL19: ADD | BM19: ITEMIZED RECEIPTS | BN19: 43706.652 | BR19: F3X | BS19: 4.0801202e+18 | BT19: t | BU19: CONTRIBUTION TO ACTBLUE | BV19: 2020 | BW19: SA | BY19: 4.0828202e+18 | BZ19: http://docquery.fec.gov/cgi-bin/fecimg/?201907299156850318 | CA19: Contributions From Individuals/Persons Other Than Political Committees
A20: C00401224 | B20: ACTBLUE | C20: 2019 | D20: MY | E20: 2.019073e+17 | F20: 11AI | G20: SA11AI_146790798 | H20: 1344765 | J20: IND | K20: INDIVIDUAL | N20: TAYLOR, DIANA | O20: W | Q20: U | R20: DIANA | T20: TAYLOR | V20: 75 CAMBRIDGE PARKWAY | X20: CAMBRIDGE | Y20: MA | Z20: 2142 | AA20: NOT EMPLOYED | AB20: NOT EMPLOYED | AF20: EARMARK | AI20: 43502 | AJ20: 25 | AK20: 183 | BK20: A | BL20: ADD | BM20: ITEMIZED RECEIPTS | BN20: 43706.652 | BR20: F3X | BS20: 4.0801202e+18 | BT20: t | BU20: EARMARKED FOR ALEXANDRIA OCASIO-CORTEZ FOR CONGRESS (C00639591) | BV20: 2020 | BW20: SA | BY20: 4.0828202e+18 | BZ20: http://docquery.fec.gov/cgi-bin/fecimg/?201907299156850318 | CA20: Contributions From Individuals/Persons Other Than Political Committees
A21: C00401224 | B21: ACTBLUE | C21: 2019 | D21: MY | E21: 2.019073e+17 | F21: 11AI | G21: SA11AI_147329080 | H21: 1344765 | J21: IND | K21: INDIVIDUAL | N21: TAYLOR, DIANA | O21: W | Q21: U | R21: DIANA | T21: TAYLOR | V21: 75 CAMBRIDGE PARKWAY | X21: CAMBRIDGE | Y21: MA | Z21: 2142 | AA21: NOT EMPLOYED | AB21: NOT EMPLOYED | AF21: CONTRIBUTION TO ACT BLUE | AI21: 43510 | AJ21: 2.5 | AK21: 69.3 | BK21: A | BL21: ADD | BM21: ITEMIZED RECEIPTS | BN21: 43706.652 | BR21: F3X | BS21: 4.0801202e+18 | BT21: t | BU21: CONTRIBUTION TO ACTBLUE | BV21: 2020 | BW21: SA | BY21: 4.0828202e+18 | BZ21: http://docquery.fec.gov/cgi-bin/fecimg/?201907299156850320 | CA21: Contributions From Individuals/Persons Other Than Political Committees
A22: C00401224 | B22: ACTBLUE | C22: 2019 | D22: MY | E22: 2.019073e+17 | F22: 11AI | G22: SA11AI_146790799 | H22: 1344765 | J22: IND | K22: INDIVIDUAL | N22: TAYLOR, DIANA | O22: W | Q22: U | R22: DIANA | T22: TAYLOR | V22: 75 CAMBRIDGE PARKWAY | X22: CAMBRIDGE | Y22: MA | Z22: 2142 | AA22: NOT EMPLOYED | AB22: NOT EMPLOYED | AF22: EARMARK | AI22: 43502 | AJ22: 25 | AK22: 50 | BK22: A | BL22: ADD | BM22: ITEMIZED RECEIPTS | BN22: 43706.652 | BR22: F3X | BS22: 4.0801202e+18 | BT22: t | BU22: EARMARKED FOR BE A HERO PAC (C00678995) | BV22: 2020 | BW22: SA | BY22: 4.0828202e+18 | BZ22: http://docquery.fec.gov/cgi-bin/fecimg/?201907299156850319 | CA22: Contributions From Individuals/Persons Other Than Political Committees
A23: C00401224 | B23: ACTBLUE | C23: 2019 | D23: MY | E23: 2.019073e+17 | F23: 11AI | G23: SA11AI_151798284 | H23: 1344765 | J23: IND | K23: INDIVIDUAL | N23: TAYLOR, DIANA | O23: W | Q23: U | R23: DIANA | T23: TAYLOR | V23: 75 CAMBRIDGE PARKWAY | X23: CAMBRIDGE | Y23: MA | Z23: 2142 | AA23: NOT EMPLOYED | AB23: NOT EMPLOYED | AF23: CONTRIBUTION TO ACT BLUE | AI23: 43551 | AJ23: 2.7 | AK23: 69.3 | BK23: A | BL23: ADD | BM23: ITEMIZED RECEIPTS | BN23: 43706.652 | BR23: F3X | BS23: 4.0801202e+18 | BT23: t | BU23: CONTRIBUTION TO ACTBLUE | BV23: 2020 | BW23: SA | BY23: 4.0828202e+18 | BZ23: http://docquery.fec.gov/cgi-bin/fecimg/?201907299156850324 | CA23: Contributions From Individuals/Persons Other Than Political Committees
A24: C00401224 | B24: ACTBLUE | C24: 2019 | D24: MY | E24: 2.019073e+17 | F24: 11AI | G24: SA11AI_153175442 | H24: 1344765 | J24: IND | K24: INDIVIDUAL | N24: TAYLOR, DIANA | O24: W | Q24: U | R24: DIANA | T24: TAYLOR | V24: 75 CAMBRIDGE PARKWAY | X24: CAMBRIDGE | Y24: MA | Z24: 2142 | AA24: NOT EMPLOYED | AB24: NOT EMPLOYED | AF24: CONTRIBUTION TO ACT BLUE | AI24: 43559 | AJ24: 10 | AK24: 69.3 | BK24: A | BL24: ADD | BM24: ITEMIZED RECEIPTS | BN24: 43706.652 | BR24: F3X | BS24: 4.0801202e+18 | BT24: t | BU24: CONTRIBUTION TO ACTBLUE | BV24: 2020 | BW24: SA | BY24: 4.0828202e+18 | BZ24: http://docquery.fec.gov/cgi-bin/fecimg/?201907299156850326 | CA24: Contributions From Individuals/Persons Other Than Political Committees
A25: C00401224 | B25: ACTBLUE | C25: 2019 | D25: MY | E25: 2.019073e+17 | F25: 11AI | G25: SA11AI_155733981 | H25: 1344765 | J25: IND | K25: INDIVIDUAL | N25: TAYLOR, DIANA | O25: W | Q25: U | R25: DIANA | T25: TAYLOR | V25: 75 CAMBRIDGE PARKWAY | X25: CAMBRIDGE | Y25: MA | Z25: 2142 | AA25: NOT EMPLOYED | AB25: NOT EMPLOYED | AF25: CONTRIBUTION TO ACT BLUE | AI25: 43582 | AJ25: 2.5 | AK25: 69.3 | BK25: A | BL25: ADD | BM25: ITEMIZED RECEIPTS | BN25: 43706.652 | BR25: F3X | BS25: 4.0801202e+18 | BT25: t | BU25: CONTRIBUTION TO ACTBLUE | BV25: 2020 | BW25: SA | BY25: 4.0828202e+18 | BZ25: http://docquery.fec.gov/cgi-bin/fecimg/?201907299156850332 | CA25: Contributions From Individuals/Persons Other Than Political Committees
A26: C00401224 | B26: ACTBLUE | C26: 2019 | D26: MY | E26: 2.019073e+17 | F26: 11AI | G26: SA11AI_155733975 | H26: 1344765 | J26: IND | K26: INDIVIDUAL | N26: TAYLOR, DIANA | O26: W | Q26: U | R26: DIANA | T26: TAYLOR | V26: 75 CAMBRIDGE PARKWAY | X26: CAMBRIDGE | Y26: MA | Z26: 2142 | AA26: NOT EMPLOYED | AB26: NOT EMPLOYED | AF26: EARMARK | AI26: 43582 | AJ26: 25 | AK26: 50 | BK26: A | BL26: ADD | BM26: ITEMIZED RECEIPTS | BN26: 43706.652 | BR26: F3X | BS26: 4.0801202e+18 | BT26: t | BU26: EARMARKED FOR BE A HERO PAC (C00678995) | BV26: 2020 | BW26: SA | BY26: 4.0828202e+18 | BZ26: http://docquery.fec.gov/cgi-bin/fecimg/?201907299156850332 | CA26: Contributions From Individuals/Persons Other Than Political Committees
A27: C00401224 | B27: ACTBLUE | C27: 2019 | D27: MY | E27: 2.019073e+17 | F27: 11AI | G27: SA11AI_155688451 | H27: 1344765 | J27: IND | K27: INDIVIDUAL | N27: TAYLOR, DIANA | O27: W | Q27: U | R27: DIANA | T27: TAYLOR | V27: 75 CAMBRIDGE PARKWAY | X27: CAMBRIDGE | Y27: MA | Z27: 2142 | AA27: NOT EMPLOYED | AB27: NOT EMPLOYED | AF27: CONTRIBUTION TO ACT BLUE | AI27: 43582 | AJ27: 2.7 | AK27: 69.3 | BK27: A | BL27: ADD | BM27: ITEMIZED RECEIPTS | BN27: 43706.652 | BR27: F3X | BS27: 4.0801202e+18 | BT27: t | BU27: CONTRIBUTION TO ACTBLUE | BV27: 2020 | BW27: SA | BY27: 4.0828202e+18 | BZ27: http://docquery.fec.gov/cgi-bin/fecimg/?201907299156850333 | CA27: Contributions From Individuals/Persons Other Than Political Committees
A28: C00401224 | B28: ACTBLUE | C28: 2019 | D28: MY | E28: 2.019073e+17 | F28: 11AI | G28: SA11AI_157993114 | H28: 1344765 | J28: IND | K28: INDIVIDUAL | L28: C00693234 | N28: TAYLOR, DIANA | O28: W | Q28: U | R28: DIANA | T28: TAYLOR | V28: 75 CAMBRIDGE PARKWAY | X28: CAMBRIDGE | Y28: MA | Z28: 2142 | AA28: NOT EMPLOYED | AB28: NOT EMPLOYED | AC28: C00693234 | AD28: 24T | AE28: EARMARKED INTERMEDIARY TREASURY OUT | AF28: EARMARK | AI28: 43602 | AJ28: 50 | AK28: 260 | AL28: P00009621 | BK28: A | BL28: ADD | BM28: ITEMIZED RECEIPTS | BN28: 43706.652 | BR28: F3X | BS28: 4.0801202e+18 | BT28: t | BU28: EARMARKED FOR WARREN FOR PRESIDENT, INC. (C00693234) | BV28: 2020 | BW28: SA | BY28: 4.0828202e+18 | BZ28: http://docquery.fec.gov/cgi-bin/fecimg/?201907299156850340 | CA28: Contributions From Individuals/Persons Other Than Political Committees
A29: C00401224 | B29: ACTBLUE | C29: 2019 | D29: MY | E29: 2.019073e+17 | F29: 11AI | G29: SA11AI_159006610 | H29: 1344765 | J29: IND | K29: INDIVIDUAL | N29: TAYLOR, DIANA | O29: W | Q29: U | R29: DIANA | T29: TAYLOR | V29: 75 CAMBRIDGE PARKWAY | X29: CAMBRIDGE | Y29: MA | Z29: 2142 | AA29: NOT EMPLOYED | AB29: NOT EMPLOYED | AF29: EARMARK | AI29: 43612 | AJ29: 27 | AK29: 183 | BK29: A | BL29: ADD | BM29: ITEMIZED RECEIPTS | BN29: 43706.652 | BR29: F3X | BS29: 4.0801202e+18 | BT29: t | BU29: EARMARKED FOR ALEXANDRIA OCASIO-CORTEZ FOR CONGRESS (C00639591) | BV29: 2020 | BW29: SA | BY29: 4.0828202e+18 | BZ29: http://docquery.fec.gov/cgi-bin/fecimg/?201907299156850342 | CA29: Contributions From Individuals/Persons Other Than Political Committees
A30: C00401224 | B30: ACTBLUE | C30: 2019 | D30: MY | E30: 2.019073e+17 | F30: 11AI | G30: SA11AI_157993123 | H30: 1344765 | J30: IND | K30: INDIVIDUAL | N30: TAYLOR, DIANA | O30: W | Q30: U | R30: DIANA | T30: TAYLOR | V30: 75 CAMBRIDGE PARKWAY | X30: CAMBRIDGE | Y30: MA | Z30: 2142 | AA30: NOT EMPLOYED | AB30: NOT EMPLOYED | AF30: CONTRIBUTION TO ACT BLUE | AI30: 43602 | AJ30: 5 | AK30: 69.3 | BK30: A | BL30: ADD | BM30: ITEMIZED RECEIPTS | BN30: 43706.652 | BR30: F3X | BS30: 4.0801202e+18 | BT30: t | BU30: CONTRIBUTION TO ACTBLUE | BV30: 2020 | BW30: SA | BY30: 4.0828202e+18 | BZ30: http://docquery.fec.gov/cgi-bin/fecimg/?201907299156850339 | CA30: Contributions From Individuals/Persons Other Than Political Committees
A31: C00401224 | B31: ACTBLUE | C31: 2019 | D31: MY | E31: 2.019073e+17 | F31: 11AI | G31: SA11AI_159006609 | H31: 1344765 | J31: IND | K31: INDIVIDUAL | N31: TAYLOR, DIANA | O31: W | Q31: U | R31: DIANA | T31: TAYLOR | V31: 75 CAMBRIDGE PARKWAY | X31: CAMBRIDGE | Y31: MA | Z31: 2142 | AA31: NOT EMPLOYED | AB31: NOT EMPLOYED | AF31: CONTRIBUTION TO ACT BLUE | AI31: 43612 | AJ31: 2.7 | AK31: 69.3 | BK31: A | BL31: ADD | BM31: ITEMIZED RECEIPTS | BN31: 43706.652 | BR31: F3X | BS31: 4.0801202e+18 | BT31: t | BU31: CONTRIBUTION TO ACTBLUE | BV31: 2020 | BW31: SA | BY31: 4.0828202e+18 | BZ31: http://docquery.fec.gov/cgi-bin/fecimg/?201907299156850341 | CA31: Contributions From Individuals/Persons Other Than Political Committees
A32: C00401224 | B32: ACTBLUE | C32: 2019 | D32: MY | E32: 2.019073e+17 | F32: 11AI | G32: SA11AI_161492067 | H32: 1344765 | J32: IND | K32: INDIVIDUAL | L32: C00693234 | N32: TAYLOR, DIANA | O32: W | Q32: U | R32: DIANA | T32: TAYLOR | V32: 75 CAMBRIDGE PARKWAY | X32: CAMBRIDGE | Y32: MA | Z32: 2142 | AA32: NOT EMPLOYED | AB32: NOT EMPLOYED | AC32: C00693234 | AD32: 24T | AE32: EARMARKED INTERMEDIARY TREASURY OUT | AF32: EARMARK | AI32: 43633 | AJ32: 10 | AK32: 260 | AL32: P00009621 | BK32: A | BL32: ADD | BM32: ITEMIZED RECEIPTS | BN32: 43706.652 | BR32: F3X | BS32: 4.0801202e+18 | BT32: t | BU32: EARMARKED FOR WARREN FOR PRESIDENT, INC. (C00693234) | BV32: 2020 | BW32: SA | BY32: 4.0828202e+18 | BZ32: http://docquery.fec.gov/cgi-bin/fecimg/?201907299156850347 | CA32: Contributions From Individuals/Persons Other Than Political Committees
A33: C00401224 | B33: ACTBLUE | C33: 2019 | D33: MY | E33: 2.019073e+17 | F33: 11AI | G33: SA11AI_162641216 | H33: 1344765 | J33: IND | K33: INDIVIDUAL | N33: TAYLOR, DIANA | O33: W | Q33: U | R33: DIANA | T33: TAYLOR | V33: 75 CAMBRIDGE PARKWAY | X33: CAMBRIDGE | Y33: MA | Z33: 2142 | AA33: NOT EMPLOYED | AB33: NOT EMPLOYED | AF33: CONTRIBUTION TO ACT BLUE | AI33: 43641 | AJ33: 5 | AK33: 69.3 | BK33: A | BL33: ADD | BM33: ITEMIZED RECEIPTS | BN33: 43706.652 | BR33: F3X | BS33: 4.0801202e+18 | BT33: t | BU33: CONTRIBUTION TO ACTBLUE | BV33: 2020 | BW33: SA | BY33: 4.0828202e+18 | BZ33: http://docquery.fec.gov/cgi-bin/fecimg/?201907299156850350 | CA33: Contributions From Individuals/Persons Other Than Political Committees
A34: C00401224 | B34: ACTBLUE | C34: 2019 | D34: MY | E34: 2.019073e+17 | F34: 11AI | G34: SA11AI_161492068 | H34: 1344765 | J34: IND | K34: INDIVIDUAL | N34: TAYLOR, DIANA | O34: W | Q34: U | R34: DIANA | T34: TAYLOR | V34: 75 CAMBRIDGE PARKWAY | X34: CAMBRIDGE | Y34: MA | Z34: 2142 | AA34: NOT EMPLOYED | AB34: NOT EMPLOYED | AF34: CONTRIBUTION TO ACT BLUE | AI34: 43633 | AJ34: 1 | AK34: 69.3 | BK34: A | BL34: ADD | BM34: ITEMIZED RECEIPTS | BN34: 43706.652 | BR34: F3X | BS34: 4.0801202e+18 | BT34: t | BU34: CONTRIBUTION TO ACTBLUE | BV34: 2020 | BW34: SA | BY34: 4.0828202e+18 | BZ34: http://docquery.fec.gov/cgi-bin/fecimg/?201907299156850348 | CA34: Contributions From Individuals/Persons Other Than Political Committees
