Workbook

Sheet Board & Executives
A1: Company | B1: Board | C1: Exec | D1: Employer | E1: Fname | F1: MI | G1: Lname | H1: Gender | I1: State | J1: Age | K1: DOB | L1: Dem | M1: Rep | N1: Neu | O1: Reg | P1: Address
A2: Fannie Mae | B2: N | C2: Y | D2: President & Interim CFO | E2: David | F2: C. | G2: Benson | H2: M | J2: 61 | Q2: =+E2&F2&G2 -> David C. Benson | R2: No FEC Data
A3: Fannie Mae | B3: Y | C3: N | D3: Independent Director | E3: Christopher | F3: J. | G3: Brummer | H3: M | Q3: =+E3&F3&G3 -> Christopher J. Brummer | R3: No FEC Data
A4: Fannie Mae | B4: Y | C4: N | D4: Independent Director | E4: Simon | G4: Johnson | H4: M | Q4: =+E4&F4&G4 -> Simon Johnson | R4: No FEC Data
A5: Fannie Mae | B5: Y | C5: Y | D5: Chairman | E5: Sheila | F5: Colleen | G5: Bair | H5: F | I5: MD & KS | J5: =71-4 -> 67 | K5: 19817 | M5: =+GETPIVOTDATA("contribution_receipt_amount",'Sheila Bair'!$A$11) -> 11200 | O5: R | P5: 14145 SHALLCROSS WHARF RD KENNEDYVILLE MD 216453447 & KS | Q5: =+E5&F5&G5 -> Sheila Colleen Bair
A6: Fannie Mae | B6: Y | C6: Y | D6: Chief Executive Officer & Director | E6: Hugh | F6: R. | G6: Frater | H6: M | Q6: =+E6&F6&G6 -> Hugh R. Frater | R6: No FEC Data
A7: Fannie Mae | B7: Y | C7: N | D7: Independent Director | E7: Robert | F7: H. | G7: Herz | H7: M | I7: NJ | L7: =+'Robert Herz'!AJ2 -> 1000 | O7: N | P7: 186 NORTHWOODS DR SOUTH ORANGE NJ 70791123 | Q7: =+E7&F7&G7 -> Robert H. Herz
A8: Fannie Mae | B8: Y | C8: N | D8: Independent Director | E8: Amy | F8: E. | G8: Alving | H8: F | Q8: =+E8&F8&G8 -> Amy E. Alving | R8: No FEC Data
A9: Fannie Mae | B9: Y | C9: N | D9: Independent Director | E9: Diane | F9: C. | G9: Nordin | H9: F | Q9: =+E9&F9&G9 -> Diane C. Nordin | R9: No FEC Data
A10: Fannie Mae | B10: Y | C10: N | D10: Independent Director | E10: Renée | F10: Lewis | G10: Glover | H10: F | I10: GA | J10: 71 | L10: =+GETPIVOTDATA("contribution_receipt_amount",'Renee Glover'!$A$413) -> 32663.29 | O10: D | P10: 553 AUBURN AVE NE ATLANTA GA 303121941 | Q10: =+E10&F10&G10 -> Renée Lewis Glover
A11: Fannie Mae | B11: Y | C11: N | D11: Independent Director | E11: Michael | F11: J. | G11: Heid | H11: M | I11: PA | L11: =+GETPIVOTDATA("contribution_receipt_amount",'Michael Heid'!$A$10) -> 300 | P11: 117 LEE ROAD PITTSBURGH PA 15237 | Q11: =+E11&F11&G11 -> Michael J. Heid
A12: Fannie Mae | B12: Y | C12: N | D12: Independent Director | E12: Antony | F12: Peter | G12: Jenkins | H12: M | I12: UK | J12: 60 | K12: 22473 | Q12: =+E12&F12&G12 -> Antony Peter Jenkins | R12: No FEC Data
A13: Fannie Mae | B13: Y | C13: N | D13: Independent Director | E13: Manuel | F13: Sánchez | G13: Rodríguez | H13: M | I13: TX | Q13: =+E13&F13&G13 -> Manuel Sánchez Rodríguez | R13: No FEC Data
A14: Fannie Mae | B14: Y | C14: N | D14: Independent Director | E14: Karin | F14: J. | G14: Kimbrough | H14: F | L14: =+'Karin Kimbrough'!AJ5 -> 750 | P14: 420 RIVERSIDE DR NEW YORK NY 100257755 | Q14: =+E14&F14&G14 -> Karin J. Kimbrough
D15: EXECUTIVES | Q15: =+E15&F15&G15
A16: Fannie Mae | B16: N | C16: Y | D16: Chief Administrative Officer & Executive VP | E16: Jeffery | F16: R. | G16: Hayward | H16: M | Q16: =+E16&F16&G16 -> Jeffery R. Hayward | R16: No FEC Data
A17: Fannie Mae | B17: N | C17: Y | D17: Senior Vice President | E17: Douglas | F17: G. | G17: Duncan | H17: M | Q17: =+E17&F17&G17 -> Douglas G. Duncan | R17: No FEC Data
A18: Fannie Mae | B18: N | C18: Y | D18: Chief Risk Officer & Executive Vice President | E18: Ryan | F18: A. | G18: Zanin | H18: M | Q18: =+E18&F18&G18 -> Ryan A. Zanin | R18: No FEC Data
A19: Fannie Mae | B19: N | C19: Y | D19: Senior Vice President | E19: Richard | F19: Scott | G19: Blackley | H19: M | N19: =+GETPIVOTDATA("contribution_receipt_amount",'Richard Blackley'!$A$37,"committee_name","CAPITAL ONE FINANCIAL CORP. ASSOC. POLITICAL FUND") -> 5961.49 | O19: D | P19: 43414 TURNBERRY ISLE COURT LEESBURG VA 20176 | Q19: =+E19&F19&G19 -> Richard Scott Blackley
A20: Fannie Mae | B20: N | C20: Y | D20: Senior Vice President & Controller | E20: Chryssa | F20: C. | G20: Halley | H20: F | Q20: =+E20&F20&G20 -> Chryssa C. Halley | R20: No FEC Data
A21: Fannie Mae | B21: N | C21: Y | D21: Secretary, Executive VP & General Counsel | E21: Stergios | G21: Theologides | H21: M | L21: =+GETPIVOTDATA("contribution_receipt_amount",'Stergios Theologides'!$A$21) -> 35600 | O21: D | P21: 950 WESTMINSTER ST NW WASHINGTON DC 200014130 | Q21: =+E21&F21&G21 -> Stergios Theologides
L23: =SUM(L2:L22) -> 70313.29 | M23: =SUM(M2:M22) -> 11200 | N23: =SUM(N2:N22) -> 5961.49

Sheet Stergios Theologides
A1: committee_id | B1: committee_name | C1: report_year | D1: report_type | E1: image_number | F1: line_number | G1: transaction_id | H1: file_number | I1: committee_name | J1: entity_type | K1: entity_type_desc | L1: unused_contbr_id | M1: contributor_prefix | N1: contributor_name | O1: recipient_committee_type | P1: recipient_committee_org_type | Q1: recipient_committee_designation | R1: contributor_first_name | S1: contributor_middle_name | T1: contributor_last_name | U1: contributor_suffix | V1: contributor_street_1 | W1: contributor_street_2 | X1: contributor_city | Y1: contributor_state | Z1: contributor_zip | AA1: contributor_employer | AB1: contributor_occupation | AC1: contributor_id | AD1: receipt_type | AE1: receipt_type_desc | AF1: receipt_type_full | AG1: memo_code | AH1: memo_code_full | AI1: contribution_receipt_date | AJ1: contribution_receipt_amount | AK1: contributor_aggregate_ytd | AL1: candidate_id | AM1: candidate_name | AN1: candidate_first_name | AO1: candidate_last_name | AP1: candidate_middle_name | AQ1: candidate_prefix | AR1: candidate_suffix | AS1: candidate_office | AT1: candidate_office_full | AU1: candidate_office_state | AV1: candidate_office_state_full | AW1: candidate_office_district | AX1: conduit_committee_id | AY1: conduit_committee_name | AZ1: conduit_committee_street1 | BA1: conduit_committee_street2 | BB1: conduit_committee_city | BC1: conduit_committee_state | BD1: conduit_committee_zip | BE1: donor_committee_name | BF1: national_committee_nonfederal_account | BG1: election_type | BH1: election_type_full | BI1: fec_election_type_desc | BJ1: fec_election_year | BK1: amendment_indicator | BL1: amendment_indicator_desc | BM1: schedule_type_full | BN1: load_date | BO1: original_sub_id | BP1: back_reference_transaction_id | BQ1: back_reference_schedule_name | BR1: filing_form | BS1: link_id | BT1: is_individual | BU1: memo_text | BV1: two_year_transaction_period | BW1: schedule_type | BX1: increased_limit | BY1: sub_id | BZ1: pdf_url | CA1: line_number_label
A2: C00660464 | B2: CHRIS PAPPAS FOR CONGRESS | C2: 2020 | D2: Q1 | E2: 2.0200526e+17 | F2: 11AI | G2: VSHA8K8ANZ8 | H2: 1408413 | J2: IND | K2: INDIVIDUAL | L2: C00401224 | N2: THEOLOGIDES, STERGIOS | O2: H | Q2: P | R2: STERGIOS | T2: THEOLOGIDES | V2: 1441 U ST NW | W2: APT 1021 | X2: WASHINGTON | Y2: DC | Z2: 200093537 | AA2: FANNIE MAE | AB2: EXECUTIVE VICE PRESIDENT | AC2: C00401224 | AD2: 15E | AE2: EARMARKED CONTRIBUTION | AI2: 43880 | AJ2: 500 | AK2: 500 | BG2: P2020 | BI2: PRIMARY | BJ2: 2020 | BK2: N | BL2: NO CHANGE | BM2: ITEMIZED RECEIPTS | BN2: 43978.071 | BP2: VSHA8K8ANZ8E | BQ2: SA11AI | BR2: F3 | BS2: 4.0525202e+18 | BT2: t | BU2: * EARMARKED CONTRIBUTION: SEE BELOW | BV2: 2020 | BW2: SA | BY2: 4.0526202e+18 | BZ2: http://docquery.fec.gov/cgi-bin/fecimg/?202005259239494338 | CA2: Contributions From Individuals/Persons Other Than Political Committees
A3: C00711549 | B3: AMY MCGRATH FOR SENATE, INC. | C3: 2020 | D3: Q3 | E3: 2.0210702e+17 | F3: 11AI | G3: 11AI-001990681 | H3: 1522129 | J3: IND | K3: INDIVIDUAL | N3: THEOLOGIDES, STERGIOS | O3: S | Q3: P | R3: STERGIOS | T3: THEOLOGIDES | V3: 950 WESTMINSTER STREET NW | X3: WASHINGTON | Y3: DC | Z3: 20001 | AA3: FANNIE MAE | AB3: ATTORNEY | AD3: 15E | AE3: EARMARKED CONTRIBUTION | AI3: 44100 | AJ3: 2800 | AK3: 2800 | BG3: G2020 | BI3: GENERAL | BJ3: 2020 | BK3: A | BL3: ADD | BM3: ITEMIZED RECEIPTS | BN3: 44384.157 | BR3: F3 | BS3: 4.0702202e+18 | BT3: t | BU3: EARMARKED THROUGH ACTBLUE 09-27-2020 $1,234,374.47 - SEE MEMO ON SCH A FOR LINE 11C | BV3: 2020 | BW3: SA | BY3: 4.0707202e+18 | BZ3: https://docquery.fec.gov/cgi-bin/fecimg/?202107019450925380 | CA3: Contributions From Individuals/Persons Other Than Political Committees
A4: C00703975 | B4: BIDEN FOR PRESIDENT | C4: 2020 | D4: M5 | E4: 2.0200521e+17 | F4: 17A | G4: 4320367 | H4: 1407726 | J4: IND | K4: INDIVIDUAL | L4: C00401224 | N4: THEOLOGIDES, STERGIOS | O4: P | Q4: P | R4: STERGIOS | T4: THEOLOGIDES | V4: 521 LUMINOUS | X4: IRVINE | Y4: CA | Z4: 926034238 | AA4: CORELOGIC | AB4: ATTORNEY | AC4: C00401224 | AD4: 15E | AE4: EARMARKED CONTRIBUTION | AI4: 43946 | AJ4: 2800 | AK4: 2800 | BG4: P2020 | BI4: PRIMARY | BJ4: 2020 | BK4: A | BL4: ADD | BM4: ITEMIZED RECEIPTS | BN4: 43981.114 | BP4: 4320367E | BQ4: SA17A | BR4: F3P | BS4: 4.0521202e+18 | BT4: t | BU4: * EARMARKED CONTRIBUTION: SEE BELOW | BV4: 2020 | BW4: SA | BY4: 4.0529202e+18 | BZ4: http://docquery.fec.gov/cgi-bin/fecimg/?202005209239448762 | CA4: Contributions From Individuals/Persons Other Than Political Committees
A5: C00744946 | B5: BIDEN VICTORY FUND | C5: 2020 | D5: 30G | E5: 2.0201204e+17 | F5: 11AI | G5: 27875881 | H5: 1481256 | J5: IND | K5: INDIVIDUAL | N5: THEOLOGIDES, STERGIOS | O5: N | Q5: J | R5: STERGIOS | T5: THEOLOGIDES | V5: 1441 U ST NW | W5: APT 1021 | X5: WASHINGTON | Y5: DC | Z5: 200093537 | AA5: FANNIE MAE | AB5: ATTORNEY | AD5: 15 | AE5: CONTRIBUTION | AI5: 44137 | AJ5: 500 | AK5: 3300 | BG5: P | BI5: PRIMARY | BK5: A | BL5: ADD | BM5: ITEMIZED RECEIPTS | BN5: 44329.161 | BR5: F3X | BS5: 4.1205202e+18 | BT5: t | BV5: 2020 | BW5: SA | BY5: 4.0104202e+18 | BZ5: https://docquery.fec.gov/cgi-bin/fecimg/?202012039342557361 | CA5: Contributions From Individuals/Persons Other Than Political Committees
A6: C00636571 | B6: KATIE PORTER FOR CONGRESS | C6: 2020 | D6: Q2 | E6: 2.0201204e+17 | F6: 11AI | G6: VTEFSYCT318 | H6: 1480684 | J6: IND | K6: INDIVIDUAL | N6: THEOLOGIDES, STERGIOS | O6: H | Q6: P | R6: STERGIOS | T6: THEOLOGIDES | V6: 1441 U ST NW | X6: WASHINGTON | Y6: DC | Z6: 200093537 | AA6: THEOLOGIDES LAW, PC | AB6: ATTORNEY | AD6: 15E | AE6: EARMARKED CONTRIBUTION | AI6: 43946 | AJ6: 1000 | AK6: 1500 | BG6: G2020 | BI6: GENERAL | BJ6: 2020 | BK6: A | BL6: ADD | BM6: ITEMIZED RECEIPTS | BN6: 44183.154 | BP6: VTEFSYCT318E | BQ6: SA11AI | BR6: F3 | BS6: 4.1205202e+18 | BT6: t | BU6: * EARMARKED CONTRIBUTION: SEE BELOW | BV6: 2020 | BW6: SA | BY6: 4.1218202e+18 | BZ6: https://docquery.fec.gov/cgi-bin/fecimg/?202012039341014768 | CA6: Contributions From Individuals/Persons Other Than Political Committees
A7: C00010603 | B7: DNC SERVICES CORP / DEMOCRATIC NATIONAL COMMITTEE | C7: 2020 | D7: 30G | E7: 2.0210402e+17 | F7: 12 | G7: 38196215 | H7: 1507252 | J7: IND | K7: INDIVIDUAL | N7: THEOLOGIDES, STERGIOS | O7: Y | Q7: U | R7: STERGIOS | T7: THEOLOGIDES | V7: 1441 U ST NW | X7: WASHINGTON | Y7: DC | Z7: 200093537 | AA7: FANNIE MAE | AB7: ATTORNEY | AD7: 15J | AE7: MEMO (FILER'S % OF CONTRIBUTION GIVEN TO JOIN | AG7: X | AI7: 44113 | AJ7: 2800 | AK7: 2800 | BG7: G2020 | BI7: GENERAL | BJ7: 2020 | BK7: A | BL7: ADD | BM7: ITEMIZED RECEIPTS | BN7: 44292.194 | BP7: 38194002 | BQ7: SA12 | BR7: F3X | BS7: 4.0403202e+18 | BT7: t | BU7: * BIDEN VICTORY FUND | BV7: 2020 | BW7: SA | BY7: 4.0406202e+18 | BZ7: https://docquery.fec.gov/cgi-bin/fecimg/?202104019443054960 | CA7: Transfers from Authorized Committees
A8: C00744946 | B8: BIDEN VICTORY FUND | C8: 2020 | D8: 12G | E8: 2.0210309e+17 | F8: 11AI | G8: 20552301 | H8: 1503262 | J8: IND | K8: INDIVIDUAL | N8: THEOLOGIDES, STERGIOS | O8: N | Q8: J | R8: STERGIOS | T8: THEOLOGIDES | V8: 950 WESTMINSTER ST NW | X8: WASHINGTON | Y8: DC | Z8: 200014130 | AA8: FANNIE MAE | AB8: ATTORNEY | AD8: 15 | AE8: CONTRIBUTION | AI8: 44113 | AJ8: 2800 | AK8: 2800 | BG8: P | BI8: PRIMARY | BK8: A | BL8: ADD | BM8: ITEMIZED RECEIPTS | BN8: 44329.164 | BR8: F3X | BS8: 4.0309202e+18 | BT8: t | BV8: 2020 | BW8: SA | BY8: 4.0309202e+18 | BZ8: https://docquery.fec.gov/cgi-bin/fecimg/?202103089440311386 | CA8: Contributions From Individuals/Persons Other Than Political Committees
A9: C00703975 | B9: BIDEN FOR PRESIDENT | C9: 2020 | D9: M9 | E9: 2.0200921e+17 | F9: 17A | G9: 11782640 | H9: 1440320 | J9: IND | K9: INDIVIDUAL | L9: C00401224 | N9: THEOLOGIDES, STERGIOS | O9: P | Q9: P | R9: STERGIOS | T9: THEOLOGIDES | V9: 1441 U ST NW | W9: APT 1021 | X9: WASHINGTON | Y9: DC | Z9: 200093537 | AA9: FANNIE MAE | AB9: ATTORNEY | AC9: C00401224 | AD9: 15E | AE9: EARMARKED CONTRIBUTION | AI9: 44066 | AJ9: 2800 | AK9: 5600 | BG9: G2020 | BI9: GENERAL | BJ9: 2020 | BK9: A | BL9: ADD | BM9: ITEMIZED RECEIPTS | BN9: 44104.184 | BP9: 11782640E | BQ9: SA17A | BR9: F3P | BS9: 4.0922202e+18 | BT9: t | BU9: * EARMARKED CONTRIBUTION: SEE BELOW | BV9: 2020 | BW9: SA | BY9: 4.0930202e+18 | BZ9: http://docquery.fec.gov/cgi-bin/fecimg/?202009209276472405 | CA9: Contributions From Individuals/Persons Other Than Political Committees
A10: C00718866 | B10: JON OSSOFF FOR SENATE | C10: 2020 | D10: Q3 | E10: 2.0201016e+17 | F10: 11AI | G10: VTE6ZZVN417 | H10: 1451841 | J10: IND | K10: INDIVIDUAL | L10: C00401224 | N10: THEOLOGIDES, STERGIOS | O10: S | Q10: P | R10: STERGIOS | T10: THEOLOGIDES | V10: 950 WESTMINSTER ST NW | X10: WASHINGTON | Y10: DC | Z10: 200014130 | AA10: FANNIE MAE | AB10: ATTORNEY | AC10: C00401224 | AD10: 15E | AE10: EARMARKED CONTRIBUTION | AI10: 44100 | AJ10: 2800 | AK10: 2800 | BG10: G2020 | BI10: GENERAL | BJ10: 2020 | BK10: A | BL10: ADD | BM10: ITEMIZED RECEIPTS | BN10: 44173.155 | BP10: VTE6ZZVN417E | BQ10: SA11AI | BR10: F3 | BS10: 4.1016202e+18 | BT10: t | BU10: * EARMARKED CONTRIBUTION: SEE BELOW | BV10: 2020 | BW10: SA | BY10: 4.1208202e+18 | BZ10: http://docquery.fec.gov/cgi-bin/fecimg/?202010159295101192 | CA10: Contributions From Individuals/Persons Other Than Political Committees
A11: C00741611 | B11: MONTANANS FOR BULLOCK | C11: 2020 | D11: Q3 | E11: 2.0210608e+17 | F11: 11AI | G11: 2781675 | H11: 1518904 | J11: IND | K11: INDIVIDUAL | N11: THEOLOGIDES, STERGIOS | O11: S | Q11: P | R11: STERGIOS | T11: THEOLOGIDES | V11: 950 WESTMINSTER ST NW | X11: WASHINGTON | Y11: DC | Z11: 200014130 | AA11: FANNIE MAE | AB11: ATTORNEY | AD11: 15E | AE11: EARMARKED CONTRIBUTION | AI11: 44100 | AJ11: 2800 | AK11: 2800 | BG11: G2020 | BI11: GENERAL | BJ11: 2020 | BK11: A | BL11: ADD | BM11: ITEMIZED RECEIPTS | BN11: 44358.156 | BP11: 2781675E | BQ11: SA11AI | BR11: F3 | BS11: 4.0608202e+18 | BT11: t | BU11: * EARMARKED CONTRIBUTION: SEE BELOW | BV11: 2020 | BW11: SA | BY11: 4.0611202e+18 | BZ11: https://docquery.fec.gov/cgi-bin/fecimg/?202106079448844695 | CA11: Contributions From Individuals/Persons Other Than Political Committees
A12: C00640623 | B12: DOUG JONES FOR SENATE COMMITTEE | C12: 2020 | D12: Q3 | E12: 2.0201118e+17 | F12: 11AI | G12: VTQYMTMQDQ7 | H12: 1472474 | J12: IND | K12: INDIVIDUAL | N12: THEOLOGIDES, STERGIOS | O12: S | Q12: P | R12: STERGIOS | T12: THEOLOGIDES | V12: 950 WESTMINSTER ST NW | X12: WASHINGTON | Y12: DC | Z12: 200014130 | AA12: FANNIE MAE | AB12: ATTORNEY | AD12: 15E | AE12: EARMARKED CONTRIBUTION | AI12: 44100 | AJ12: 2800 | AK12: 2800 | BG12: G2020 | BI12: GENERAL | BJ12: 2020 | BK12: A | BL12: ADD | BM12: ITEMIZED RECEIPTS | BN12: 44161.157 | BP12: VTQYMTMQDQ7E | BQ12: SA11AI | BR12: F3 | BS12: 4.1117202e+18 | BT12: t | BU12: * EARMARKED CONTRIBUTION: SEE BELOW | BV12: 2020 | BW12: SA | BY12: 4.1126202e+18 | BZ12: http://docquery.fec.gov/cgi-bin/fecimg/?202011179337013466 | CA12: Contributions From Individuals/Persons Other Than Political Committees
A13: C00702225 | B13: CANDACE FOR 24 | C13: 2020 | D13: Q3 | E13: 2.0201016e+17 | F13: 11AI | G13: 7710037 | H13: 1452728 | J13: IND | K13: INDIVIDUAL | L13: C00401224 | N13: THEOLOGIDES, STERGIOS | O13: H | Q13: P | R13: STERGIOS | T13: THEOLOGIDES | V13: 1441 U ST NW | W13: APT 1021 | X13: WASHINGTON | Y13: DC | Z13: 200093537 | AA13: CORELOGIC | AB13: ATTORNEY | AC13: C00401224 | AD13: 15E | AE13: EARMARKED CONTRIBUTION | AI13: 44066 | AJ13: 1000 | AK13: 1000 | BG13: G2020 | BI13: GENERAL | BJ13: 2020 | BK13: A | BL13: ADD | BM13: ITEMIZED RECEIPTS | BN13: 44163.152 | BP13: 7710037E | BQ13: SA11AI | BR13: F3 | BS13: 4.1016202e+18 | BT13: t | BU13: * EARMARKED CONTRIBUTION: SEE BELOW | BV13: 2020 | BW13: SA | BY13: 4.1128202e+18 | BZ13: http://docquery.fec.gov/cgi-bin/fecimg/?202010159295663761 | CA13: Contributions From Individuals/Persons Other Than Political Committees
A14: C00696153 | B14: JAIME HARRISON FOR US SENATE | C14: 2020 | D14: Q3 | E14: 2.0201016e+17 | F14: 11AI | G14: VVC3HSZAZ01 | H14: 1449356 | J14: IND | K14: INDIVIDUAL | L14: C00401224 | N14: THEOLOGIDES, STERGIOS | O14: S | Q14: P | R14: STERGIOS | T14: THEOLOGIDES | V14: 950 WESTMINSTER ST NW | X14: WASHINGTON | Y14: DC | Z14: 200014130 | AA14: FANNIE MAE | AB14: ATTORNEY | AC14: C00401224 | AD14: 15E | AE14: EARMARKED CONTRIBUTION | AI14: 44100 | AJ14: 2800 | AK14: 2800 | BG14: G2020 | BI14: GENERAL | BJ14: 2020 | BK14: A | BL14: ADD | BM14: ITEMIZED RECEIPTS | BN14: 44170.166 | BP14: VVC3HSZAZ01E | BQ14: SA11AI | BR14: F3 | BS14: 4.1016202e+18 | BT14: t | BU14: * EARMARKED CONTRIBUTION: SEE BELOW | BV14: 2020 | BW14: SA | BY14: 4.1205202e+18 | BZ14: http://docquery.fec.gov/cgi-bin/fecimg/?202010159294115307 | CA14: Contributions From Individuals/Persons Other Than Political Committees
A15: C00709410 | B15: CAL FOR NC | C15: 2020 | D15: Q3 | E15: 2.0201202e+17 | F15: 11AI | G15: VVC0QW4VT20 | H15: 1475453 | J15: IND | K15: INDIVIDUAL | N15: THEOLOGIDES, STERGIOS | O15: S | Q15: P | R15: STERGIOS | T15: THEOLOGIDES | V15: 950 WESTMINSTER ST NW | X15: WASHINGTON | Y15: DC | Z15: 200014130 | AA15: FANNIE MAE | AB15: ATTORNEY | AD15: 15E | AE15: EARMARKED CONTRIBUTION | AI15: 44100 | AJ15: 2800 | AK15: 2800 | BG15: G2020 | BI15: GENERAL | BJ15: 2020 | BK15: A | BL15: ADD | BM15: ITEMIZED RECEIPTS | BN15: 44189.167 | BP15: VVC0QW4VT20E | BQ15: SA11AI | BR15: F3 | BS15: 4.1202202e+18 | BT15: t | BU15: * EARMARKED CONTRIBUTION: SEE BELOW | BV15: 2020 | BW15: SA | BY15: 4.1224202e+18 | BZ15: https://docquery.fec.gov/cgi-bin/fecimg/?202012019337326982 | CA15: Contributions From Individuals/Persons Other Than Political Committees
A16: C00636571 | B16: KATIE PORTER FOR CONGRESS | C16: 2020 | D16: Q3 | E16: 2.0201204e+17 | F16: 11AI | G16: VTEFSZXPN76 | H16: 1480781 | J16: IND | K16: INDIVIDUAL | N16: THEOLOGIDES, STERGIOS | O16: H | Q16: P | R16: STERGIOS | T16: THEOLOGIDES | V16: 1441 U ST NW | X16: WASHINGTON | Y16: DC | Z16: 200093537 | AA16: THEOLOGIDES LAW, PC | AB16: ATTORNEY | AD16: 15E | AE16: EARMARKED CONTRIBUTION | AI16: 44100 | AJ16: 1800 | AK16: 3300 | BG16: G2020 | BI16: GENERAL | BJ16: 2020 | BK16: A | BL16: ADD | BM16: ITEMIZED RECEIPTS | BN16: 44189.173 | BP16: VTEFSZXPN76E | BQ16: SA11AI | BR16: F3 | BS16: 4.1205202e+18 | BT16: t | BU16: * EARMARKED CONTRIBUTION: SEE BELOW | BV16: 2020 | BW16: SA | BY16: 4.1224202e+18 | BZ16: https://docquery.fec.gov/cgi-bin/fecimg/?202012039341042127 | CA16: Contributions From Individuals/Persons Other Than Political Committees
A17: C00709899 | B17: SARA GIDEON FOR MAINE | C17: 2020 | D17: Q3 | E17: 2.0201204e+17 | F17: 11AI | G17: VVC97W6FQY5 | H17: 1477776 | J17: IND | K17: INDIVIDUAL | N17: THEOLOGIDES, STERGIOS | O17: S | Q17: P | R17: STERGIOS | T17: THEOLOGIDES | V17: 950 WESTMINSTER ST NW | X17: WASHINGTON | Y17: DC | Z17: 200014130 | AA17: FANNIE MAE | AB17: ATTORNEY | AD17: 15E | AE17: EARMARKED CONTRIBUTION | AI17: 44100 | AJ17: 2800 | AK17: 2800 | BG17: G2020 | BI17: GENERAL | BJ17: 2020 | BK17: A | BL17: ADD | BM17: ITEMIZED RECEIPTS | BN17: 44202.163 | BP17: VVC97W6FQY5E | BQ17: SA11AI | BR17: F3 | BS17: 4.1204202e+18 | BT17: t | BU17: * EARMARKED CONTRIBUTION: SEE BELOW | BV17: 2020 | BW17: SA | BY17: 4.0106202e+18 | BZ17: https://docquery.fec.gov/cgi-bin/fecimg/?202012039337639643 | CA17: Contributions From Individuals/Persons Other Than Political Committees
V19: =+V17&X17&Y17&Z17 -> 950 WESTMINSTER ST NWWASHINGTONDC200014130
A21: Row Labels | B21: Sum of contribution_receipt_amount
A22: AMY MCGRATH FOR SENATE, INC. | B22: 2800 | C22: D
A23: BIDEN FOR PRESIDENT | B23: 5600 | C23: D
A24: BIDEN VICTORY FUND | B24: 3300 | C24: D
A25: CAL FOR NC | B25: 2800 | C25: D
A26: CANDACE FOR 24 | B26: 1000 | C26: D
A27: CHRIS PAPPAS FOR CONGRESS | B27: 500 | C27: D
A28: DNC SERVICES CORP / DEMOCRATIC NATIONAL COMMITTEE | B28: 2800 | C28: D
A29: DOUG JONES FOR SENATE COMMITTEE | B29: 2800 | C29: D
A30: JAIME HARRISON FOR US SENATE | B30: 2800 | C30: D
A31: JON OSSOFF FOR SENATE | B31: 2800 | C31: D
A32: KATIE PORTER FOR CONGRESS | B32: 2800 | C32: D
A33: MONTANANS FOR BULLOCK | B33: 2800 | C33: D
A34: SARA GIDEON FOR MAINE | B34: 2800 | C34: D
A35: Grand Total | B35: 35600

Sheet Richard Blackley
A1: committee_id | B1: committee_name | C1: report_year | D1: report_type | E1: image_number | F1: line_number | G1: transaction_id | H1: file_number | I1: committee_name | J1: entity_type | K1: entity_type_desc | L1: unused_contbr_id | M1: contributor_prefix | N1: contributor_name | O1: recipient_committee_type | P1: recipient_committee_org_type | Q1: recipient_committee_designation | R1: contributor_first_name | S1: contributor_middle_name | T1: contributor_last_name | U1: contributor_suffix | V1: contributor_street_1 | W1: contributor_street_2 | X1: contributor_city | Y1: contributor_state | Z1: contributor_zip | AA1: contributor_employer | AB1: contributor_occupation | AC1: contributor_id | AD1: receipt_type | AE1: receipt_type_desc | AF1: receipt_type_full | AG1: memo_code | AH1: memo_code_full | AI1: contribution_receipt_date | AJ1: contribution_receipt_amount | AK1: contributor_aggregate_ytd | AL1: candidate_id | AM1: candidate_name | AN1: candidate_first_name | AO1: candidate_last_name | AP1: candidate_middle_name | AQ1: candidate_prefix | AR1: candidate_suffix | AS1: candidate_office | AT1: candidate_office_full | AU1: candidate_office_state | AV1: candidate_office_state_full | AW1: candidate_office_district | AX1: conduit_committee_id | AY1: conduit_committee_name | AZ1: conduit_committee_street1 | BA1: conduit_committee_street2 | BB1: conduit_committee_city | BC1: conduit_committee_state | BD1: conduit_committee_zip | BE1: donor_committee_name | BF1: national_committee_nonfederal_account | BG1: election_type | BH1: election_type_full | BI1: fec_election_type_desc | BJ1: fec_election_year | BK1: amendment_indicator | BL1: amendment_indicator_desc | BM1: schedule_type_full | BN1: load_date | BO1: original_sub_id | BP1: back_reference_transaction_id | BQ1: back_reference_schedule_name | BR1: filing_form | BS1: link_id | BT1: is_individual | BU1: memo_text | BV1: two_year_transaction_period | BW1: schedule_type | BX1: increased_limit | BY1: sub_id | BZ1: pdf_url | CA1: line_number_label
A2: C00326595 | B2: CAPITAL ONE FINANCIAL CORP. ASSOC. POLITICAL FUND | C2: 2019 | D2: M11 | E2: 2.0191121e+17 | F2: 11AI | G2: A2019-2463543 | H2: 1363758 | J2: IND | K2: INDIVIDUAL | N2: BLACKLEY, RICHARD S | O2: Q | P2: C | Q2: B | R2: RICHARD | S2: S | T2: BLACKLEY | V2: 43414 TURNBERRY ISLE COURT | X2: LEESBURG | Y2: VA | Z2: 20176 | AA2: CAPITAL ONE | AB2: EXECUTIVE COMMITTEE | AD2: 15 | AE2: CONTRIBUTION | AI2: 43749 | AJ2: 192.31 | AK2: 4038.51 | BG2: P | BI2: PRIMARY | BK2: A | BL2: ADD | BM2: ITEMIZED RECEIPTS | BN2: 43790.095 | BR2: F3X | BS2: 4.1120202e+18 | BT2: t | BV2: 2020 | BW2: SA | BY2: 4.1120202e+18 | BZ2: http://docquery.fec.gov/cgi-bin/fecimg/?201911209165667838 | CA2: Contributions From Individuals/Persons Other Than Political Committees
A3: C00326595 | B3: CAPITAL ONE FINANCIAL CORP. ASSOC. POLITICAL FUND | C3: 2019 | D3: M11 | E3: 2.0191121e+17 | F3: 11AI | G3: A2019-2488881 | H3: 1363758 | J3: IND | K3: INDIVIDUAL | N3: BLACKLEY, RICHARD S | O3: Q | P3: C | Q3: B | R3: RICHARD | S3: S | T3: BLACKLEY | V3: 43414 TURNBERRY ISLE COURT | X3: LEESBURG | Y3: VA | Z3: 20176 | AA3: CAPITAL ONE | AB3: EXECUTIVE COMMITTEE | AD3: 15 | AE3: CONTRIBUTION | AI3: 43763 | AJ3: 192.31 | AK3: 4230.82 | BG3: P | BI3: PRIMARY | BK3: A | BL3: ADD | BM3: ITEMIZED RECEIPTS | BN3: 43790.095 | BR3: F3X | BS3: 4.1120202e+18 | BT3: t | BV3: 2020 | BW3: SA | BY3: 4.1120202e+18 | BZ3: http://docquery.fec.gov/cgi-bin/fecimg/?201911209165667838 | CA3: Contributions From Individuals/Persons Other Than Political Committees
A4: C00326595 | B4: CAPITAL ONE FINANCIAL CORP. ASSOC. POLITICAL FUND | C4: 2019 | D4: M12 | E4: 2.0191218e+17 | F4: 11AI | G4: A2019-2621013 | H4: 1366599 | J4: IND | K4: INDIVIDUAL | N4: BLACKLEY, RICHARD S | O4: Q | P4: C | Q4: B | R4: RICHARD | S4: S | T4: BLACKLEY | V4: 43414 TURNBERRY ISLE COURT | X4: LEESBURG | Y4: VA | Z4: 20176 | AA4: CAPITAL ONE | AB4: EXECUTIVE COMMITTEE | AD4: 15 | AE4: CONTRIBUTION | AI4: 43777 | AJ4: 192.31 | AK4: 4423.13 | BG4: P | BI4: PRIMARY | BK4: A | BL4: ADD | BM4: ITEMIZED RECEIPTS | BN4: 43818.071 | BR4: F3X | BS4: 4.1218202e+18 | BT4: t | BV4: 2020 | BW4: SA | BY4: 4.1218202e+18 | BZ4: http://docquery.fec.gov/cgi-bin/fecimg/?201912179166318425 | CA4: Contributions From Individuals/Persons Other Than Political Committees
A5: C00326595 | B5: CAPITAL ONE FINANCIAL CORP. ASSOC. POLITICAL FUND | C5: 2019 | D5: M12 | E5: 2.0191218e+17 | F5: 11AI | G5: A2019-2714183 | H5: 1366599 | J5: IND | K5: INDIVIDUAL | N5: BLACKLEY, RICHARD S | O5: Q | P5: C | Q5: B | R5: RICHARD | S5: S | T5: BLACKLEY | V5: 43414 TURNBERRY ISLE COURT | X5: LEESBURG | Y5: VA | Z5: 20176 | AA5: CAPITAL ONE | AB5: EXECUTIVE COMMITTEE | AD5: 15 | AE5: CONTRIBUTION | AI5: 43791 | AJ5: 192.31 | AK5: 4615.44 | BG5: P | BI5: PRIMARY | BK5: A | BL5: ADD | BM5: ITEMIZED RECEIPTS | BN5: 43818.071 | BR5: F3X | BS5: 4.1218202e+18 | BT5: t | BV5: 2020 | BW5: SA | BY5: 4.1218202e+18 | BZ5: http://docquery.fec.gov/cgi-bin/fecimg/?201912179166318425 | CA5: Contributions From Individuals/Persons Other Than Political Committees
A6: C00326595 | B6: CAPITAL ONE FINANCIAL CORP. ASSOC. POLITICAL FUND | C6: 2019 | D6: YE | E6: 2.0200131e+17 | F6: 11AI | G6: A2019-2948511 | H6: 1375953 | J6: IND | K6: INDIVIDUAL | N6: BLACKLEY, RICHARD S | O6: Q | P6: C | Q6: B | R6: RICHARD | S6: S | T6: BLACKLEY | V6: 43414 TURNBERRY ISLE COURT | X6: LEESBURG | Y6: VA | Z6: 20176 | AA6: CAPITAL ONE | AB6: EXECUTIVE COMMITTEE | AD6: 15 | AE6: CONTRIBUTION | AI6: 43805 | AJ6: 192.31 | AK6: 4807.75 | BG6: P | BI6: PRIMARY | BK6: A | BL6: ADD | BM6: ITEMIZED RECEIPTS | BN6: 43882.104 | BR6: F3X | BS6: 4.0130202e+18 | BT6: t | BV6: 2020 | BW6: SA | BY6: 4.0220202e+18 | BZ6: http://docquery.fec.gov/cgi-bin/fecimg/?202001309182502729 | CA6: Contributions From Individuals/Persons Other Than Political Committees
A7: C00326595 | B7: CAPITAL ONE FINANCIAL CORP. ASSOC. POLITICAL FUND | C7: 2019 | D7: YE | E7: 2.0200131e+17 | F7: 11AI | G7: A2019-2954736 | H7: 1375953 | J7: IND | K7: INDIVIDUAL | N7: BLACKLEY, RICHARD S | O7: Q | P7: C | Q7: B | R7: RICHARD | S7: S | T7: BLACKLEY | V7: 43414 TURNBERRY ISLE COURT | X7: LEESBURG | Y7: VA | Z7: 20176 | AA7: CAPITAL ONE | AB7: EXECUTIVE COMMITTEE | AD7: 15 | AE7: CONTRIBUTION | AI7: 43819 | AJ7: 192.25 | AK7: 5000 | BG7: P | BI7: PRIMARY | BK7: A | BL7: ADD | BM7: ITEMIZED RECEIPTS | BN7: 43882.104 | BR7: F3X | BS7: 4.0130202e+18 | BT7: t | BV7: 2020 | BW7: SA | BY7: 4.0220202e+18 | BZ7: http://docquery.fec.gov/cgi-bin/fecimg/?202001309182502729 | CA7: Contributions From Individuals/Persons Other Than Political Committees
A8: C00326595 | B8: CAPITAL ONE FINANCIAL CORP. ASSOC. POLITICAL FUND | C8: 2020 | D8: M2 | E8: 2.0200219e+17 | F8: 11AI | G8: A2020-40733 | H8: 1383171 | J8: IND | K8: INDIVIDUAL | N8: BLACKLEY, RICHARD S | O8: Q | P8: C | Q8: B | R8: RICHARD | S8: S | T8: BLACKLEY | V8: 43414 TURNBERRY ISLE COURT | X8: LEESBURG | Y8: VA | Z8: 20176 | AA8: CAPITAL ONE | AB8: EXECUTIVE COMMITTEE | AD8: 15 | AE8: CONTRIBUTION | AI8: 43847 | AJ8: 192.31 | AK8: 384.62 | BG8: P | BI8: PRIMARY | BK8: A | BL8: ADD | BM8: ITEMIZED RECEIPTS | BN8: 43888.064 | BR8: F3X | BS8: 4.0219202e+18 | BT8: t | BV8: 2020 | BW8: SA | BY8: 4.0226202e+18 | BZ8: http://docquery.fec.gov/cgi-bin/fecimg/?202002189186519495 | CA8: Contributions From Individuals/Persons Other Than Political Committees
A9: C00326595 | B9: CAPITAL ONE FINANCIAL CORP. ASSOC. POLITICAL FUND | C9: 2020 | D9: M2 | E9: 2.0200219e+17 | F9: 11AI | G9: A2020-85690 | H9: 1383171 | J9: IND | K9: INDIVIDUAL | N9: BLACKLEY, RICHARD S | O9: Q | P9: C | Q9: B | R9: RICHARD | S9: S | T9: BLACKLEY | V9: 43414 TURNBERRY ISLE COURT | X9: LEESBURG | Y9: VA | Z9: 20176 | AA9: CAPITAL ONE | AB9: EXECUTIVE COMMITTEE | AD9: 15 | AE9: CONTRIBUTION | AI9: 43861 | AJ9: 192.31 | AK9: 576.93 | BG9: P | BI9: PRIMARY | BK9: A | BL9: ADD | BM9: ITEMIZED RECEIPTS | BN9: 43888.064 | BR9: F3X | BS9: 4.0219202e+18 | BT9: t | BV9: 2020 | BW9: SA | BY9: 4.0226202e+18 | BZ9: http://docquery.fec.gov/cgi-bin/fecimg/?202002189186519495 | CA9: Contributions From Individuals/Persons Other Than Political Committees
A10: C00326595 | B10: CAPITAL ONE FINANCIAL CORP. ASSOC. POLITICAL FUND | C10: 2020 | D10: M3 | E10: 2.0200319e+17 | F10: 11AI | G10: A2020-283789 | H10: 1390603 | J10: IND | K10: INDIVIDUAL | N10: BLACKLEY, RICHARD S | O10: Q | P10: C | Q10: B | R10: RICHARD | S10: S | T10: BLACKLEY | V10: 43414 TURNBERRY ISLE COURT | X10: LEESBURG | Y10: VA | Z10: 20176 | AA10: CAPITAL ONE | AB10: EXECUTIVE COMMITTEE | AD10: 15 | AE10: CONTRIBUTION | AI10: 43875 | AJ10: 192.31 | AK10: 769.24 | BG10: P | BI10: PRIMARY | BK10: A | BL10: ADD | BM10: ITEMIZED RECEIPTS | BN10: 43910.096 | BR10: F3X | BS10: 4.0319202e+18 | BT10: t | BV10: 2020 | BW10: SA | BY10: 4.0319202e+18 | BZ10: http://docquery.fec.gov/cgi-bin/fecimg/?202003189203897183 | CA10: Contributions From Individuals/Persons Other Than Political Committees
A11: C00326595 | B11: CAPITAL ONE FINANCIAL CORP. ASSOC. POLITICAL FUND | C11: 2020 | D11: M3 | E11: 2.0200319e+17 | F11: 11AI | G11: A2020-313442 | H11: 1390603 | J11: IND | K11: INDIVIDUAL | N11: BLACKLEY, RICHARD S | O11: Q | P11: C | Q11: B | R11: RICHARD | S11: S | T11: BLACKLEY | V11: 43414 TURNBERRY ISLE COURT | X11: LEESBURG | Y11: VA | Z11: 20176 | AA11: CAPITAL ONE | AB11: EXECUTIVE COMMITTEE | AD11: 15 | AE11: CONTRIBUTION | AI11: 43889 | AJ11: 192.31 | AK11: 961.55 | BG11: P | BI11: PRIMARY | BK11: A | BL11: ADD | BM11: ITEMIZED RECEIPTS | BN11: 43910.096 | BR11: F3X | BS11: 4.0319202e+18 | BT11: t | BV11: 2020 | BW11: SA | BY11: 4.0319202e+18 | BZ11: http://docquery.fec.gov/cgi-bin/fecimg/?202003189203897184 | CA11: Contributions From Individuals/Persons Other Than Political Committees
A12: C00326595 | B12: CAPITAL ONE FINANCIAL CORP. ASSOC. POLITICAL FUND | C12: 2020 | D12: M4 | E12: 2.0200418e+17 | F12: 11AI | G12: A2020-532829 | H12: 1401883 | J12: IND | K12: INDIVIDUAL | N12: BLACKLEY, RICHARD S | O12: Q | P12: C | Q12: B | R12: RICHARD | S12: S | T12: BLACKLEY | V12: 43414 TURNBERRY ISLE COURT | X12: LEESBURG | Y12: VA | Z12: 20176 | AA12: CAPITAL ONE | AB12: EXECUTIVE COMMITTEE | AD12: 15 | AE12: CONTRIBUTION | AI12: 43903 | AJ12: 192.31 | AK12: 1153.86 | BG12: P | BI12: PRIMARY | BK12: A | BL12: ADD | BM12: ITEMIZED RECEIPTS | BN12: 43942.074 | BR12: F3X | BS12: 4.0418202e+18 | BT12: t | BV12: 2020 | BW12: SA | BY12: 4.0420202e+18 | BZ12: http://docquery.fec.gov/cgi-bin/fecimg/?202004179219700995 | CA12: Contributions From Individuals/Persons Other Than Political Committees
A13: C00326595 | B13: CAPITAL ONE FINANCIAL CORP. ASSOC. POLITICAL FUND | C13: 2020 | D13: M4 | E13: 2.0200418e+17 | F13: 11AI | G13: A2020-555628 | H13: 1401883 | J13: IND | K13: INDIVIDUAL | N13: BLACKLEY, RICHARD S | O13: Q | P13: C | Q13: B | R13: RICHARD | S13: S | T13: BLACKLEY | V13: 43414 TURNBERRY ISLE COURT | X13: LEESBURG | Y13: VA | Z13: 20176 | AA13: CAPITAL ONE | AB13: EXECUTIVE COMMITTEE | AD13: 15 | AE13: CONTRIBUTION | AI13: 43917 | AJ13: 192.31 | AK13: 1346.17 | BG13: P | BI13: PRIMARY | BK13: A | BL13: ADD | BM13: ITEMIZED RECEIPTS | BN13: 43942.074 | BR13: F3X | BS13: 4.0418202e+18 | BT13: t | BV13: 2020 | BW13: SA | BY13: 4.0420202e+18 | BZ13: http://docquery.fec.gov/cgi-bin/fecimg/?202004179219700996 | CA13: Contributions From Individuals/Persons Other Than Political Committees
... A32: C00326595 | B32: CAPITAL ONE FINANCIAL CORP. ASSOC. POLITICAL FUND | C32: 2020 | D32: 30G | E32: 2.0201204e+17 | F32: 11AI | G32: A2020-2501812 | H32: 1479855 | J32: IND | K32: INDIVIDUAL | N32: BLACKLEY, RICHARD S | O32: Q | P32: C | Q32: B | R32: RICHARD | S32: S | T32: BLACKLEY | V32: 43414 TURNBERRY ISLE COURT | X32: LEESBURG | Y32: VA | Z32: 20176 | AA32: CAPITAL ONE | AB32: EXECUTIVE COMMITTEE | AD32: 15 | AE32: CONTRIBUTION | AI32: 44155 | AJ32: 192.31 | AK32: 4615.44 | BG32: P | BI32: PRIMARY | BK32: A | BL32: ADD | BM32: ITEMIZED RECEIPTS | BN32: 44197.155 | BR32: F3X | BS32: 4.1204202e+18 | BT32: t | BV32: 2020 | BW32: SA | BY32: 4.0101202e+18 | BZ32: https://docquery.fec.gov/cgi-bin/fecimg/?202012039340006655 | CA32: Contributions From Individuals/Persons Other Than Political Committees
V35: =+V32&X32&Y32&Z32 -> 43414 TURNBERRY ISLE COURTLEESBURGVA20176
A37: Row Labels | B37: Sum of contribution_receipt_amount | D37: D | E37: R
A38: CAPITAL ONE FINANCIAL CORP. ASSOC. POLITICAL FUND | B38: 5961.49 | D38: 0.5281 | E38: 0.4719
A39: Grand Total | B39: 5961.49

Sheet Karin Kimbrough
A1: committee_id | B1: committee_name | C1: report_year | D1: report_type | E1: image_number | F1: line_number | G1: transaction_id | H1: file_number | I1: committee_name | J1: entity_type | K1: entity_type_desc | L1: unused_contbr_id | M1: contributor_prefix | N1: contributor_name | O1: recipient_committee_type | P1: recipient_committee_org_type | Q1: recipient_committee_designation | R1: contributor_first_name | S1: contributor_middle_name | T1: contributor_last_name | U1: contributor_suffix | V1: contributor_street_1 | W1: contributor_street_2 | X1: contributor_city | Y1: contributor_state | Z1: contributor_zip | AA1: contributor_employer | AB1: contributor_occupation | AC1: contributor_id | AD1: receipt_type | AE1: receipt_type_desc | AF1: receipt_type_full | AG1: memo_code | AH1: memo_code_full | AI1: contribution_receipt_date | AJ1: contribution_receipt_amount | AK1: contributor_aggregate_ytd | AL1: candidate_id | AM1: candidate_name | AN1: candidate_first_name | AO1: candidate_last_name | AP1: candidate_middle_name | AQ1: candidate_prefix | AR1: candidate_suffix | AS1: candidate_office | AT1: candidate_office_full | AU1: candidate_office_state | AV1: candidate_office_state_full | AW1: candidate_office_district | AX1: conduit_committee_id | AY1: conduit_committee_name | AZ1: conduit_committee_street1 | BA1: conduit_committee_street2 | BB1: conduit_committee_city | BC1: conduit_committee_state | BD1: conduit_committee_zip | BE1: donor_committee_name | BF1: national_committee_nonfederal_account | BG1: election_type | BH1: election_type_full | BI1: fec_election_type_desc | BJ1: fec_election_year | BK1: amendment_indicator | BL1: amendment_indicator_desc | BM1: schedule_type_full | BN1: load_date | BO1: original_sub_id | BP1: back_reference_transaction_id | BQ1: back_reference_schedule_name | BR1: filing_form | BS1: link_id | BT1: is_individual | BU1: memo_text | BV1: two_year_transaction_period | BW1: schedule_type | BX1: increased_limit | BY1: sub_id | BZ1: pdf_url | CA1: line_number_label
A2: C00718866 | B2: JON OSSOFF FOR SENATE | C2: 2020 | D2: 12R | E2: 2.0210603e+17 | F2: 11AI | G2: 5518895 | H2: 1518550 | J2: IND | K2: INDIVIDUAL | N2: KIMBROUGH, KARIN | O2: S | Q2: P | R2: KARIN | T2: KIMBROUGH | V2: 420 RIVERSIDE DR | X2: NEW YORK | Y2: NY | Z2: 100257755 | AA2: LINKEDIN | AB2: ECONOMIST | AD2: 15E | AE2: EARMARKED CONTRIBUTION | AI2: 44177 | AJ2: 250 | AK2: 250 | BG2: O2020 | BH2: RUN-OFF GENERAL | BJ2: 2020 | BK2: A | BL2: ADD | BM2: ITEMIZED RECEIPTS | BN2: 44358.157 | BP2: 5518895E | BQ2: SA11AI | BR2: F3 | BS2: 4.0604202e+18 | BT2: t | BU2: * EARMARKED CONTRIBUTION: SEE BELOW | BV2: 2020 | BW2: SA | BY2: 4.0611202e+18 | BZ2: https://docquery.fec.gov/cgi-bin/fecimg/?202106029448611499 | CA2: Contributions From Individuals/Persons Other Than Political Committees
A3: C00736876 | B3: WARNOCK FOR GEORGIA | C3: 2020 | D3: 12S | E3: 2.0201225e+17 | F3: 11AI | G3: 11438160 | H3: 1484293 | J3: IND | K3: INDIVIDUAL | L3: C00401224 | N3: KIMBROUGH, KARIN | O3: S | Q3: P | R3: KARIN | T3: KIMBROUGH | V3: 420 RIVERSIDE DR | W3: APT 2E | X3: NEW YORK | Y3: NY | Z3: 100257755 | AA3: LINKEDIN | AB3: ECONOMIST | AC3: C00401224 | AD3: 15E | AE3: EARMARKED CONTRIBUTION | AI3: 44177 | AJ3: 500 | AK3: 500 | BG3: G2020 | BH3: RUN-OFF SPECIAL | BI3: GENERAL | BJ3: 2020 | BK3: A | BL3: ADD | BM3: ITEMIZED RECEIPTS | BN3: 44219.477 | BP3: 11438160E | BQ3: SA11AI | BR3: F3 | BS3: 4.1226202e+18 | BT3: t | BU3: * EARMARKED CONTRIBUTION: SEE BELOW | BV3: 2020 | BW3: SA | BY3: 4.0123202e+18 | BZ3: https://docquery.fec.gov/cgi-bin/fecimg/?202012249394094609 | CA3: Contributions From Individuals/Persons Other Than Political Committees
V5: =+V3&X3&Y3&Z3 -> 420 RIVERSIDE DRNEW YORKNY100257755 | AJ5: =SUM(AJ2:AJ4) -> 750

Sheet Michael Heid
A1: committee_id | B1: committee_name | C1: report_year | D1: report_type | E1: image_number | F1: line_number | G1: transaction_id | H1: file_number | I1: committee_name | J1: entity_type | K1: entity_type_desc | L1: unused_contbr_id | M1: contributor_prefix | N1: contributor_name | O1: recipient_committee_type | P1: recipient_committee_org_type | Q1: recipient_committee_designation | R1: contributor_first_name | S1: contributor_middle_name | T1: contributor_last_name | U1: contributor_suffix | V1: contributor_street_1 | W1: contributor_street_2 | X1: contributor_city | Y1: contributor_state | Z1: contributor_zip | AA1: contributor_employer | AB1: contributor_occupation | AC1: contributor_id | AD1: receipt_type | AE1: receipt_type_desc | AF1: receipt_type_full | AG1: memo_code | AH1: memo_code_full | AI1: contribution_receipt_date | AJ1: contribution_receipt_amount | AK1: contributor_aggregate_ytd | AL1: candidate_id | AM1: candidate_name | AN1: candidate_first_name | AO1: candidate_last_name | AP1: candidate_middle_name | AQ1: candidate_prefix | AR1: candidate_suffix | AS1: candidate_office | AT1: candidate_office_full | AU1: candidate_office_state | AV1: candidate_office_state_full | AW1: candidate_office_district | AX1: conduit_committee_id | AY1: conduit_committee_name | AZ1: conduit_committee_street1 | BA1: conduit_committee_street2 | BB1: conduit_committee_city | BC1: conduit_committee_state | BD1: conduit_committee_zip | BE1: donor_committee_name | BF1: national_committee_nonfederal_account | BG1: election_type | BH1: election_type_full | BI1: fec_election_type_desc | BJ1: fec_election_year | BK1: amendment_indicator | BL1: amendment_indicator_desc | BM1: schedule_type_full | BN1: load_date | BO1: original_sub_id | BP1: back_reference_transaction_id | BQ1: back_reference_schedule_name | BR1: filing_form | BS1: link_id | BT1: is_individual | BU1: memo_text | BV1: two_year_transaction_period | BW1: schedule_type | BX1: increased_limit | BY1: sub_id | BZ1: pdf_url | CA1: line_number_label
A2: C00401224 | B2: ACTBLUE | C2: 2019 | D2: YE | E2: 2.020013e+17 | F2: 11AI | G2: SA11AI_193740683 | H2: 1378435 | J2: IND | K2: INDIVIDUAL | N2: HEID, MICHAEL | O2: V | Q2: U | R2: MICHAEL | T2: HEID | V2: 117 LEE ROAD | X2: PITTSBURGH | Y2: PA | Z2: 15237 | AA2: NOT EMPLOYED | AB2: NOT EMPLOYED | AF2: EARMARK | AI2: 43815 | AJ2: 100 | AK2: 100 | BF2: _x000D_ | BK2: A | BL2: ADD | BM2: ITEMIZED RECEIPTS | BN2: 43894.298 | BR2: F3X | BS2: 4.0201202e+18 | BT2: t | BU2: EARMARKED FOR AMY FOR AMERICA (C00696419) | BV2: 2020 | BW2: SA | BY2: 4.0302202e+18 | BZ2: http://docquery.fec.gov/cgi-bin/fecimg/?202001299170592378 | CA2: Contributions From Individuals/Persons Other Than Political Committees
A3: C00401224 | B3: ACTBLUE | C3: 2020 | D3: M2 | E3: 2.0200222e+17 | F3: 11AI | G3: SA11AI_197813221 | H3: 1385527 | J3: IND | K3: INDIVIDUAL | N3: HEID, MICHAEL | O3: V | Q3: U | R3: MICHAEL | T3: HEID | V3: 117 LEE ROAD | X3: PITTSBURGH | Y3: PA | Z3: 15237 | AA3: NOT EMPLOYED | AB3: NOT EMPLOYED | AF3: EARMARK | AI3: 43832 | AJ3: 100 | AK3: 100 | BK3: A | BL3: ADD | BM3: ITEMIZED RECEIPTS | BN3: 43915.263 | BR3: F3X | BS3: 4.0221202e+18 | BT3: t | BU3: EARMARKED FOR AMY FOR AMERICA (C00696419) | BV3: 2020 | BW3: SA | BY3: 4.0324202e+18 | BZ3: http://docquery.fec.gov/cgi-bin/fecimg/?202002219200710831 | CA3: Contributions From Individuals/Persons Other Than Political Committees
A4: C00401224 | B4: ACTBLUE | C4: 2020 | D4: M3 | E4: 2.0200321e+17 | F4: 11AI | G4: SA11AI_204921141 | H4: 1391686 | J4: IND | K4: INDIVIDUAL | N4: HEID, MICHAEL | O4: V | Q4: U | R4: MICHAEL | T4: HEID | V4: 117 LEE ROAD | X4: PITTSBURGH | Y4: PA | Z4: 15237 | AA4: NOT EMPLOYED | AB4: NOT EMPLOYED | AF4: EARMARK | AI4: 43863 | AJ4: 25 | AK4: 125 | BK4: A | BL4: ADD | BM4: ITEMIZED RECEIPTS | BN4: 43924.473 | BR4: F3X | BS4: 4.0323202e+18 | BT4: t | BU4: EARMARKED FOR AMY FOR AMERICA (C00696419) | BV4: 2020 | BW4: SA | BY4: 4.0402202e+18 | BZ4: http://docquery.fec.gov/cgi-bin/fecimg/?202003209211349729 | CA4: Contributions From Individuals/Persons Other Than Political Committees
A5: C00401224 | B5: ACTBLUE | C5: 2020 | D5: M4 | E5: 2.0200422e+17 | F5: 11AI | G5: SA11AI_215550876 | H5: 1402724 | J5: IND | K5: INDIVIDUAL | N5: HEID, MICHAEL | O5: V | Q5: U | R5: MICHAEL | T5: HEID | V5: 117 LEE ROAD | X5: PITTSBURGH | Y5: PA | Z5: 15237 | AA5: NOT EMPLOYED | AB5: NOT EMPLOYED | AF5: EARMARK | AI5: 43892 | AJ5: 25 | AK5: 150 | BK5: A | BL5: ADD | BM5: ITEMIZED RECEIPTS | BN5: 43966.323 | BR5: F3X | BS5: 4.0420202e+18 | BT5: t | BU5: EARMARKED FOR AMY FOR AMERICA (C00696419) | BV5: 2020 | BW5: SA | BY5: 4.0514202e+18 | BZ5: http://docquery.fec.gov/cgi-bin/fecimg/?202004219229138920 | CA5: Contributions From Individuals/Persons Other Than Political Committees
A6: C00696419 | B6: AMY FOR AMERICA | C6: 2020 | D6: M4 | E6: 2.0200716e+17 | F6: 17A | G6: 1611598 | H6: 1424519 | J6: IND | K6: INDIVIDUAL | L6: C00401224 | N6: HEID, MICHAEL | O6: P | Q6: P | R6: MICHAEL | T6: HEID | V6: 117 LEE RD | X6: PITTSBURGH | Y6: PA | Z6: 152373908 | AA6: NOT EMPLOYED | AB6: NOT EMPLOYED | AC6: C00401224 | AD6: 15E | AE6: EARMARKED CONTRIBUTION | AI6: 43892 | AJ6: 25 | AK6: 250 | BG6: P2020 | BI6: PRIMARY | BJ6: 2020 | BK6: N | BL6: NO CHANGE | BM6: ITEMIZED RECEIPTS | BN6: 44029.117 | BP6: 1611598E | BQ6: SA17A | BR6: F3P | BS6: 4.0716202e+18 | BT6: t | BU6: * EARMARKED CONTRIBUTION: SEE BELOW | BV6: 2020 | BW6: SA | BY6: 4.0716202e+18 | BZ6: http://docquery.fec.gov/cgi-bin/fecimg/?202007159249971242 | CA6: Contributions From Individuals/Persons Other Than Political Committees
A7: C00696419 | B7: AMY FOR AMERICA | C7: 2020 | D7: M3 | E7: 2.0200716e+17 | F7: 17A | G7: 1250568 | H7: 1424472 | J7: IND | K7: INDIVIDUAL | N7: HEID, MICHAEL | O7: P | Q7: P | R7: MICHAEL | T7: HEID | V7: 117 LEE RD | X7: PITTSBURGH | Y7: PA | Z7: 152373908 | AA7: NOT EMPLOYED | AB7: NOT EMPLOYED | AD7: 15E | AE7: EARMARKED CONTRIBUTION | AI7: 43863 | AJ7: 25 | AK7: 225 | BG7: P2020 | BI7: PRIMARY | BJ7: 2020 | BK7: A | BL7: ADD | BM7: ITEMIZED RECEIPTS | BN7: 44033.137 | BP7: 1250568E | BQ7: SA17A | BR7: F3P | BS7: 4.0716202e+18 | BT7: t | BU7: * EARMARKED CONTRIBUTION: SEE BELOW | BV7: 2020 | BW7: SA | BY7: 4.0720202e+18 | BZ7: http://docquery.fec.gov/cgi-bin/fecimg/?202007159249951823 | CA7: Contributions From Individuals/Persons Other Than Political Committees
V9: =+V5&X5&Y5&Z5 -> 117 LEE ROADPITTSBURGHPA15237
A10: Row Labels | B10: Sum of contribution_receipt_amount
A11: ACTBLUE | B11: 250
A12: AMY FOR AMERICA | B12: 50
A13: Grand Total | B13: 300

Sheet Renee Glover
A1: committee_id | B1: committee_name | C1: report_year | D1: report_type | E1: image_number | F1: line_number | G1: transaction_id | H1: file_number | I1: committee_name | J1: entity_type | K1: entity_type_desc | L1: unused_contbr_id | M1: contributor_prefix | N1: contributor_name | O1: recipient_committee_type | P1: recipient_committee_org_type | Q1: recipient_committee_designation | R1: contributor_first_name | S1: contributor_middle_name | T1: contributor_last_name | U1: contributor_suffix | V1: contributor_street_1 | W1: contributor_street_2 | X1: contributor_city | Y1: contributor_state | Z1: contributor_zip | AA1: contributor_employer | AB1: contributor_occupation | AC1: contributor_id | AD1: receipt_type | AE1: receipt_type_desc | AF1: receipt_type_full | AG1: memo_code | AH1: memo_code_full | AI1: contribution_receipt_date | AJ1: contribution_receipt_amount | AK1: contributor_aggregate_ytd | AL1: candidate_id | AM1: candidate_name | AN1: candidate_first_name | AO1: candidate_last_name | AP1: candidate_middle_name | AQ1: candidate_prefix | AR1: candidate_suffix | AS1: candidate_office | AT1: candidate_office_full | AU1: candidate_office_state | AV1: candidate_office_state_full | AW1: candidate_office_district | AX1: conduit_committee_id | AY1: conduit_committee_name | AZ1: conduit_committee_street1 | BA1: conduit_committee_street2 | BB1: conduit_committee_city | BC1: conduit_committee_state | BD1: conduit_committee_zip | BE1: donor_committee_name | BF1: national_committee_nonfederal_account | BG1: election_type | BH1: election_type_full | BI1: fec_election_type_desc | BJ1: fec_election_year | BK1: amendment_indicator | BL1: amendment_indicator_desc | BM1: schedule_type_full | BN1: load_date | BO1: original_sub_id | BP1: back_reference_transaction_id | BQ1: back_reference_schedule_name | BR1: filing_form | BS1: link_id | BT1: is_individual | BU1: memo_text | BV1: two_year_transaction_period | BW1: schedule_type | BX1: increased_limit | BY1: sub_id | BZ1: pdf_url | CA1: line_number_label
A2: C00147512 | B2: CONGRESSIONAL BLACK CAUCUS PAC | C2: 2020 | D2: M9 | E2: 2.020092e+17 | F2: 11AI | G2: VNW66J06GJ1 | H2: 1439904 | J2: IND | K2: INDIVIDUAL | N2: GLOVER, RENEE | O2: Q | Q2: U | R2: RENEE | T2: GLOVER | V2: 553 AUBURN AVE NE | X2: ATLANTA | Y2: GA | Z2: 303121941 | AA2: THE CATALYST GROUP LLC | AB2: BUSINESS CONSULTANT | AD2: 15 | AE2: CONTRIBUTION | AI2: 44053 | AJ2: 25 | AK2: 450 | BG2: P | BI2: PRIMARY | BK2: A | BL2: ADD | BM2: ITEMIZED RECEIPTS | BN2: 44106.151 | BR2: F3X | BS2: 4.0920202e+18 | BT2: t | BV2: 2020 | BW2: SA | BY2: 4.1002202e+18 | BZ2: http://docquery.fec.gov/cgi-bin/fecimg/?202009199275282561 | CA2: Contributions From Individuals/Persons Other Than Political Committees
A3: C00147512 | B3: CONGRESSIONAL BLACK CAUCUS PAC | C3: 2020 | D3: M9 | E3: 2.020092e+17 | F3: 11AI | G3: VNW66J1QCZ1 | H3: 1439904 | J3: IND | K3: INDIVIDUAL | N3: GLOVER, RENEE | O3: Q | Q3: U | R3: RENEE | T3: GLOVER | V3: 553 AUBURN AVE NE | X3: ATLANTA | Y3: GA | Z3: 303121941 | AA3: THE CATALYST GROUP LLC | AB3: BUSINESS CONSULTANT | AD3: 15 | AE3: CONTRIBUTION | AI3: 44074 | AJ3: 25 | AK3: 450 | BG3: P | BI3: PRIMARY | BK3: A | BL3: ADD | BM3: ITEMIZED RECEIPTS | BN3: 44106.151 | BR3: F3X | BS3: 4.0920202e+18 | BT3: t | BV3: 2020 | BW3: SA | BY3: 4.1002202e+18 | BZ3: http://docquery.fec.gov/cgi-bin/fecimg/?202009199275282561 | CA3: Contributions From Individuals/Persons Other Than Political Committees
A4: C00147512 | B4: CONGRESSIONAL BLACK CAUCUS PAC | C4: 2020 | D4: YE | E4: 2.021013e+17 | F4: 11AI | G4: VNW66JYTNE1 | H4: 1492994 | J4: IND | K4: INDIVIDUAL | N4: GLOVER, RENEE | O4: Q | Q4: U | R4: RENEE | T4: GLOVER | V4: 553 AUBURN AVE NE | X4: ATLANTA | Y4: GA | Z4: 303121941 | AA4: THE CATALYST GROUP LLC | AB4: BUSINESS CONSULTANT | AD4: 15 | AE4: CONTRIBUTION | AI4: 44165 | AJ4: 50 | AK4: 750 | BG4: P | BI4: PRIMARY | BK4: A | BL4: ADD | BM4: ITEMIZED RECEIPTS | BN4: 44229.151 | BR4: F3X | BS4: 4.0130202e+18 | BT4: t | BV4: 2020 | BW4: SA | BY4: 4.0202202e+18 | BZ4: https://docquery.fec.gov/cgi-bin/fecimg/?202101299413841311 | CA4: Contributions From Individuals/Persons Other Than Political Committees
A5: C00147512 | B5: CONGRESSIONAL BLACK CAUCUS PAC | C5: 2020 | D5: 12G | E5: 2.0201023e+17 | F5: 11AI | G5: VNW66JEQW66 | H5: 1462303 | J5: IND | K5: INDIVIDUAL | N5: GLOVER, RENEE | O5: Q | Q5: U | R5: RENEE | T5: GLOVER | V5: 553 AUBURN AVE NE | X5: ATLANTA | Y5: GA | Z5: 303121941 | AA5: THE CATALYST GROUP LLC | AB5: BUSINESS CONSULTANT | AD5: 15 | AE5: CONTRIBUTION | AI5: 44105 | AJ5: 50 | AK5: 700 | BG5: P | BI5: PRIMARY | BK5: A | BL5: ADD | BM5: ITEMIZED RECEIPTS | BN5: 44169.19 | BR5: F3X | BS5: 4.1023202e+18 | BT5: t | BV5: 2020 | BW5: SA | BY5: 4.1204202e+18 | BZ5: http://docquery.fec.gov/cgi-bin/fecimg/?202010229332830242 | CA5: Contributions From Individuals/Persons Other Than Political Committees
A6: C00147512 | B6: CONGRESSIONAL BLACK CAUCUS PAC | C6: 2020 | D6: M9 | E6: 2.020092e+17 | F6: 11AI | G6: VNW66HZB528 | H6: 1439904 | J6: IND | K6: INDIVIDUAL | N6: GLOVER, RENEE | O6: Q | Q6: U | R6: RENEE | T6: GLOVER | V6: 553 AUBURN AVE NE | X6: ATLANTA | Y6: GA | Z6: 303121941 | AA6: THE CATALYST GROUP LLC | AB6: BUSINESS CONSULTANT | AD6: 15 | AE6: CONTRIBUTION | AI6: 44046 | AJ6: 100 | AK6: 450 | BG6: P | BI6: PRIMARY | BK6: A | BL6: ADD | BM6: ITEMIZED RECEIPTS | BN6: 44106.151 | BR6: F3X | BS6: 4.0920202e+18 | BT6: t | BV6: 2020 | BW6: SA | BY6: 4.1002202e+18 | BZ6: http://docquery.fec.gov/cgi-bin/fecimg/?202009199275282560 | CA6: Contributions From Individuals/Persons Other Than Political Committees
A7: C00147512 | B7: CONGRESSIONAL BLACK CAUCUS PAC | C7: 2020 | D7: M9 | E7: 2.020092e+17 | F7: 11AI | G7: VNW66HZW9N1 | H7: 1439904 | J7: IND | K7: INDIVIDUAL | N7: GLOVER, RENEE | O7: Q | Q7: U | R7: RENEE | T7: GLOVER | V7: 553 AUBURN AVE NE | X7: ATLANTA | Y7: GA | Z7: 303121941 | AA7: THE CATALYST GROUP LLC | AB7: BUSINESS CONSULTANT | AD7: 15 | AE7: CONTRIBUTION | AI7: 44053 | AJ7: 100 | AK7: 450 | BG7: P | BI7: PRIMARY | BK7: A | BL7: ADD | BM7: ITEMIZED RECEIPTS | BN7: 44106.151 | BR7: F3X | BS7: 4.0920202e+18 | BT7: t | BV7: 2020 | BW7: SA | BY7: 4.1002202e+18 | BZ7: http://docquery.fec.gov/cgi-bin/fecimg/?202009199275282560 | CA7: Contributions From Individuals/Persons Other Than Political Committees
A8: C00147512 | B8: CONGRESSIONAL BLACK CAUCUS PAC | C8: 2020 | D8: M9 | E8: 2.020092e+17 | F8: 11AI | G8: VNW66J1BHC9 | H8: 1439904 | J8: IND | K8: INDIVIDUAL | N8: GLOVER, RENEE | O8: Q | Q8: U | R8: RENEE | T8: GLOVER | V8: 553 AUBURN AVE NE | X8: ATLANTA | Y8: GA | Z8: 303121941 | AA8: THE CATALYST GROUP LLC | AB8: BUSINESS CONSULTANT | AD8: 15 | AE8: CONTRIBUTION | AI8: 44067 | AJ8: 100 | AK8: 450 | BG8: P | BI8: PRIMARY | BK8: A | BL8: ADD | BM8: ITEMIZED RECEIPTS | BN8: 44106.151 | BR8: F3X | BS8: 4.0920202e+18 | BT8: t | BV8: 2020 | BW8: SA | BY8: 4.1002202e+18 | BZ8: http://docquery.fec.gov/cgi-bin/fecimg/?202009199275282561 | CA8: Contributions From Individuals/Persons Other Than Political Committees
A9: C00147512 | B9: CONGRESSIONAL BLACK CAUCUS PAC | C9: 2020 | D9: M10 | E9: 2.0201021e+17 | F9: 11AI | G9: VNW66J6JRY7 | H9: 1458645 | J9: IND | K9: INDIVIDUAL | N9: GLOVER, RENEE | O9: Q | Q9: U | R9: RENEE | T9: GLOVER | V9: 553 AUBURN AVE NE | X9: ATLANTA | Y9: GA | Z9: 303121941 | AA9: THE CATALYST GROUP LLC | AB9: BUSINESS CONSULTANT | AD9: 15 | AE9: CONTRIBUTION | AI9: 44095 | AJ9: 100 | AK9: 650 | BG9: P | BI9: PRIMARY | BK9: A | BL9: ADD | BM9: ITEMIZED RECEIPTS | BN9: 44170.162 | BR9: F3X | BS9: 4.1022202e+18 | BT9: t | BV9: 2020 | BW9: SA | BY9: 4.1205202e+18 | BZ9: http://docquery.fec.gov/cgi-bin/fecimg/?202010209298294278 | CA9: Contributions From Individuals/Persons Other Than Political Committees
A10: C00147512 | B10: CONGRESSIONAL BLACK CAUCUS PAC | C10: 2020 | D10: M10 | E10: 2.0201021e+17 | F10: 11AI | G10: VNW66J6JS53 | H10: 1458645 | J10: IND | K10: INDIVIDUAL | N10: GLOVER, RENEE | O10: Q | Q10: U | R10: RENEE | T10: GLOVER | V10: 553 AUBURN AVE NE | X10: ATLANTA | Y10: GA | Z10: 303121941 | AA10: THE CATALYST GROUP LLC | AB10: BUSINESS CONSULTANT | AD10: 15 | AE10: CONTRIBUTION | AI10: 44095 | AJ10: 100 | AK10: 650 | BG10: P | BI10: PRIMARY | BK10: A | BL10: ADD | BM10: ITEMIZED RECEIPTS | BN10: 44170.162 | BR10: F3X | BS10: 4.1022202e+18 | BT10: t | BV10: 2020 | BW10: SA | BY10: 4.1205202e+18 | BZ10: http://docquery.fec.gov/cgi-bin/fecimg/?202010209298294278 | CA10: Contributions From Individuals/Persons Other Than Political Committees
A11: C00042366 | B11: DSCC | C11: 2019 | D11: YE | E11: 2.0200132e+17 | F11: 11AI | G11: 13548096 | H11: 1376980 | J11: IND | K11: INDIVIDUAL | L11: C00401224 | N11: GLOVER, RENEE | O11: Y | Q11: U | R11: RENEE | T11: GLOVER | V11: 553 AUBURN AVE NE | X11: ATLANTA | Y11: GA | Z11: 303121941 | AA11: THE CATALYST GROUP LLC | AB11: BUSINESS CONSULTANT | AC11: C00401224 | AD11: 15E | AE11: EARMARKED CONTRIBUTION | AI11: 43830 | AJ11: 100 | AK11: 300 | BG11: P | BI11: PRIMARY | BK11: A | BL11: ADD | BM11: ITEMIZED RECEIPTS | BN11: 43869.071 | BP11: 13548096E | BQ11: SA11AI | BR11: F3X | BS11: 4.0131202e+18 | BT11: t | BU11: * EARMARKED CONTRIBUTION: SEE BELOW | BV11: 2020 | BW11: SA | BY11: 4.0207202e+18 | BZ11: http://docquery.fec.gov/cgi-bin/fecimg/?202001319184184886 | CA11: Contributions From Individuals/Persons Other Than Political Committees
A12: C00000935 | B12: DCCC | C12: 2020 | D12: M10 | E12: 2.0210331e+17 | F12: 11AI | G12: 31827833 | H12: 1506705 | J12: IND | K12: INDIVIDUAL | N12: GLOVER, RENEE | O12: Y | Q12: U | R12: RENEE | T12: GLOVER | V12: 553 AUBURN AVE NE | X12: ATLANTA | Y12: GA | Z12: 303121941 | AA12: THE CATALYST GROUP LLC | AB12: BUSINESS CONSULTANT | AD12: 15E | AE12: EARMARKED CONTRIBUTION | AI12: 44103 | AJ12: 125 | AK12: 1479 | BG12: P | BI12: PRIMARY | BK12: A | BL12: ADD | BM12: ITEMIZED RECEIPTS | BN12: 44292.177 | BP12: 31827833E | BQ12: SA11AI | BR12: F3X | BS12: 4.0331202e+18 | BT12: t | BU12: * EARMARKED CONTRIBUTION: SEE BELOW EARMARKED THROUGH ACTBLUE | BV12: 2020 | BW12: SA | BY12: 4.0406202e+18 | BZ12: https://docquery.fec.gov/cgi-bin/fecimg/?202103309442644757 | CA12: Contributions From Individuals/Persons Other Than Political Committees
A13: C00401224 | B13: ACTBLUE | C13: 2020 | D13: M10 | E13: 2.0201215e+17 | F13: 11AI | G13: SA11AI_302862221 | H13: 1482832 | J13: IND | K13: INDIVIDUAL | L13: C00147512 | N13: GLOVER, RENEE | O13: V | Q13: U | R13: RENEE | T13: GLOVER | V13: 553 AUBURN AVENUE NE | X13: ATLANTA | Y13: GA | Z13: 30312 | AA13: THE CATALYST GROUP, LLC | AB13: BUSINESS CONSULTANT | AC13: C00147512 | AD13: 24T | AE13: EARMARKED INTERMEDIARY TREASURY OUT | AF13: EARMARK | AI13: 44094 | AJ13: 100 | AK13: 700 | BF13: _x000D_ | BK13: A | BL13: ADD | BM13: ITEMIZED RECEIPTS | BN13: 44218.646 | BR13: F3X | BS13: 4.1216202e+18 | BT13: t | BU13: EARMARKED FOR CONGRESSIONAL BLACK CAUCUS PAC (C00147512) | BV13: 2020 | BW13: SA | BY13: 4.0121202e+18 | BZ13: https://docquery.fec.gov/cgi-bin/fecimg/?202012149376634937 | CA13: Contributions From Individuals/Persons Other Than Political Committees
A14: C00401224 | B14: ACTBLUE | C14: 2020 | D14: M10 | E14: 2.0201215e+17 | F14: 11AI | G14: SA11AI_302862367 | H14: 1482832 | J14: IND | K14: INDIVIDUAL | N14: GLOVER, RENEE | O14: V | Q14: U | R14: RENEE | T14: GLOVER | V14: 553 AUBURN AVENUE NE | X14: ATLANTA | Y14: GA | Z14: 30312 | AA14: THE CATALYST GROUP, LLC | AB14: BUSINESS CONSULTANT | AD14: 15 | AE14: CONTRIBUTION | AF14: CONTRIBUTION TO ACT BLUE | AI14: 44094 | AJ14: 10 | AK14: 1172.9 | BF14: _x000D_ | BK14: A | BL14: ADD | BM14: ITEMIZED RECEIPTS | BN14: 44218.646 | BR14: F3X | BS14: 4.1216202e+18 | BT14: t | BU14: CONTRIBUTION TO ACTBLUE | BV14: 2020 | BW14: SA | BY14: 4.0121202e+18 | BZ14: https://docquery.fec.gov/cgi-bin/fecimg/?202012149376634936 | CA14: Contributions From Individuals/Persons Other Than Political Committees
A15: C00401224 | B15: ACTBLUE | C15: 2020 | D15: M10 | E15: 2.0201215e+17 | F15: 11AI | G15: SA11AI_302861527 | H15: 1482832 | J15: IND | K15: INDIVIDUAL | N15: GLOVER, RENEE | O15: V | Q15: U | R15: RENEE | T15: GLOVER | V15: 553 AUBURN AVENUE NE | X15: ATLANTA | Y15: GA | Z15: 30312 | AA15: THE CATALYST GROUP, LLC | AB15: BUSINESS CONSULTANT | AD15: 15 | AE15: CONTRIBUTION | AF15: CONTRIBUTION TO ACT BLUE | AI15: 44094 | AJ15: 10 | AK15: 1172.9 | BF15: _x000D_ | BK15: A | BL15: ADD | BM15: ITEMIZED RECEIPTS | BN15: 44218.646 | BR15: F3X | BS15: 4.1216202e+18 | BT15: t | BU15: CONTRIBUTION TO ACTBLUE | BV15: 2020 | BW15: SA | BY15: 4.0121202e+18 | BZ15: https://docquery.fec.gov/cgi-bin/fecimg/?202012149376634936 | CA15: Contributions From Individuals/Persons Other Than Political Committees
A16: C00401224 | B16: ACTBLUE | C16: 2020 | D16: M10 | E16: 2.0201215e+17 | F16: 11AI | G16: SA11AI_298099587 | H16: 1482832 | J16: IND | K16: INDIVIDUAL | L16: C00633404 | N16: GLOVER, RENEE | O16: V | Q16: U | R16: RENEE | T16: GLOVER | V16: 553 AUBURN AVENUE NE | X16: ATLANTA | Y16: GA | Z16: 30312 | AA16: THE CATALYST GROUP, LLC | AB16: BUSINESS CONSULTANT | AC16: C00633404 | AD16: 24T | AE16: EARMARKED INTERMEDIARY TREASURY OUT | AF16: EARMARK | AI16: 44092 | AJ16: 100 | AK16: 1400 | BF16: _x000D_ | BK16: A | BL16: ADD | BM16: ITEMIZED RECEIPTS | BN16: 44218.646 | BR16: F3X | BS16: 4.1216202e+18 | BT16: t | BU16: EARMARKED FOR STOP REPUBLICANS (C00633404) | BV16: 2020 | BW16: SA | BY16: 4.0121202e+18 | BZ16: https://docquery.fec.gov/cgi-bin/fecimg/?202012149376634935 | CA16: Contributions From Individuals/Persons Other Than Political Committees
A17: C00401224 | B17: ACTBLUE | C17: 2020 | D17: M10 | E17: 2.0201215e+17 | F17: 11AI | G17: SA11AI_298100311 | H17: 1482832 | J17: IND | K17: INDIVIDUAL | N17: GLOVER, RENEE | O17: V | Q17: U | R17: RENEE | T17: GLOVER | V17: 553 AUBURN AVENUE NE | X17: ATLANTA | Y17: GA | Z17: 30312 | AA17: THE CATALYST GROUP, LLC | AB17: BUSINESS CONSULTANT | AD17: 15 | AE17: CONTRIBUTION | AF17: CONTRIBUTION TO ACT BLUE | AI17: 44092 | AJ17: 10 | AK17: 1172.9 | BF17: _x000D_ | BK17: A | BL17: ADD | BM17: ITEMIZED RECEIPTS | BN17: 44218.646 | BR17: F3X | BS17: 4.1216202e+18 | BT17: t | BU17: CONTRIBUTION TO ACTBLUE | BV17: 2020 | BW17: SA | BY17: 4.0121202e+18 | BZ17: https://docquery.fec.gov/cgi-bin/fecimg/?202012149376634934 | CA17: Contributions From Individuals/Persons Other Than Political Committees
A18: C00401224 | B18: ACTBLUE | C18: 2020 | D18: M10 | E18: 2.0201215e+17 | F18: 11AI | G18: SA11AI_298096693 | H18: 1482832 | J18: IND | K18: INDIVIDUAL | N18: GLOVER, RENEE | O18: V | Q18: U | R18: RENEE | T18: GLOVER | V18: 553 AUBURN AVENUE NE | X18: ATLANTA | Y18: GA | Z18: 30312 | AA18: THE CATALYST GROUP, LLC | AB18: BUSINESS CONSULTANT | AD18: 15 | AE18: CONTRIBUTION | AF18: CONTRIBUTION TO ACT BLUE | AI18: 44092 | AJ18: 10 | AK18: 1172.9 | BF18: _x000D_ | BK18: A | BL18: ADD | BM18: ITEMIZED RECEIPTS | BN18: 44218.646 | BR18: F3X | BS18: 4.1216202e+18 | BT18: t | BU18: CONTRIBUTION TO ACTBLUE | BV18: 2020 | BW18: SA | BY18: 4.0121202e+18 | BZ18: https://docquery.fec.gov/cgi-bin/fecimg/?202012149376634935 | CA18: Contributions From Individuals/Persons Other Than Political Committees
A19: C00401224 | B19: ACTBLUE | C19: 2020 | D19: M10 | E19: 2.0201215e+17 | F19: 11AI | G19: SA11AI_298095941 | H19: 1482832 | J19: IND | K19: INDIVIDUAL | L19: C00633404 | N19: GLOVER, RENEE | O19: V | Q19: U | R19: RENEE | T19: GLOVER | V19: 553 AUBURN AVENUE NE | X19: ATLANTA | Y19: GA | Z19: 30312 | AA19: THE CATALYST GROUP, LLC | AB19: BUSINESS CONSULTANT | AC19: C00633404 | AD19: 24T | AE19: EARMARKED INTERMEDIARY TREASURY OUT | AF19: EARMARK | AI19: 44092 | AJ19: 100 | AK19: 1400 | BF19: _x000D_ | BK19: A | BL19: ADD | BM19: ITEMIZED RECEIPTS | BN19: 44218.646 | BR19: F3X | BS19: 4.1216202e+18 | BT19: t | BU19: EARMARKED FOR STOP REPUBLICANS (C00633404) | BV19: 2020 | BW19: SA | BY19: 4.0121202e+18 | BZ19: https://docquery.fec.gov/cgi-bin/fecimg/?202012149376634934 | CA19: Contributions From Individuals/Persons Other Than Political Committees
