Workbook

Sheet Board & Executives
A1: Company | B1: Board | C1: Exec | D1: Employer | E1: Fname | F1: MI | G1: Lname | H1: Gender | I1: State | J1: Age | K1: DOB | L1: Dem | M1: Rep | N1: Neutral | O1: Reg | P1: Address
A2: FORD | B2: Y | C2: N | D2: President Kimberly Casiano & Associates, | E2: Kimberly | F2: A | G2: Casiano | H2: F | I2: Puerto Rico | J2: 63 | Q2: Kimberly A Casiano | R2: No FEC Data
A3: FORD | B3: Y | C3: N | D3: Retired Executive Chairman of the Board Director PG&E Corporation | E3: Anthony | F3: F. | G3: Earley, Jr | H3: M | J3: 71 | L3: =+GETPIVOTDATA("contribution_receipt_amount",'Anthony Earley'!$B$35) -> 15100 | P3: 3926 OAKLAND DR BLOOMFIELD HILLS MI 48301 | Q3: Anthony F. Earley, Jr
A4: FORD | B4: Y | C4: Y | D4: A Director of Corporate Strategy, Ford Motor Company | E4: Alexandra | F4: Ford | G4: English | H4: F | J4: 33 | Q4: Alexandra Ford English | R4: No FEC Data
A5: FORD | B5: Y | C5: Y | D5: President and Chief Executive Officer, Ford Motor Company | E5: James | F5: D. | G5: Farley, Jr | H5: M | J5: 58 | Q5: James D. Farley, Jr | R5: No FEC Data
A6: FORD | B6: Y | C6: Y | D6: A Director of Investor Relations, Ford Motor Company | E6: Henry | G6: Ford III | H6: M | J6: 40 | L6: =+'Henry Ford III'!B28 -> 12700 | N6: =+'Henry Ford III'!B29 -> 210 | P6: 2000 BRUSH ST DETROIT MI 482262251 | Q6: Henry Ford III
A7: FORD | B7: Y | C7: Y | D7: Executive Chairman and Chairman of the Board Ford Motor Company | E7: William | F7: Clay | G7: Ford, Jr | H7: M | J7: 63 | L7: =+'William Clay Ford'!B18 -> 500 | M7: =+'William Clay Ford'!B16 -> 20000 | N7: =+'William Clay Ford'!B17 -> 10000 | P7: 2000 BRUSH ST STE 440 DETROIT MI 482262251 | Q7: William Clay Ford, Jr
A8: FORD | B8: Y | C8: N | D8: General Partner, Greylock Partners | E8: William | F8: W. | G8: Helman IV | H8: M | J8: 62 | L8: =+GETPIVOTDATA("contribution_receipt_amount",'William Helman'!$A$10) -> 2850 | P8: 106 7TH AVE PH 12 NEW YORK NY 10011 | Q8: William W. Helman IV
A9: FORD | B9: Y | C9: N | D9: Former Chairman, Atlantic Council and Former Chairman, Huntsman Cancer Foun | E9: Jon | F9: M. | G9: Huntsman, Jr | H9: M | J9: 61 | K9: 22001 | M9: =+'Jon Huntsman'!AJ2 -> 2800 | P9: 1605 E NEW BEDFORD DR SALT LAKE CITY UT 84103 | Q9: Jon M. Huntsman, Jr
A10: FORD | B10: Y | C10: N | D10: Chairman, Velocitas Partners LLC | E10: William | F10: E | G10: . Kennard | H10: M | J10: 64 | K10: 20839 | L10: =+'William Kennard'!B15 -> 1250 | M10: =+'William Kennard'!B16 -> 5000 | P10: 41 MEETING ST CHARLESTON SC 294012736 | Q10: William E. Kennard
A11: FORD | B11: Y | C11: N | D11: Retired Chairman and Chief Executive Officer, KeyCorp | E11: Beth | F11: E. | G11: Mooney | H11: F | J11: 66 | K11: 1955 | L11: =+GETPIVOTDATA("contribution_receipt_amount",'Beth Mooney'!$A$59) -> 33813.2 | P11: 11 COLONY LN BRATENAHL OH 441081119 | Q11: Beth E. Mooney
A12: FORD | B12: Y | C12: N | D12: Executive Chairman, Barrick Gold Corporation | E12: John | F12: L. | G12: Thornton | H12: M | J12: 67 | K12: 19726 | M12: =+GETPIVOTDATA("contribution_receipt_amount",'John Thornton'!$E$136) -> 2813.14 | P12: 5108 LEWELLYN RD LAKELAND FL 338100789 | Q12: John L. Thornton
A13: FORD | B13: Y | C13: N | D13: Retired Chairman and Chief Executive Officer, KPMG, LLP and retired Chairman of KPMG International | E13: John | F13: B. | G13: Veihmeyer | H13: M | J13: 65 | K13: 21730 | Q13: John B. Veihmeyer | R13: No FEC Data
A14: FORD | B14: Y | C14: N | D14: Former Executive Vice President & Chief Marketing Officer, Salesforce | E14: Lynn | F14: M. | G14: Vojvodich | H14: F | J14: 53 | P14: San Francisco Ca? | Q14: Lynn M. Vojvodich | R14: No FEC Data
A15: FORD | B15: Y | C15: N | D15: Co-Chief Executive Officer and Co-Chairman of the Board of Directors, Evercore Partners Inc. | E15: John | F15: S. | G15: Weinberg | H15: M | J15: 64 | P15: NY CT? | Q15: John S. Weinberg | R15: No FEC Data
A16: FORD | B16: N | C16: Y | D16: Chief Financial Officer | E16: John | F16: T. | G16: Lawler | H16: M | Q16: John T. Lawler | R16: No FEC Data
A17: FORD | B17: N | C17: Y | D17: Chief Product Platform & Operations Officer | E17: Hau | G17: Thai-Tang | J17: 55 | K17: 24362 | L17: =+GETPIVOTDATA("contribution_receipt_amount",'Hau Thai-Tang'!$A$20,"committee_name","FORD MOTOR COMPANY CIVIC ACTION FUND")*'Hau Thai-Tang'!C22 -> 1726.7328 | M17: =+GETPIVOTDATA("contribution_receipt_amount",'Hau Thai-Tang'!$A$20,"committee_name","FORD MOTOR COMPANY CIVIC ACTION FUND")*'Hau Thai-Tang'!C21 -> 3265.2672 | P17: 1362 JUNIPER LN BLOOMFIELD HILLS MI 483021959 | Q17: Hau Thai-Tang
A18: FORD | B18: N | C18: Y | D18: President Americas and International Markets | E18: Ashwani | F18: ‘‘Kumar’’ | G18: Galhotra | J18: 56 | K18: 24077 | Q18: Ashwani ‘‘Kumar’’ Galhotra | R18: No FEC Data
A19: FORD | B19: N | C19: Y | D19: Former Presidernt and CEO | E19: James | F19: P. | G19: Hackett | H19: M | J19: 66 | K19: 20201 | L19: =+GETPIVOTDATA("contribution_receipt_amount",'James P. Hackett'!$A$20,"committee_name","FORD MOTOR COMPANY CIVIC ACTION FUND")*'James P. Hackett'!F21 -> 1245.24 | M19: =+GETPIVOTDATA("contribution_receipt_amount",'James P. Hackett'!$A$20,"committee_name","FORD MOTOR COMPANY CIVIC ACTION FUND")*'James P. Hackett'!D21+GETPIVOTDATA("contribution_receipt_amount",'James P. Hackett'!$A$20,"committee_name","NRCC") -> 2604.76 | P19: 1547 BRIAR CLIFF DR. SE GRAND RAPIDS MI 495469689 | Q19: James P. Hackett
A20: FORD | B20: N | C20: Y | D20: Former Chief Financial Officer | E20: Tim | G20: Stone | H20: M | L20: =+GETPIVOTDATA("contribution_receipt_amount",'Tim Stone'!$A$14,"committee_name","FORD MOTOR COMPANY CIVIC ACTION FUND")*'Tim Stone'!F15 -> 1438.944 | M20: =+GETPIVOTDATA("contribution_receipt_amount",'Tim Stone'!$A$14,"committee_name","FORD MOTOR COMPANY CIVIC ACTION FUND")*'Tim Stone'!D15 -> 2721.056 | P20: 322 JERUSALEM COHASSET MA 20251138 | Q20: Tim Stone
L22: =SUM(L2:L21) -> 70624.117 | M22: =SUM(M2:M21) -> 39204.223 | N22: =SUM(N2:N21) -> 10210

Sheet Company PAC
A1: committee_id | B1: committee_name | D1: Political Affiliation | E1: Republican | F1: Democratic | G1: Independent | H1: %Republican | I1: %Democrat
A2: C00000422 | B2: AMERICAN MEDICAL ASSOCIATION POLITICAL ACTION COMMITTEE
A3: C00000935 | B3: DCCC | D3: D
A4: C00001180 | B4: MICHIGAN DOCTORS POLITICAL ACTION COMMITTEE - MICHIGAN STATE MEDICAL SOCIETY
A5: C00001305 | B5: REPUBLICAN PARTY OF VIRGINIA INC | D5: R
A6: C00001313 | B6: REPUBLICAN PARTY OF MINNESOTA - FEDERAL | D6: R
A7: C00002840 | B7: UAW - V - CAP (UAW VOLUNTARY COMMUNITY ACTION PROGRAM)
A8: C00003111 | B8: MAINE REPUBLICAN PARTY | D8: R
A9: C00003418 | B9: REPUBLICAN NATIONAL COMMITTEE | D9: R
A10: C00003764 | B10: NATIONAL RESTAURANT ASSOCIATION PAC (RESTAURANT PAC)
A11: C00003988 | B11: NEBRASKA DEMOCRATIC PARTY | D11: D
A12: C00004606 | B12: KANSAS REPUBLICAN PARTY | D12: R
A13: C00005561 | B13: DEMOCRATIC EXECUTIVE COMMITTEE OF FLORIDA | D13: D
A14: C00005785 | B14: WYOMING REPUBLICAN PARTY, INC. | D14: R
A15: C00005926 | B15: ILLINOIS REPUBLICAN PARTY - FEDERAL | D15: R
A16: C00006486 | B16: INDIANA REPUBLICAN STATE COMMITTEE, INC. | D16: R
A17: C00008086 | B17: MONTANA REPUBLICAN STATE CENTRAL COMMITTEE | D17: R
A18: C00008227 | B18: ARIZONA REPUBLICAN PARTY | D18: R
A19: C00008664 | B19: MISSOURI REPUBLICAN STATE COMMITTEE-FEDERAL | D19: R
A20: C00010603 | B20: DNC SERVICES CORP / DEMOCRATIC NATIONAL COMMITTEE | D20: D
A21: C00011197 | B21: KENTUCKY STATE DEMOCRATIC CENTRAL EXECUTIVE COMMITTEE | D21: D
A22: C00012229 | B22: ALASKANS FOR DON YOUNG
A23: C00012880 | B23: AMERICAN PHYSICAL THERAPY ASSOCIATION PHYSICAL THERAPY POLITICAL ACTION COMMITTEE (PT-PAC)
A24: C00014498 | B24: REPUBLICAN PARTY OF IOWA | D24: R
A25: C00016899 | B25: OHIO DEMOCRATIC PARTY | D25: D
A26: C00019331 | B26: DEMOCRATIC PARTY OF WISCONSIN | D26: D
A27: C00020818 | B27: REPUBLICAN CAMPAIGN COMMITTEE OF NEW MEXICO | D27: R
A28: C00022343 | B28: INDEPENDENT INSURANCE AGENTS & BROKERS OF AMERICA, INC. POLITICAL ACTION COMMITTEE (INSURPAC)
A29: C00024521 | B29: AMERICAN ASSOCIATION FOR JUSTICE POLITICAL ACTION COMMITTEE (AAJ PAC)
A30: C00024679 | B30: VERMONT DEMOCRATIC PARTY | D30: D
A31: C00025254 | B31: MINNESOTA DEMOCRATIC-FARMER-LABOR PARTY | D31: D
A32: C00027466 | B32: NRSC | D32: R
A33: C00030718 | B33: NATIONAL ASSOCIATION OF REALTORS POLITICAL ACTION COMMITTEE
A34: C00031054 | B34: MICHIGAN DEMOCRATIC STATE CENTRAL COMMITTEE | D34: D
A35: C00032334 | B35: NEBRASKA REPUBLICAN PARTY | D35: R
A36: C00033134 | B36: COLORADO REPUBLICAN COMMITTEE | D36: R
A37: C00038505 | B37: NORTH CAROLINA REPUBLICAN PARTY | D37: R
A38: C00040857 | B38: OAKLAND COUNTY DEMOCRATIC PARTY | D38: D
A39: C00040998 | B39: NATIONAL AUTOMOBILE DEALERS ASSOCIATION POLITICAL ACTION COMMITTEE
A40: C00041160 | B40: MICHIGAN REPUBLICAN PARTY | D40: R
...

Sheet Tim Stone
A1: committee_id | B1: committee_name | C1: report_year | D1: report_type | E1: image_number | F1: line_number | G1: transaction_id | H1: file_number | I1: committee_name | J1: entity_type | K1: entity_type_desc | L1: unused_contbr_id | M1: contributor_prefix | N1: contributor_name | O1: recipient_committee_type | P1: recipient_committee_org_type | Q1: recipient_committee_designation | R1: contributor_first_name | S1: contributor_middle_name | T1: contributor_last_name | U1: contributor_suffix | V1: contributor_street_1 | W1: contributor_street_2 | X1: contributor_city | Y1: contributor_state | Z1: contributor_zip | AA1: contributor_employer | AB1: contributor_occupation | AC1: contributor_id | AD1: receipt_type | AE1: receipt_type_desc | AF1: receipt_type_full | AG1: memo_code | AH1: memo_code_full | AI1: contribution_receipt_date | AJ1: contribution_receipt_amount | AK1: contributor_aggregate_ytd | AL1: candidate_id | AM1: candidate_name | AN1: candidate_first_name | AO1: candidate_last_name | AP1: candidate_middle_name | AQ1: candidate_prefix | AR1: candidate_suffix | AS1: candidate_office | AT1: candidate_office_full | AU1: candidate_office_state | AV1: candidate_office_state_full | AW1: candidate_office_district | AX1: conduit_committee_id | AY1: conduit_committee_name | AZ1: conduit_committee_street1 | BA1: conduit_committee_street2 | BB1: conduit_committee_city | BC1: conduit_committee_state | BD1: conduit_committee_zip | BE1: donor_committee_name | BF1: national_committee_nonfederal_account | BG1: election_type | BH1: election_type_full | BI1: fec_election_type_desc | BJ1: fec_election_year | BK1: amendment_indicator | BL1: amendment_indicator_desc | BM1: schedule_type_full | BN1: load_date | BO1: original_sub_id | BP1: back_reference_transaction_id | BQ1: back_reference_schedule_name | BR1: filing_form | BS1: link_id | BT1: is_individual | BU1: memo_text | BV1: two_year_transaction_period | BW1: schedule_type | BX1: increased_limit | BY1: sub_id | BZ1: pdf_url | CA1: line_number_label
A2: C00046474 | B2: FORD MOTOR COMPANY CIVIC ACTION FUND | C2: 2019 | D2: YE | E2: 2.0200129e+17 | F2: 11AI | G2: PR929617431700 | H2: 1374056 | J2: IND | K2: INDIVIDUAL | M2: MR | N2: STONE, TIM MR | O2: Q | P2: C | Q2: B | R2: TIM | T2: STONE | V2: 2987 FRANKLIN STREET, UNIT W | X2: DETROIT | Y2: MI | Z2: 482074262 | AA2: FORD MOTOR COMPANY | AB2: EXECUTIVE VICE PRESIDENT | AD2: 15 | AE2: CONTRIBUTION | AI2: 43830 | AJ2: 416 | AK2: 1248 | BG2: P | BI2: PRIMARY | BK2: A | BL2: ADD | BM2: ITEMIZED RECEIPTS | BN2: 43859.073 | BR2: F3X | BS2: 4.0128202e+18 | BT2: t | BU2: P/R DEDUCTION ($416.00 MONTHLY) | BV2: 2020 | BW2: SA | BY2: 4.0128202e+18 | BZ2: http://docquery.fec.gov/cgi-bin/fecimg/?202001289167420499 | CA2: Contributions From Individuals/Persons Other Than Political Committees
A3: C00046474 | B3: FORD MOTOR COMPANY CIVIC ACTION FUND | C3: 2019 | D3: M12 | E3: 2.0191219e+17 | F3: 11AI | G3: PR929617431137 | H3: 1366669 | J3: IND | K3: INDIVIDUAL | M3: MR | N3: STONE, TIM MR | O3: Q | P3: C | Q3: B | R3: TIM | T3: STONE | V3: 2987 FRANKLIN STREET, UNIT W | X3: DETROIT | Y3: MI | Z3: 482074262 | AA3: FORD MOTOR COMPANY | AB3: EXECUTIVE VICE PRESIDENT | AD3: 15 | AE3: CONTRIBUTION | AI3: 43799 | AJ3: 416 | AK3: 832 | BG3: P | BI3: PRIMARY | BK3: A | BL3: ADD | BM3: ITEMIZED RECEIPTS | BN3: 43818.072 | BR3: F3X | BS3: 4.1218202e+18 | BT3: t | BU3: P/R DEDUCTION ($416.00 MONTHLY) | BV3: 2020 | BW3: SA | BY3: 4.1218202e+18 | BZ3: http://docquery.fec.gov/cgi-bin/fecimg/?201912189166359698 | CA3: Contributions From Individuals/Persons Other Than Political Committees
A4: C00046474 | B4: FORD MOTOR COMPANY CIVIC ACTION FUND | C4: 2020 | D4: M8 | E4: 2.0200815e+17 | F4: 11AI | G4: PR929617433448 | H4: 1432298 | J4: IND | K4: INDIVIDUAL | M4: MR | N4: STONE, TIM MR | O4: Q | P4: C | Q4: B | R4: TIM | T4: STONE | V4: 2987 FRANKLIN STREET, UNIT W | X4: DETROIT | Y4: MI | Z4: 482074262 | AA4: FMC US | AB4: VP, CHIEF FINANCIAL OFFICER | AD4: 15 | AE4: CONTRIBUTION | AI4: 44043 | AJ4: 416 | AK4: 2912 | BG4: P | BI4: PRIMARY | BK4: A | BL4: ADD | BM4: ITEMIZED RECEIPTS | BN4: 44065.164 | BR4: F3X | BS4: 4.0815202e+18 | BT4: t | BU4: P/R DEDUCTION ($416.00 MONTHLY) | BV4: 2020 | BW4: SA | BY4: 4.0822202e+18 | BZ4: http://docquery.fec.gov/cgi-bin/fecimg/?202008149261306926 | CA4: Contributions From Individuals/Persons Other Than Political Committees
A5: C00046474 | B5: FORD MOTOR COMPANY CIVIC ACTION FUND | C5: 2020 | D5: M2 | E5: 2.0200219e+17 | F5: 11AI | G5: PR929617431849 | H5: 1383073 | J5: IND | K5: INDIVIDUAL | M5: MR | N5: STONE, TIM MR | O5: Q | P5: C | Q5: B | R5: TIM | T5: STONE | V5: 2987 FRANKLIN STREET, UNIT W | X5: DETROIT | Y5: MI | Z5: 482074262 | AA5: FORD MOTOR COMPANY | AB5: EXECUTIVE VICE PRESIDENT | AD5: 15 | AE5: CONTRIBUTION | AI5: 43861 | AJ5: 416 | AK5: 416 | BG5: P | BI5: PRIMARY | BK5: A | BL5: ADD | BM5: ITEMIZED RECEIPTS | BN5: 43886.075 | BR5: F3X | BS5: 4.0218202e+18 | BT5: t | BU5: P/R DEDUCTION ($416.00 MONTHLY) | BV5: 2020 | BW5: SA | BY5: 4.0224202e+18 | BZ5: http://docquery.fec.gov/cgi-bin/fecimg/?202002189186515571 | CA5: Contributions From Individuals/Persons Other Than Political Committees
A6: C00046474 | B6: FORD MOTOR COMPANY CIVIC ACTION FUND | C6: 2020 | D6: M3 | E6: 2.0200319e+17 | F6: 11AI | G6: PR929617432112 | H6: 1390420 | J6: IND | K6: INDIVIDUAL | M6: MR | N6: STONE, TIM MR | O6: Q | P6: C | Q6: B | R6: TIM | T6: STONE | V6: 2987 FRANKLIN STREET, UNIT W | X6: DETROIT | Y6: MI | Z6: 482074262 | AA6: FORD MOTOR COMPANY | AB6: EXECUTIVE VICE PRESIDENT | AD6: 15 | AE6: CONTRIBUTION | AI6: 43890 | AJ6: 416 | AK6: 832 | BG6: P | BI6: PRIMARY | BK6: A | BL6: ADD | BM6: ITEMIZED RECEIPTS | BN6: 43909.096 | BR6: F3X | BS6: 4.0318202e+18 | BT6: t | BU6: P/R DEDUCTION ($416.00 MONTHLY) | BV6: 2020 | BW6: SA | BY6: 4.0318202e+18 | BZ6: http://docquery.fec.gov/cgi-bin/fecimg/?202003189203874381 | CA6: Contributions From Individuals/Persons Other Than Political Committees
A7: C00046474 | B7: FORD MOTOR COMPANY CIVIC ACTION FUND | C7: 2020 | D7: M7 | E7: 2.020071e+17 | F7: 11AI | G7: PR929617433026 | H7: 1418223 | J7: IND | K7: INDIVIDUAL | M7: MR | N7: STONE, TIM MR | O7: Q | P7: C | Q7: B | R7: TIM | T7: STONE | V7: 2987 FRANKLIN STREET, UNIT W | X7: DETROIT | Y7: MI | Z7: 482074262 | AA7: FMC US | AB7: CHIEF FINANCIAL OFFICER | AD7: 15 | AE7: CONTRIBUTION | AI7: 44012 | AJ7: 416 | AK7: 2496 | BG7: P | BI7: PRIMARY | BK7: A | BL7: ADD | BM7: ITEMIZED RECEIPTS | BN7: 44023.088 | BR7: F3X | BS7: 4.0709202e+18 | BT7: t | BU7: P/R DEDUCTION ($416.00 MONTHLY) | BV7: 2020 | BW7: SA | BY7: 4.0710202e+18 | BZ7: http://docquery.fec.gov/cgi-bin/fecimg/?202007099244394670 | CA7: Contributions From Individuals/Persons Other Than Political Committees
A8: C00046474 | B8: FORD MOTOR COMPANY CIVIC ACTION FUND | C8: 2020 | D8: M6 | E8: 2.020071e+17 | F8: 11AI | G8: PR929617432739 | H8: 1418185 | J8: IND | K8: INDIVIDUAL | M8: MR | N8: STONE, TIM MR | O8: Q | P8: C | Q8: B | R8: TIM | T8: STONE | V8: 2987 FRANKLIN STREET, UNIT W | X8: DETROIT | Y8: MI | Z8: 482074262 | AA8: FMC US | AB8: CHIEF FINANCIAL OFFICER | AD8: 15 | AE8: CONTRIBUTION | AI8: 43982 | AJ8: 416 | AK8: 2080 | BG8: P | BI8: PRIMARY | BK8: A | BL8: ADD | BM8: ITEMIZED RECEIPTS | BN8: 44024.093 | BR8: F3X | BS8: 4.0709202e+18 | BT8: t | BU8: P/R DEDUCTION ($416.00 MONTHLY) | BV8: 2020 | BW8: SA | BY8: 4.0711202e+18 | BZ8: http://docquery.fec.gov/cgi-bin/fecimg/?202007099244393517 | CA8: Contributions From Individuals/Persons Other Than Political Committees
A9: C00046474 | B9: FORD MOTOR COMPANY CIVIC ACTION FUND | C9: 2020 | D9: M9 | E9: 2.0200918e+17 | F9: 11AI | G9: PR929617433701 | H9: 1438561 | J9: IND | K9: INDIVIDUAL | M9: MR | N9: STONE, TIM MR | O9: Q | P9: C | Q9: B | R9: TIM | T9: STONE | V9: 322 JERUSALEM | X9: COHASSET | Y9: MA | Z9: 20251138 | AA9: FMC US | AB9: VP, CHIEF FINANCIAL OFFICER | AD9: 15 | AE9: CONTRIBUTION | AI9: 44074 | AJ9: 416 | AK9: 3328 | BG9: P | BI9: PRIMARY | BK9: A | BL9: ADD | BM9: ITEMIZED RECEIPTS | BN9: 44092.152 | BR9: F3X | BS9: 4.0918202e+18 | BT9: t | BU9: P/R DEDUCTION ($416.00 MONTHLY) | BV9: 2020 | BW9: SA | BY9: 4.0918202e+18 | BZ9: http://docquery.fec.gov/cgi-bin/fecimg/?202009179267222529 | CA9: Contributions From Individuals/Persons Other Than Political Committees
A10: C00046474 | B10: FORD MOTOR COMPANY CIVIC ACTION FUND | C10: 2020 | D10: 12G | E10: 2.0201022e+17 | F10: 11AI | G10: PR929617434207 | H10: 1459687 | J10: IND | K10: INDIVIDUAL | M10: MR | N10: STONE, TIM MR | O10: Q | P10: C | Q10: B | R10: TIM | T10: STONE | V10: 322 JERUSALEM | X10: COHASSET | Y10: MA | Z10: 20251138 | AA10: FORD MOTOR COMPANY | AB10: EXECUTIVE VICE PRESIDENT | AD10: 15 | AE10: CONTRIBUTION | AI10: 44118 | AJ10: 416 | AK10: 4160 | BG10: P | BI10: PRIMARY | BK10: A | BL10: ADD | BM10: ITEMIZED RECEIPTS | BN10: 44168.152 | BR10: F3X | BS10: 4.1022202e+18 | BT10: t | BU10: P/R DEDUCTION ($416.00 MONTHLY) | BV10: 2020 | BW10: SA | BY10: 4.1203202e+18 | BZ10: http://docquery.fec.gov/cgi-bin/fecimg/?202010219326755919 | CA10: Contributions From Individuals/Persons Other Than Political Committees
A11: C00046474 | B11: FORD MOTOR COMPANY CIVIC ACTION FUND | C11: 2020 | D11: M10 | E11: 2.020102e+17 | F11: 11AI | G11: PR929617434128 | H11: 1456209 | J11: IND | K11: INDIVIDUAL | M11: MR | N11: STONE, TIM MR | O11: Q | P11: C | Q11: B | R11: TIM | T11: STONE | V11: 322 JERUSALEM | X11: COHASSET | Y11: MA | Z11: 20251138 | AA11: FMC US | AB11: EXECUTIVE VICE PRESIDENT | AD11: 15 | AE11: CONTRIBUTION | AI11: 44104 | AJ11: 416 | AK11: 3744 | BG11: P | BI11: PRIMARY | BK11: A | BL11: ADD | BM11: ITEMIZED RECEIPTS | BN11: 44161.158 | BR11: F3X | BS11: 4.1020202e+18 | BT11: t | BU11: P/R DEDUCTION ($416.00 MONTHLY) | BV11: 2020 | BW11: SA | BY11: 4.1126202e+18 | BZ11: http://docquery.fec.gov/cgi-bin/fecimg/?202010199297279890 | CA11: Contributions From Individuals/Persons Other Than Political Committees
V13: =+V11&X11&Y11&Z11 -> 322 JERUSALEMCOHASSETMA20251138
A14: Row Labels | B14: Sum of contribution_receipt_amount
A15: FORD MOTOR COMPANY CIVIC ACTION FUND | B15: 4160 | D15: 0.6541 | E15: R | F15: =1-D15 -> 0.3459 | G15: D
A16: Grand Total | B16: 4160

Sheet James P. Hackett
A1: committee_id | B1: committee_name | C1: report_year | D1: report_type | E1: image_number | F1: line_number | G1: transaction_id | H1: file_number | I1: committee_name | J1: entity_type | K1: entity_type_desc | L1: unused_contbr_id | M1: contributor_prefix | N1: contributor_name | O1: recipient_committee_type | P1: recipient_committee_org_type | Q1: recipient_committee_designation | R1: contributor_first_name | S1: contributor_middle_name | T1: contributor_last_name | U1: contributor_suffix | V1: contributor_street_1 | W1: contributor_street_2 | X1: contributor_city | Y1: contributor_state | Z1: contributor_zip | AA1: contributor_employer | AB1: contributor_occupation | AC1: contributor_id | AD1: receipt_type | AE1: receipt_type_desc | AF1: receipt_type_full | AG1: memo_code | AH1: memo_code_full | AI1: contribution_receipt_date | AJ1: contribution_receipt_amount | AK1: contributor_aggregate_ytd | AL1: candidate_id | AM1: candidate_name | AN1: candidate_first_name | AO1: candidate_last_name | AP1: candidate_middle_name | AQ1: candidate_prefix | AR1: candidate_suffix | AS1: candidate_office | AT1: candidate_office_full | AU1: candidate_office_state | AV1: candidate_office_state_full | AW1: candidate_office_district | AX1: conduit_committee_id | AY1: conduit_committee_name | AZ1: conduit_committee_street1 | BA1: conduit_committee_street2 | BB1: conduit_committee_city | BC1: conduit_committee_state | BD1: conduit_committee_zip | BE1: donor_committee_name | BF1: national_committee_nonfederal_account | BG1: election_type | BH1: election_type_full | BI1: fec_election_type_desc | BJ1: fec_election_year | BK1: amendment_indicator | BL1: amendment_indicator_desc | BM1: schedule_type_full | BN1: load_date | BO1: original_sub_id | BP1: back_reference_transaction_id | BQ1: back_reference_schedule_name | BR1: filing_form | BS1: link_id | BT1: is_individual | BU1: memo_text | BV1: two_year_transaction_period | BW1: schedule_type | BX1: increased_limit | BY1: sub_id | BZ1: pdf_url | CA1: line_number_label
A2: C00046474 | B2: FORD MOTOR COMPANY CIVIC ACTION FUND | C2: 2019 | D2: YE | E2: 2.0200129e+17 | F2: 11AI | G2: PR868935031700 | H2: 1374056 | J2: IND | K2: INDIVIDUAL | N2: HACKETT, JAMES P | O2: Q | P2: C | Q2: B | R2: JAMES P | T2: HACKETT | V2: 1547 BRIARCLIFF DR. SE | X2: GRAND RAPIDS | Y2: MI | Z2: 495469689 | AA2: FORD MOTOR COMPANY | AB2: PRESIDENT & CEO | AD2: 15 | AE2: CONTRIBUTION | AI2: 43830 | AJ2: 300 | AK2: 3600 | BG2: P | BI2: PRIMARY | BK2: A | BL2: ADD | BM2: ITEMIZED RECEIPTS | BN2: 43859.073 | BR2: F3X | BS2: 4.0128202e+18 | BT2: t | BU2: P/R DEDUCTION ($300.00 MONTHLY) | BV2: 2020 | BW2: SA | BY2: 4.0128202e+18 | BZ2: http://docquery.fec.gov/cgi-bin/fecimg/?202001289167420483 | CA2: Contributions From Individuals/Persons Other Than Political Committees
A3: C00046474 | B3: FORD MOTOR COMPANY CIVIC ACTION FUND | C3: 2019 | D3: M12 | E3: 2.0191219e+17 | F3: 11AI | G3: PR868935031137 | H3: 1366669 | J3: IND | K3: INDIVIDUAL | N3: HACKETT, JAMES P | O3: Q | P3: C | Q3: B | R3: JAMES | S3: P | T3: HACKETT | V3: 1547 BRIARCLIFF DR. SE | X3: GRAND RAPIDS | Y3: MI | Z3: 495469689 | AA3: FORD MOTOR COMPANY | AB3: PRESIDENT & CEO | AD3: 15 | AE3: CONTRIBUTION | AI3: 43799 | AJ3: 300 | AK3: 3300 | BG3: P | BI3: PRIMARY | BK3: A | BL3: ADD | BM3: ITEMIZED RECEIPTS | BN3: 43818.072 | BR3: F3X | BS3: 4.1218202e+18 | BT3: t | BU3: P/R DEDUCTION ($300.00 MONTHLY) | BV3: 2020 | BW3: SA | BY3: 4.1218202e+18 | BZ3: http://docquery.fec.gov/cgi-bin/fecimg/?201912189166359682 | CA3: Contributions From Individuals/Persons Other Than Political Committees
A4: C00046474 | B4: FORD MOTOR COMPANY CIVIC ACTION FUND | C4: 2020 | D4: M8 | E4: 2.0200815e+17 | F4: 11AI | G4: PR868935033448 | H4: 1432298 | J4: IND | K4: INDIVIDUAL | N4: HACKETT, JAMES P | O4: Q | P4: C | Q4: B | R4: JAMES | S4: P | T4: HACKETT | V4: 1547 BRIARCLIFF DR. SE | X4: GRAND RAPIDS | Y4: MI | Z4: 495469689 | AA4: FMC US | AB4: PRESIDENT & CEO | AD4: 15 | AE4: CONTRIBUTION | AI4: 44043 | AJ4: 300 | AK4: 2100 | BG4: P | BI4: PRIMARY | BK4: A | BL4: ADD | BM4: ITEMIZED RECEIPTS | BN4: 44065.164 | BR4: F3X | BS4: 4.0815202e+18 | BT4: t | BU4: P/R DEDUCTION ($300.00 MONTHLY) | BV4: 2020 | BW4: SA | BY4: 4.0822202e+18 | BZ4: http://docquery.fec.gov/cgi-bin/fecimg/?202008149261306911 | CA4: Contributions From Individuals/Persons Other Than Political Committees
A5: C00046474 | B5: FORD MOTOR COMPANY CIVIC ACTION FUND | C5: 2020 | D5: M2 | E5: 2.0200219e+17 | F5: 11AI | G5: PR868935031849 | H5: 1383073 | J5: IND | K5: INDIVIDUAL | N5: HACKETT, JAMES P | O5: Q | P5: C | Q5: B | R5: JAMES P | T5: HACKETT | V5: 1547 BRIARCLIFF DR. SE | X5: GRAND RAPIDS | Y5: MI | Z5: 495469689 | AA5: FORD MOTOR COMPANY | AB5: PRESIDENT & CEO | AD5: 15 | AE5: CONTRIBUTION | AI5: 43861 | AJ5: 300 | AK5: 300 | BG5: P | BI5: PRIMARY | BK5: A | BL5: ADD | BM5: ITEMIZED RECEIPTS | BN5: 43886.075 | BR5: F3X | BS5: 4.0218202e+18 | BT5: t | BU5: P/R DEDUCTION ($300.00 MONTHLY) | BV5: 2020 | BW5: SA | BY5: 4.0224202e+18 | BZ5: http://docquery.fec.gov/cgi-bin/fecimg/?202002189186515568 | CA5: Contributions From Individuals/Persons Other Than Political Committees
A6: C00046474 | B6: FORD MOTOR COMPANY CIVIC ACTION FUND | C6: 2020 | D6: YE | E6: 2.0210116e+17 | F6: 11AI | G6: PR868935035156 | H6: 1488043 | J6: IND | K6: INDIVIDUAL | N6: HACKETT, JAMES P | O6: Q | P6: C | Q6: B | R6: JAMES | S6: P | T6: HACKETT | V6: 1547 BRIARCLIFF DR. SE | X6: GRAND RAPIDS | Y6: MI | Z6: 495469689 | AA6: FMC US | AB6: ADVISOR TO THE OCCE | AD6: 15 | AE6: CONTRIBUTION | AI6: 44196 | AJ6: 300 | AK6: 3600 | BG6: P | BI6: PRIMARY | BK6: A | BL6: ADD | BM6: ITEMIZED RECEIPTS | BN6: 44212.068 | BR6: F3X | BS6: 4.0115202e+18 | BT6: t | BU6: P/R DEDUCTION ($300.00 MONTHLY) | BV6: 2020 | BW6: SA | BY6: 4.0115202e+18 | BZ6: https://docquery.fec.gov/cgi-bin/fecimg/?202101159404713089 | CA6: Contributions From Individuals/Persons Other Than Political Committees
A7: C00046474 | B7: FORD MOTOR COMPANY CIVIC ACTION FUND | C7: 2020 | D7: M3 | E7: 2.0200319e+17 | F7: 11AI | G7: PR868935032112 | H7: 1390420 | J7: IND | K7: INDIVIDUAL | N7: HACKETT, JAMES P | O7: Q | P7: C | Q7: B | R7: JAMES | S7: P | T7: HACKETT | V7: 1547 BRIARCLIFF DR. SE | X7: GRAND RAPIDS | Y7: MI | Z7: 495469689 | AA7: FORD MOTOR COMPANY | AB7: PRESIDENT & CEO | AD7: 15 | AE7: CONTRIBUTION | AI7: 43890 | AJ7: 300 | AK7: 600 | BG7: P | BI7: PRIMARY | BK7: A | BL7: ADD | BM7: ITEMIZED RECEIPTS | BN7: 43909.096 | BR7: F3X | BS7: 4.0318202e+18 | BT7: t | BU7: P/R DEDUCTION ($300.00 MONTHLY) | BV7: 2020 | BW7: SA | BY7: 4.0318202e+18 | BZ7: http://docquery.fec.gov/cgi-bin/fecimg/?202003189203874378 | CA7: Contributions From Individuals/Persons Other Than Political Committees
A8: C00046474 | B8: FORD MOTOR COMPANY CIVIC ACTION FUND | C8: 2020 | D8: M7 | E8: 2.020071e+17 | F8: 11AI | G8: PR868935033026 | H8: 1418223 | J8: IND | K8: INDIVIDUAL | N8: HACKETT, JAMES P | O8: Q | P8: C | Q8: B | R8: JAMES | S8: P | T8: HACKETT | V8: 1547 BRIARCLIFF DR. SE | X8: GRAND RAPIDS | Y8: MI | Z8: 495469689 | AA8: FMC US | AB8: PRESIDENT & CEO | AD8: 15 | AE8: CONTRIBUTION | AI8: 44012 | AJ8: 300 | AK8: 1800 | BG8: P | BI8: PRIMARY | BK8: A | BL8: ADD | BM8: ITEMIZED RECEIPTS | BN8: 44023.088 | BR8: F3X | BS8: 4.0709202e+18 | BT8: t | BU8: P/R DEDUCTION ($300.00 MONTHLY) | BV8: 2020 | BW8: SA | BY8: 4.0710202e+18 | BZ8: http://docquery.fec.gov/cgi-bin/fecimg/?202007099244394662 | CA8: Contributions From Individuals/Persons Other Than Political Committees
A9: C00046474 | B9: FORD MOTOR COMPANY CIVIC ACTION FUND | C9: 2020 | D9: M6 | E9: 2.020071e+17 | F9: 11AI | G9: PR868935032739 | H9: 1418185 | J9: IND | K9: INDIVIDUAL | N9: HACKETT, JAMES P | O9: Q | P9: C | Q9: B | R9: JAMES | S9: P | T9: HACKETT | V9: 1547 BRIARCLIFF DR. SE | X9: GRAND RAPIDS | Y9: MI | Z9: 495469689 | AA9: FMC US | AB9: PRESIDENT & CEO | AD9: 15 | AE9: CONTRIBUTION | AI9: 43982 | AJ9: 300 | AK9: 1500 | BG9: P | BI9: PRIMARY | BK9: A | BL9: ADD | BM9: ITEMIZED RECEIPTS | BN9: 44024.093 | BR9: F3X | BS9: 4.0709202e+18 | BT9: t | BU9: P/R DEDUCTION ($300.00 MONTHLY) | BV9: 2020 | BW9: SA | BY9: 4.0711202e+18 | BZ9: http://docquery.fec.gov/cgi-bin/fecimg/?202007099244393510 | CA9: Contributions From Individuals/Persons Other Than Political Committees
A10: C00046474 | B10: FORD MOTOR COMPANY CIVIC ACTION FUND | C10: 2020 | D10: M9 | E10: 2.0200918e+17 | F10: 11AI | G10: PR868935033701 | H10: 1438561 | J10: IND | K10: INDIVIDUAL | N10: HACKETT, JAMES P | O10: Q | P10: C | Q10: B | R10: JAMES | S10: P | T10: HACKETT | V10: 1547 BRIARCLIFF DR. SE | X10: GRAND RAPIDS | Y10: MI | Z10: 495469689 | AA10: FMC US | AB10: PRESIDENT & CEO | AD10: 15 | AE10: CONTRIBUTION | AI10: 44074 | AJ10: 300 | AK10: 2400 | BG10: P | BI10: PRIMARY | BK10: A | BL10: ADD | BM10: ITEMIZED RECEIPTS | BN10: 44092.152 | BR10: F3X | BS10: 4.0918202e+18 | BT10: t | BU10: P/R DEDUCTION ($300.00 MONTHLY) | BV10: 2020 | BW10: SA | BY10: 4.0918202e+18 | BZ10: http://docquery.fec.gov/cgi-bin/fecimg/?202009179267222512 | CA10: Contributions From Individuals/Persons Other Than Political Committees
A11: C00046474 | B11: FORD MOTOR COMPANY CIVIC ACTION FUND | C11: 2020 | D11: 12G | E11: 2.0201022e+17 | F11: 11AI | G11: PR868935034207 | H11: 1459687 | J11: IND | K11: INDIVIDUAL | N11: HACKETT, JAMES P | O11: Q | P11: C | Q11: B | R11: JAMES | S11: P | T11: HACKETT | V11: 1547 BRIARCLIFF DR. SE | X11: GRAND RAPIDS | Y11: MI | Z11: 495469689 | AA11: FORD MOTOR COMPANY | AB11: PRESIDENT & CEO | AD11: 15 | AE11: CONTRIBUTION | AI11: 44118 | AJ11: 300 | AK11: 3000 | BG11: P | BI11: PRIMARY | BK11: A | BL11: ADD | BM11: ITEMIZED RECEIPTS | BN11: 44168.152 | BR11: F3X | BS11: 4.1022202e+18 | BT11: t | BU11: P/R DEDUCTION ($300.00 MONTHLY) | BV11: 2020 | BW11: SA | BY11: 4.1203202e+18 | BZ11: http://docquery.fec.gov/cgi-bin/fecimg/?202010219326755902 | CA11: Contributions From Individuals/Persons Other Than Political Committees
A12: C00075820 | B12: NRCC | C12: 2020 | D12: YE | E12: 2.0210132e+17 | F12: 11AI | G12: SA11A.21390027 | H12: 1496211 | J12: IND | K12: INDIVIDUAL | N12: HACKETT, JAMES P. | O12: Y | Q12: U | R12: JAMES | S12: P. | T12: HACKETT | V12: 8455 S HERITAGE CT | X12: OAK CREEK | Y12: WI | Z12: 531543242 | AD12: 15 | AE12: CONTRIBUTION | AF12: CONTRIBUTION | AI12: 44174 | AJ12: 250 | AK12: 250 | BG12: P | BI12: PRIMARY | BK12: A | BL12: ADD | BM12: ITEMIZED RECEIPTS | BN12: 44231.449 | BR12: F3X | BS12: 4.0201202e+18 | BT12: t | BV12: 2020 | BW12: SA | BY12: 4.0203202e+18 | BZ12: https://docquery.fec.gov/cgi-bin/fecimg/?202101319418519386 | CA12: Contributions From Individuals/Persons Other Than Political Committees
A13: C00046474 | B13: FORD MOTOR COMPANY CIVIC ACTION FUND | C13: 2020 | D13: M10 | E13: 2.020102e+17 | F13: 11AI | G13: PR868935034128 | H13: 1456209 | J13: IND | K13: INDIVIDUAL | N13: HACKETT, JAMES P | O13: Q | P13: C | Q13: B | R13: JAMES | S13: P | T13: HACKETT | V13: 1547 BRIARCLIFF DR. SE | X13: GRAND RAPIDS | Y13: MI | Z13: 495469689 | AA13: FMC US | AB13: ADVISOR TO THE OCCE | AD13: 15 | AE13: CONTRIBUTION | AI13: 44104 | AJ13: 300 | AK13: 2700 | BG13: P | BI13: PRIMARY | BK13: A | BL13: ADD | BM13: ITEMIZED RECEIPTS | BN13: 44161.158 | BR13: F3X | BS13: 4.1020202e+18 | BT13: t | BU13: P/R DEDUCTION ($300.00 MONTHLY) | BV13: 2020 | BW13: SA | BY13: 4.1126202e+18 | BZ13: http://docquery.fec.gov/cgi-bin/fecimg/?202010199297279875 | CA13: Contributions From Individuals/Persons Other Than Political Committees
A14: C00046474 | B14: FORD MOTOR COMPANY CIVIC ACTION FUND | C14: 2020 | D14: 30G | E14: 2.0201202e+17 | F14: 11AI | G14: PR868935034585 | H14: 1475097 | J14: IND | K14: INDIVIDUAL | N14: HACKETT, JAMES P P | O14: Q | P14: C | Q14: B | R14: JAMES P | S14: P | T14: HACKETT | V14: 1547 BRIARCLIFF DR. SE | X14: GRAND RAPIDS | Y14: MI | Z14: 495469689 | AA14: FORD MOTOR COMPANY | AB14: PRESIDENT & CEO | AD14: 15 | AE14: CONTRIBUTION | AI14: 44158 | AJ14: 300 | AK14: 3300 | BG14: P | BI14: PRIMARY | BK14: A | BL14: ADD | BM14: ITEMIZED RECEIPTS | BN14: 44177.155 | BR14: F3X | BS14: 4.1202202e+18 | BT14: t | BU14: P/R DEDUCTION ($300.00 MONTHLY) | BV14: 2020 | BW14: SA | BY14: 4.1212202e+18 | BZ14: http://docquery.fec.gov/cgi-bin/fecimg/?202012019337235406 | CA14: Contributions From Individuals/Persons Other Than Political Committees
V17: =+V14&X14&Y14&Z14 -> 1547 BRIARCLIFF DR. SEGRAND RAPIDSMI495469689
A20: Row Labels | B20: Sum of contribution_receipt_amount
A21: FORD MOTOR COMPANY CIVIC ACTION FUND | B21: 3600 | D21: 0.6541 | E21: R | F21: =1-D21 -> 0.3459 | G21: D
A22: NRCC | B22: 250 | C22: R
A23: Grand Total | B23: 3850

Sheet Hau Thai-Tang
A1: committee_id | B1: committee_name | C1: report_year | D1: report_type | E1: image_number | F1: line_number | G1: transaction_id | H1: file_number | I1: committee_name | J1: entity_type | K1: entity_type_desc | L1: unused_contbr_id | M1: contributor_prefix | N1: contributor_name | O1: recipient_committee_type | P1: recipient_committee_org_type | Q1: recipient_committee_designation | R1: contributor_first_name | S1: contributor_middle_name | T1: contributor_last_name | U1: contributor_suffix | V1: contributor_street_1 | W1: contributor_street_2 | X1: contributor_city | Y1: contributor_state | Z1: contributor_zip | AA1: contributor_employer | AB1: contributor_occupation | AC1: contributor_id | AD1: receipt_type | AE1: receipt_type_desc | AF1: receipt_type_full | AG1: memo_code | AH1: memo_code_full | AI1: contribution_receipt_date | AJ1: contribution_receipt_amount | AK1: contributor_aggregate_ytd | AL1: candidate_id | AM1: candidate_name | AN1: candidate_first_name | AO1: candidate_last_name | AP1: candidate_middle_name | AQ1: candidate_prefix | AR1: candidate_suffix | AS1: candidate_office | AT1: candidate_office_full | AU1: candidate_office_state | AV1: candidate_office_state_full | AW1: candidate_office_district | AX1: conduit_committee_id | AY1: conduit_committee_name | AZ1: conduit_committee_street1 | BA1: conduit_committee_street2 | BB1: conduit_committee_city | BC1: conduit_committee_state | BD1: conduit_committee_zip | BE1: donor_committee_name | BF1: national_committee_nonfederal_account | BG1: election_type | BH1: election_type_full | BI1: fec_election_type_desc | BJ1: fec_election_year | BK1: amendment_indicator | BL1: amendment_indicator_desc | BM1: schedule_type_full | BN1: load_date | BO1: original_sub_id | BP1: back_reference_transaction_id | BQ1: back_reference_schedule_name | BR1: filing_form | BS1: link_id | BT1: is_individual | BU1: memo_text | BV1: two_year_transaction_period | BW1: schedule_type | BX1: increased_limit | BY1: sub_id | BZ1: pdf_url | CA1: line_number_label
A2: C00046474 | B2: FORD MOTOR COMPANY CIVIC ACTION FUND | C2: 2019 | D2: YE | E2: 2.0200129e+17 | F2: 11AI | G2: PR209587231700 | H2: 1374056 | J2: IND | K2: INDIVIDUAL | M2: MR | N2: THAI-TANG, HAU N MR | O2: Q | P2: C | Q2: B | R2: HAU N | T2: THAI-TANG | V2: 1362 JUNIPER LN | X2: BLOOMFIELD HILLS | Y2: MI | Z2: 483021959 | AA2: FORD MOTOR COMPANY | AB2: EXECUTIVE VICE PRESIDENT | AD2: 15 | AE2: CONTRIBUTION | AI2: 43830 | AJ2: 416 | AK2: 4992 | BG2: P | BI2: PRIMARY | BK2: A | BL2: ADD | BM2: ITEMIZED RECEIPTS | BN2: 43859.073 | BR2: F3X | BS2: 4.0128202e+18 | BT2: t | BU2: P/R DEDUCTION ($416.00 MONTHLY) | BV2: 2020 | BW2: SA | BY2: 4.0128202e+18 | BZ2: http://docquery.fec.gov/cgi-bin/fecimg/?202001289167420168 | CA2: Contributions From Individuals/Persons Other Than Political Committees
A3: C00046474 | B3: FORD MOTOR COMPANY CIVIC ACTION FUND | C3: 2019 | D3: M12 | E3: 2.0191219e+17 | F3: 11AI | G3: PR209587231137 | H3: 1366669 | J3: IND | K3: INDIVIDUAL | M3: MR | N3: THAI-TANG, HAU N MR | O3: Q | P3: C | Q3: B | R3: HAU | S3: N | T3: THAI-TANG | V3: 1362 JUNIPER LN | X3: BLOOMFIELD HILLS | Y3: MI | Z3: 483021959 | AA3: FORD MOTOR COMPANY | AB3: EXECUTIVE VICE PRESIDENT | AD3: 15 | AE3: CONTRIBUTION | AI3: 43799 | AJ3: 416 | AK3: 4576 | BG3: P | BI3: PRIMARY | BK3: A | BL3: ADD | BM3: ITEMIZED RECEIPTS | BN3: 43818.072 | BR3: F3X | BS3: 4.1218202e+18 | BT3: t | BU3: P/R DEDUCTION ($416.00 MONTHLY) | BV3: 2020 | BW3: SA | BY3: 4.1218202e+18 | BZ3: http://docquery.fec.gov/cgi-bin/fecimg/?201912189166359367 | CA3: Contributions From Individuals/Persons Other Than Political Committees
A4: C00046474 | B4: FORD MOTOR COMPANY CIVIC ACTION FUND | C4: 2020 | D4: M8 | E4: 2.0200815e+17 | F4: 11AI | G4: PR209587233448 | H4: 1432298 | J4: IND | K4: INDIVIDUAL | M4: MR | N4: THAI-TANG, HAU N MR | O4: Q | P4: C | Q4: B | R4: HAU | S4: N | T4: THAI-TANG | V4: 1362 JUNIPER LN | X4: BLOOMFIELD HILLS | Y4: MI | Z4: 483021959 | AA4: FMC US | AB4: CHIEF PD & PURCHASING OFFICER | AD4: 15 | AE4: CONTRIBUTION | AI4: 44043 | AJ4: 416 | AK4: 2912 | BG4: P | BI4: PRIMARY | BK4: A | BL4: ADD | BM4: ITEMIZED RECEIPTS | BN4: 44065.164 | BR4: F3X | BS4: 4.0815202e+18 | BT4: t | BU4: P/R DEDUCTION ($416.00 MONTHLY) | BV4: 2020 | BW4: SA | BY4: 4.0822202e+18 | BZ4: http://docquery.fec.gov/cgi-bin/fecimg/?202008149261306646 | CA4: Contributions From Individuals/Persons Other Than Political Committees
A5: C00046474 | B5: FORD MOTOR COMPANY CIVIC ACTION FUND | C5: 2020 | D5: M2 | E5: 2.0200219e+17 | F5: 11AI | G5: PR209587231849 | H5: 1383073 | J5: IND | K5: INDIVIDUAL | M5: MR | N5: THAI-TANG, HAU N MR | O5: Q | P5: C | Q5: B | R5: HAU N | T5: THAI-TANG | V5: 1362 JUNIPER LN | X5: BLOOMFIELD HILLS | Y5: MI | Z5: 483021959 | AA5: FORD MOTOR COMPANY | AB5: EXECUTIVE VICE PRESIDENT | AD5: 15 | AE5: CONTRIBUTION | AI5: 43861 | AJ5: 416 | AK5: 416 | BG5: P | BI5: PRIMARY | BK5: A | BL5: ADD | BM5: ITEMIZED RECEIPTS | BN5: 43886.075 | BR5: F3X | BS5: 4.0218202e+18 | BT5: t | BU5: P/R DEDUCTION ($416.00 MONTHLY) | BV5: 2020 | BW5: SA | BY5: 4.0224202e+18 | BZ5: http://docquery.fec.gov/cgi-bin/fecimg/?202002189186515551 | CA5: Contributions From Individuals/Persons Other Than Political Committees
A6: C00046474 | B6: FORD MOTOR COMPANY CIVIC ACTION FUND | C6: 2020 | D6: YE | E6: 2.0210116e+17 | F6: 11AI | G6: PR209587235156 | H6: 1488043 | J6: IND | K6: INDIVIDUAL | M6: MR | N6: THAI-TANG, HAU N MR | O6: Q | P6: C | Q6: B | R6: HAU | S6: N | T6: THAI-TANG | V6: 1362 JUNIPER LN | X6: BLOOMFIELD HILLS | Y6: MI | Z6: 483021959 | AA6: FMC US | AB6: CHIEF PRODUCT PLATFORM & OPS | AD6: 15 | AE6: CONTRIBUTION | AI6: 44196 | AJ6: 416 | AK6: 4992 | BG6: P | BI6: PRIMARY | BK6: A | BL6: ADD | BM6: ITEMIZED RECEIPTS | BN6: 44212.068 | BR6: F3X | BS6: 4.0115202e+18 | BT6: t | BU6: P/R DEDUCTION ($416.00 MONTHLY) | BV6: 2020 | BW6: SA | BY6: 4.0115202e+18 | BZ6: https://docquery.fec.gov/cgi-bin/fecimg/?202101159404712797 | CA6: Contributions From Individuals/Persons Other Than Political Committees
A7: C00046474 | B7: FORD MOTOR COMPANY CIVIC ACTION FUND | C7: 2020 | D7: M3 | E7: 2.0200319e+17 | F7: 11AI | G7: PR209587232112 | H7: 1390420 | J7: IND | K7: INDIVIDUAL | M7: MR | N7: THAI-TANG, HAU N MR | O7: Q | P7: C | Q7: B | R7: HAU | S7: N | T7: THAI-TANG | V7: 1362 JUNIPER LN | X7: BLOOMFIELD HILLS | Y7: MI | Z7: 483021959 | AA7: FORD MOTOR COMPANY | AB7: EXECUTIVE VICE PRESIDENT | AD7: 15 | AE7: CONTRIBUTION | AI7: 43890 | AJ7: 416 | AK7: 832 | BG7: P | BI7: PRIMARY | BK7: A | BL7: ADD | BM7: ITEMIZED RECEIPTS | BN7: 43909.096 | BR7: F3X | BS7: 4.0318202e+18 | BT7: t | BU7: P/R DEDUCTION ($416.00 MONTHLY) | BV7: 2020 | BW7: SA | BY7: 4.0318202e+18 | BZ7: http://docquery.fec.gov/cgi-bin/fecimg/?202003189203874360 | CA7: Contributions From Individuals/Persons Other Than Political Committees
A8: C00046474 | B8: FORD MOTOR COMPANY CIVIC ACTION FUND | C8: 2020 | D8: M7 | E8: 2.020071e+17 | F8: 11AI | G8: PR209587233026 | H8: 1418223 | J8: IND | K8: INDIVIDUAL | M8: MR | N8: THAI-TANG, HAU N MR | O8: Q | P8: C | Q8: B | R8: HAU | S8: N | T8: THAI-TANG | V8: 1362 JUNIPER LN | X8: BLOOMFIELD HILLS | Y8: MI | Z8: 483021959 | AA8: FMC US | AB8: CHIEF PD & PURCHASING OFFICER | AD8: 15 | AE8: CONTRIBUTION | AI8: 44012 | AJ8: 416 | AK8: 2496 | BG8: P | BI8: PRIMARY | BK8: A | BL8: ADD | BM8: ITEMIZED RECEIPTS | BN8: 44023.088 | BR8: F3X | BS8: 4.0709202e+18 | BT8: t | BU8: P/R DEDUCTION ($416.00 MONTHLY) | BV8: 2020 | BW8: SA | BY8: 4.0710202e+18 | BZ8: http://docquery.fec.gov/cgi-bin/fecimg/?202007099244394512 | CA8: Contributions From Individuals/Persons Other Than Political Committees
A9: C00046474 | B9: FORD MOTOR COMPANY CIVIC ACTION FUND | C9: 2020 | D9: M6 | E9: 2.020071e+17 | F9: 11AI | G9: PR209587232739 | H9: 1418185 | J9: IND | K9: INDIVIDUAL | M9: MR | N9: THAI-TANG, HAU N MR | O9: Q | P9: C | Q9: B | R9: HAU | S9: N | T9: THAI-TANG | V9: 1362 JUNIPER LN | X9: BLOOMFIELD HILLS | Y9: MI | Z9: 483021959 | AA9: FMC US | AB9: CHIEF PD & PURCHASING OFFICER | AD9: 15 | AE9: CONTRIBUTION | AI9: 43982 | AJ9: 416 | AK9: 2080 | BG9: P | BI9: PRIMARY | BK9: A | BL9: ADD | BM9: ITEMIZED RECEIPTS | BN9: 44024.093 | BR9: F3X | BS9: 4.0709202e+18 | BT9: t | BU9: P/R DEDUCTION ($416.00 MONTHLY) | BV9: 2020 | BW9: SA | BY9: 4.0711202e+18 | BZ9: http://docquery.fec.gov/cgi-bin/fecimg/?202007099244393363 | CA9: Contributions From Individuals/Persons Other Than Political Committees
A10: C00046474 | B10: FORD MOTOR COMPANY CIVIC ACTION FUND | C10: 2020 | D10: M9 | E10: 2.0200918e+17 | F10: 11AI | G10: PR209587233701 | H10: 1438561 | J10: IND | K10: INDIVIDUAL | M10: MR | N10: THAI-TANG, HAU N MR | O10: Q | P10: C | Q10: B | R10: HAU | S10: N | T10: THAI-TANG | V10: 1362 JUNIPER LN | X10: BLOOMFIELD HILLS | Y10: MI | Z10: 483021959 | AA10: FMC US | AB10: CHIEF PD & PURCHASING OFFICER | AD10: 15 | AE10: CONTRIBUTION | AI10: 44074 | AJ10: 416 | AK10: 3328 | BG10: P | BI10: PRIMARY | BK10: A | BL10: ADD | BM10: ITEMIZED RECEIPTS | BN10: 44092.152 | BR10: F3X | BS10: 4.0918202e+18 | BT10: t | BU10: P/R DEDUCTION ($416.00 MONTHLY) | BV10: 2020 | BW10: SA | BY10: 4.0918202e+18 | BZ10: http://docquery.fec.gov/cgi-bin/fecimg/?202009179267222246 | CA10: Contributions From Individuals/Persons Other Than Political Committees
A11: C00046474 | B11: FORD MOTOR COMPANY CIVIC ACTION FUND | C11: 2020 | D11: 12G | E11: 2.0201022e+17 | F11: 11AI | G11: PR209587234207 | H11: 1459687 | J11: IND | K11: INDIVIDUAL | M11: MR | N11: THAI-TANG, HAU N MR | O11: Q | P11: C | Q11: B | R11: HAU | S11: N | T11: THAI-TANG | V11: 1362 JUNIPER LN | X11: BLOOMFIELD HILLS | Y11: MI | Z11: 483021959 | AA11: FORD MOTOR COMPANY | AB11: EXECUTIVE VICE PRESIDENT | AD11: 15 | AE11: CONTRIBUTION | AI11: 44118 | AJ11: 416 | AK11: 4160 | BG11: P | BI11: PRIMARY | BK11: A | BL11: ADD | BM11: ITEMIZED RECEIPTS | BN11: 44168.152 | BR11: F3X | BS11: 4.1022202e+18 | BT11: t | BU11: P/R DEDUCTION ($416.00 MONTHLY) | BV11: 2020 | BW11: SA | BY11: 4.1203202e+18 | BZ11: http://docquery.fec.gov/cgi-bin/fecimg/?202010219326755627 | CA11: Contributions From Individuals/Persons Other Than Political Committees
A12: C00046474 | B12: FORD MOTOR COMPANY CIVIC ACTION FUND | C12: 2020 | D12: M10 | E12: 2.020102e+17 | F12: 11AI | G12: PR209587234128 | H12: 1456209 | J12: IND | K12: INDIVIDUAL | M12: MR | N12: THAI-TANG, HAU N MR | O12: Q | P12: C | Q12: B | R12: HAU | S12: N | T12: THAI-TANG | V12: 1362 JUNIPER LN | X12: BLOOMFIELD HILLS | Y12: MI | Z12: 483021959 | AA12: FMC US | AB12: CHIEF PD & PURCHASING OFFICER | AD12: 15 | AE12: CONTRIBUTION | AI12: 44104 | AJ12: 416 | AK12: 3744 | BG12: P | BI12: PRIMARY | BK12: A | BL12: ADD | BM12: ITEMIZED RECEIPTS | BN12: 44161.158 | BR12: F3X | BS12: 4.1020202e+18 | BT12: t | BU12: P/R DEDUCTION ($416.00 MONTHLY) | BV12: 2020 | BW12: SA | BY12: 4.1126202e+18 | BZ12: http://docquery.fec.gov/cgi-bin/fecimg/?202010199297279613 | CA12: Contributions From Individuals/Persons Other Than Political Committees
A13: C00046474 | B13: FORD MOTOR COMPANY CIVIC ACTION FUND | C13: 2020 | D13: 30G | E13: 2.0201202e+17 | F13: 11AI | G13: PR209587234585 | H13: 1475097 | J13: IND | K13: INDIVIDUAL | M13: MR | N13: THAI-TANG, HAU N N MR | O13: Q | P13: C | Q13: B | R13: HAU N | S13: N | T13: THAI-TANG | V13: 1362 JUNIPER LN | X13: BLOOMFIELD HILLS | Y13: MI | Z13: 483021959 | AA13: FORD MOTOR COMPANY | AB13: EXECUTIVE VICE PRESIDENT | AD13: 15 | AE13: CONTRIBUTION | AI13: 44158 | AJ13: 416 | AK13: 4576 | BG13: P | BI13: PRIMARY | BK13: A | BL13: ADD | BM13: ITEMIZED RECEIPTS | BN13: 44177.155 | BR13: F3X | BS13: 4.1202202e+18 | BT13: t | BU13: P/R DEDUCTION ($416.00 MONTHLY) | BV13: 2020 | BW13: SA | BY13: 4.1212202e+18 | BZ13: http://docquery.fec.gov/cgi-bin/fecimg/?202012019337235101 | CA13: Contributions From Individuals/Persons Other Than Political Committees
V16: =+V13&X13&Y13&Z13 -> 1362 JUNIPER LNBLOOMFIELD HILLSMI483021959
A20: Row Labels | B20: Sum of contribution_receipt_amount
A21: FORD MOTOR COMPANY CIVIC ACTION FUND | B21: 4992 | C21: 0.6541 | D21: R
A22: Grand Total | B22: 4992 | C22: =1-C21 -> 0.3459 | D22: D

Sheet John Thornton
A1: committee_id | B1: committee_name | C1: report_year | D1: report_type | E1: image_number | F1: line_number | G1: transaction_id | H1: file_number | I1: committee_name | J1: entity_type | K1: entity_type_desc | L1: unused_contbr_id | M1: contributor_prefix | N1: contributor_name | O1: recipient_committee_type | P1: recipient_committee_org_type | Q1: recipient_committee_designation | R1: contributor_first_name | S1: contributor_middle_name | T1: contributor_last_name | U1: contributor_suffix | V1: contributor_street_1 | W1: contributor_street_2 | X1: contributor_city | Y1: contributor_state | Z1: contributor_zip | AA1: contributor_employer | AB1: contributor_occupation | AC1: contributor_id | AD1: receipt_type | AE1: receipt_type_desc | AF1: receipt_type_full | AG1: memo_code | AH1: memo_code_full | AI1: contribution_receipt_date | AJ1: contribution_receipt_amount | AK1: contributor_aggregate_ytd | AL1: candidate_id | AM1: candidate_name | AN1: candidate_first_name | AO1: candidate_last_name | AP1: candidate_middle_name | AQ1: candidate_prefix | AR1: candidate_suffix | AS1: candidate_office | AT1: candidate_office_full | AU1: candidate_office_state | AV1: candidate_office_state_full | AW1: candidate_office_district | AX1: conduit_committee_id | AY1: conduit_committee_name | AZ1: conduit_committee_street1 | BA1: conduit_committee_street2 | BB1: conduit_committee_city | BC1: conduit_committee_state | BD1: conduit_committee_zip | BE1: donor_committee_name | BF1: national_committee_nonfederal_account | BG1: election_type | BH1: election_type_full | BI1: fec_election_type_desc | BJ1: fec_election_year | BK1: amendment_indicator | BL1: amendment_indicator_desc | BM1: schedule_type_full | BN1: load_date | BO1: original_sub_id | BP1: back_reference_transaction_id | BQ1: back_reference_schedule_name | BR1: filing_form | BS1: link_id | BT1: is_individual | BU1: memo_text | BV1: two_year_transaction_period | BW1: schedule_type | BX1: increased_limit | BY1: sub_id | BZ1: pdf_url | CA1: line_number_label
A2: C00760124 | B2: NATIONAL VICTORY ACTION FUND | C2: 2020 | D2: YE | E2: 2.0210311e+17 | F2: 11AI | G2: A483E631E09D9431E981 | H2: 1503618 | J2: IND | K2: INDIVIDUAL | N2: THORNTON, JOHN | O2: V | Q2: U | R2: JOHN | T2: THORNTON | V2: 5108 LEWELLYN ROAD | X2: LAKELAND | Y2: FL | Z2: 33810 | AA2: RETIRED | AB2: RETIRED | AF2: CONTRIBUTION | AI2: 44166 | AJ2: 50 | AK2: 75 | BK2: A | BL2: ADD | BM2: ITEMIZED RECEIPTS | BN2: 44270.15 | BR2: F3X | BS2: 4.0311202e+18 | BT2: t | BV2: 2020 | BW2: SA | BY2: 4.0315202e+18 | BZ2: https://docquery.fec.gov/cgi-bin/fecimg/?202103109440432720 | CA2: Contributions From Individuals/Persons Other Than Political Committees
A3: C00618371 | B3: TRUMP MAKE AMERICA GREAT AGAIN COMMITTEE | C3: 2020 | D3: Q3 | E3: 2.021021e+17 | F3: 11AI | G3: SA11AI.1582602 | H3: 1499308 | J3: IND | K3: INDIVIDUAL | N3: THORNTON, ,, JOHN | O3: N | Q3: J | R3: JOHN | T3: THORNTON, , | V3: 5108 LEWELLYN RD | X3: LAKELAND | Y3: FL | Z3: 33810 | AA3: RETIRED | AB3: RETIRED | AF3: EARMARKED THROUGH WINRED [SA11AI.4498] | AI3: 44016 | AJ3: 42 | AK3: 42 | BK3: A | BL3: ADD | BM3: ITEMIZED RECEIPTS | BN3: 44249.164 | BR3: F3X | BS3: 4.0211202e+18 | BT3: t | BV3: 2020 | BW3: SA | BY3: 4.0222202e+18 | BZ3: https://docquery.fec.gov/cgi-bin/fecimg/?202102099427616884 | CA3: Contributions From Individuals/Persons Other Than Political Committees
A4: C00618371 | B4: TRUMP MAKE AMERICA GREAT AGAIN COMMITTEE | C4: 2020 | D4: Q3 | E4: 2.021021e+17 | F4: 11AI | G4: SA11AI.1582603 | H4: 1499308 | J4: IND | K4: INDIVIDUAL | N4: THORNTON, ,, JOHN | O4: N | Q4: J | R4: JOHN | T4: THORNTON, , | V4: 5108 LEWELLYN RD | X4: LAKELAND | Y4: FL | Z4: 33810 | AA4: RETIRED | AB4: RETIRED | AF4: EARMARKED THROUGH WINRED [SA11AI.4499] | AI4: 44019 | AJ4: 35 | AK4: 77 | BK4: A | BL4: ADD | BM4: ITEMIZED RECEIPTS | BN4: 44249.164 | BR4: F3X | BS4: 4.0211202e+18 | BT4: t | BV4: 2020 | BW4: SA | BY4: 4.0222202e+18 | BZ4: https://docquery.fec.gov/cgi-bin/fecimg/?202102099427616884 | CA4: Contributions From Individuals/Persons Other Than Political Committees
A5: C00618371 | B5: TRUMP MAKE AMERICA GREAT AGAIN COMMITTEE | C5: 2020 | D5: Q3 | E5: 2.021021e+17 | F5: 11AI | G5: SA11AI.1582604 | H5: 1499308 | J5: IND | K5: INDIVIDUAL | N5: THORNTON, ,, JOHN | O5: N | Q5: J | R5: JOHN | T5: THORNTON, , | V5: 5108 LEWELLYN RD | X5: LAKELAND | Y5: FL | Z5: 33810 | AA5: RETIRED | AB5: RETIRED | AF5: EARMARKED THROUGH WINRED [SA11AI.4504] | AI5: 44026 | AJ5: 42 | AK5: 119 | BK5: A | BL5: ADD | BM5: ITEMIZED RECEIPTS | BN5: 44249.164 | BR5: F3X | BS5: 4.0211202e+18 | BT5: t | BV5: 2020 | BW5: SA | BY5: 4.0222202e+18 | BZ5: https://docquery.fec.gov/cgi-bin/fecimg/?202102099427616885 | CA5: Contributions From Individuals/Persons Other Than Political Committees
A6: C00618371 | B6: TRUMP MAKE AMERICA GREAT AGAIN COMMITTEE | C6: 2020 | D6: Q3 | E6: 2.021021e+17 | F6: 11AI | G6: SA11AI.1582599 | H6: 1499308 | J6: IND | K6: INDIVIDUAL | N6: THORNTON, ,, JOHN | O6: N | Q6: J | R6: JOHN | T6: THORNTON, , | V6: 5108 LEWELLYN RD | X6: LAKELAND | Y6: FL | Z6: 33810 | AA6: RETIRED | AB6: RETIRED | AF6: EARMARKED THROUGH WINRED [SA11A1.4523] | AI6: 44047 | AJ6: 42 | AK6: 161 | BK6: A | BL6: ADD | BM6: ITEMIZED RECEIPTS | BN6: 44249.164 | BR6: F3X | BS6: 4.0211202e+18 | BT6: t | BV6: 2020 | BW6: SA | BY6: 4.0222202e+18 | BZ6: https://docquery.fec.gov/cgi-bin/fecimg/?202102099427616885 | CA6: Contributions From Individuals/Persons Other Than Political Committees
A7: C00618371 | B7: TRUMP MAKE AMERICA GREAT AGAIN COMMITTEE | C7: 2020 | D7: Q3 | E7: 2.021021e+17 | F7: 11AI | G7: SA11AI.1582600 | H7: 1499308 | J7: IND | K7: INDIVIDUAL | N7: THORNTON, ,, JOHN | O7: N | Q7: J | R7: JOHN | T7: THORNTON, , | V7: 5108 LEWELLYN RD | X7: LAKELAND | Y7: FL | Z7: 33810 | AA7: RETIRED | AB7: RETIRED | AD7: 15E | AE7: EARMARKED CONTRIBUTION | AF7: EARMARKED THROUGH WINRED [SA11A1.4540] | AI7: 44078 | AJ7: 42 | AK7: 203 | BG7: P | BI7: PRIMARY | BK7: A | BL7: ADD | BM7: ITEMIZED RECEIPTS | BN7: 44249.164 | BR7: F3X | BS7: 4.0211202e+18 | BT7: t | BV7: 2020 | BW7: SA | BY7: 4.0222202e+18 | BZ7: https://docquery.fec.gov/cgi-bin/fecimg/?202102099427616885 | CA7: Contributions From Individuals/Persons Other Than Political Committees
A8: C00694323 | B8: WINRED | C8: 2020 | D8: Q3 | E8: 2.0210126e+17 | F8: 11AI | G8: A3FB0320EE7914840B4B | H8: 1490496 | J8: IND | K8: INDIVIDUAL | L8: C00491357 | N8: THORNTON, JOHN | O8: V | Q8: U | R8: JOHN | T8: THORNTON | V8: 5108 LEWELLYN RD | X8: LAKELAND | Y8: FL | Z8: 338100789 | AA8: RETIRED | AB8: RETIRED | AC8: C00491357 | AD8: 15E | AE8: EARMARKED CONTRIBUTION | AF8: EARMARKED FOR STEVE DAINES FOR MONTANA (C00491357) | AI8: 44078 | AJ8: 10 | AK8: 1097.76 | AL8: S2MT00096 | BK8: A | BL8: ADD | BM8: ITEMIZED RECEIPTS | BN8: 44252.57 | BR8: F3X | BS8: 4.0125202e+18 | BT8: t | BV8: 2020 | BW8: SA | BY8: 4.0224202e+18 | BZ8: https://docquery.fec.gov/cgi-bin/fecimg/?202101259407874977 | CA8: Contributions From Individuals/Persons Other Than Political Committees
A9: C00618371 | B9: TRUMP MAKE AMERICA GREAT AGAIN COMMITTEE | C9: 2020 | D9: Q3 | E9: 2.021021e+17 | F9: 11AI | G9: SA11AI.1582601 | H9: 1499308 | J9: IND | K9: INDIVIDUAL | N9: THORNTON, ,, JOHN | O9: N | Q9: J | R9: JOHN | T9: THORNTON, , | V9: 5108 LEWELLYN RD | X9: LAKELAND | Y9: FL | Z9: 33810 | AA9: RETIRED | AB9: RETIRED | AD9: 15E | AE9: EARMARKED CONTRIBUTION | AF9: EARMARKED THROUGH WINRED [SA11A1.4552] | AI9: 44097 | AJ9: 10 | AK9: 213 | BG9: P | BI9: PRIMARY | BK9: A | BL9: ADD | BM9: ITEMIZED RECEIPTS | BN9: 44249.164 | BR9: F3X | BS9: 4.0211202e+18 | BT9: t | BV9: 2020 | BW9: SA | BY9: 4.0222202e+18 | BZ9: https://docquery.fec.gov/cgi-bin/fecimg/?202102099427616886 | CA9: Contributions From Individuals/Persons Other Than Political Committees
A10: C00694323 | B10: WINRED | C10: 2020 | D10: Q3 | E10: 2.0210126e+17 | F10: 11AI | G10: AF6F8E7866BAB4671B11 | H10: 1490496 | J10: IND | K10: INDIVIDUAL | L10: C00458828 | N10: THORNTON, JOHN | O10: V | Q10: U | R10: JOHN | T10: THORNTON | V10: 5108 LEWELLYN RD | X10: LAKELAND | Y10: FL | Z10: 338100789 | AA10: RETIRED | AB10: RETIRED | AC10: C00458828 | AD10: 15E | AE10: EARMARKED CONTRIBUTION | AF10: EARMARKED FOR TEAM GRAHAM, INC. (C00458828) | AI10: 44095 | AJ10: 10 | AK10: 1177.76 | AL10: S0SC00149 | BK10: A | BL10: ADD | BM10: ITEMIZED RECEIPTS | BN10: 44252.579 | BR10: F3X | BS10: 4.0125202e+18 | BT10: t | BV10: 2020 | BW10: SA | BY10: 4.0224202e+18 | BZ10: https://docquery.fec.gov/cgi-bin/fecimg/?202101259408605706 | CA10: Contributions From Individuals/Persons Other Than Political Committees
A11: C00694323 | B11: WINRED | C11: 2020 | D11: Q3 | E11: 2.0210126e+17 | F11: 11AI | G11: A3F98367D591F4264B1A | H11: 1490496 | J11: IND | K11: INDIVIDUAL | L11: C00705236 | N11: THORNTON, JOHN | O11: V | Q11: U | R11: JOHN | T11: THORNTON | V11: 5108 LEWELLYN RD | X11: LAKELAND | Y11: FL | Z11: 338100789 | AA11: RETIRED | AB11: RETIRED | AC11: C00705236 | AD11: 15E | AE11: EARMARKED CONTRIBUTION | AF11: EARMARKED FOR JOE COLLINS FOR CONGRESS (C00705236) | AI11: 44104 | AJ11: 10 | AK11: 1312.76 | AL11: H0CA43108 | BK11: A | BL11: ADD | BM11: ITEMIZED RECEIPTS | BN11: 44252.572 | BR11: F3X | BS11: 4.0125202e+18 | BT11: t | BV11: 2020 | BW11: SA | BY11: 4.0224202e+18 | BZ11: https://docquery.fec.gov/cgi-bin/fecimg/?202101259409207202 | CA11: Contributions From Individuals/Persons Other Than Political Committees
A12: C00694323 | B12: WINRED | C12: 2020 | D12: Q3 | E12: 2.0210126e+17 | F12: 11AI | G12: A32BED74D3B85487DA14 | H12: 1490496 | J12: IND | K12: INDIVIDUAL | L12: C00711689 | N12: THORNTON, JOHN | O12: V | Q12: U | R12: JOHN | T12: THORNTON | V12: 5108 LEWELLYN RD | X12: LAKELAND | Y12: FL | Z12: 338100789 | AA12: RETIRED | AB12: RETIRED | AC12: C00711689 | AD12: 15E | AE12: EARMARKED CONTRIBUTION | AF12: EARMARKED FOR LACY JOHNSON FOR CONGRESS (C00711689) | AI12: 44052 | AJ12: 15 | AK12: 868 | AL12: H0MN05178 | BK12: A | BL12: ADD | BM12: ITEMIZED RECEIPTS | BN12: 44252.575 | BR12: F3X | BS12: 4.0125202e+18 | BT12: t | BV12: 2020 | BW12: SA | BY12: 4.0224202e+18 | BZ12: https://docquery.fec.gov/cgi-bin/fecimg/?202101259406737909 | CA12: Contributions From Individuals/Persons Other Than Political Committees
A13: C00694323 | B13: WINRED | C13: 2020 | D13: Q3 | E13: 2.0210126e+17 | F13: 11AI | G13: A416D250CCD364110B11 | H13: 1490496 | J13: IND | K13: INDIVIDUAL | L13: C00666040 | N13: THORNTON, JOHN | O13: V | Q13: U | R13: JOHN | T13: THORNTON | V13: 5108 LEWELLYN RD | X13: LAKELAND | Y13: FL | Z13: 338100789 | AA13: RETIRED | AB13: RETIRED | AC13: C00666040 | AD13: 15E | AE13: EARMARKED CONTRIBUTION | AF13: EARMARKED FOR MCSALLY FOR SENATE INC (C00666040) | AI13: 44102 | AJ13: 10 | AK13: 1292.76 | AL13: S8AZ00221 | BK13: A | BL13: ADD | BM13: ITEMIZED RECEIPTS | BN13: 44252.572 | BR13: F3X | BS13: 4.0125202e+18 | BT13: t | BV13: 2020 | BW13: SA | BY13: 4.0224202e+18 | BZ13: https://docquery.fec.gov/cgi-bin/fecimg/?202101259409014897 | CA13: Contributions From Individuals/Persons Other Than Political Committees
A14: C00694323 | B14: WINRED | C14: 2020 | D14: Q3 | E14: 2.0210126e+17 | F14: 11AI | G14: A5E31552C130546A5B14 | H14: 1490496 | J14: IND | K14: INDIVIDUAL | L14: C00711689 | N14: THORNTON, JOHN | O14: V | Q14: U | R14: JOHN | T14: THORNTON | V14: 5108 LEWELLYN RD | X14: LAKELAND | Y14: FL | Z14: 338100789 | AA14: RETIRED | AB14: RETIRED | AC14: C00711689 | AD14: 15E | AE14: EARMARKED CONTRIBUTION | AF14: EARMARKED FOR LACY JOHNSON FOR CONGRESS (C00711689) | AI14: 44057 | AJ14: 5 | AK14: 920.76 | AL14: H0MN05178 | BK14: A | BL14: ADD | BM14: ITEMIZED RECEIPTS | BN14: 44252.575 | BR14: F3X | BS14: 4.0125202e+18 | BT14: t | BV14: 2020 | BW14: SA | BY14: 4.0224202e+18 | BZ14: https://docquery.fec.gov/cgi-bin/fecimg/?202101259406914136 | CA14: Contributions From Individuals/Persons Other Than Political Committees
A15: C00694323 | B15: WINRED | C15: 2020 | D15: Q3 | E15: 2.0210126e+17 | F15: 11AI | G15: AF735D59B56964034AFC | H15: 1490496 | J15: IND | K15: INDIVIDUAL | L15: C00618371 | N15: THORNTON, JOHN | O15: V | Q15: U | R15: JOHN | T15: THORNTON | V15: 5108 LEWELLYN RD | X15: LAKELAND | Y15: FL | Z15: 338100789 | AA15: RETIRED | AB15: RETIRED | AC15: C00618371 | AD15: 15E | AE15: EARMARKED CONTRIBUTION | AF15: EARMARKED FOR TRUMP MAKE AMERICA GREAT AGAIN COMMITTEE (C00618371) | AI15: 44026 | AJ15: 42 | AK15: 766 | BK15: A | BL15: ADD | BM15: ITEMIZED RECEIPTS | BN15: 44252.579 | BR15: F3X | BS15: 4.0125202e+18 | BT15: t | BV15: 2020 | BW15: SA | BY15: 4.0224202e+18 | BZ15: https://docquery.fec.gov/cgi-bin/fecimg/?202101259405823117 | CA15: Contributions From Individuals/Persons Other Than Political Committees
A16: C00694323 | B16: WINRED | C16: 2020 | D16: Q3 | E16: 2.0210126e+17 | F16: 11AI | G16: AF6ED570C08314B20B7A | H16: 1490496 | J16: IND | K16: INDIVIDUAL | L16: C00504530 | N16: THORNTON, JOHN | O16: V | Q16: U | R16: JOHN | T16: THORNTON | V16: 5108 LEWELLYN RD | X16: LAKELAND | Y16: FL | Z16: 338100789 | AA16: RETIRED | AB16: RETIRED | AC16: C00504530 | AD16: 15E | AE16: EARMARKED CONTRIBUTION | AF16: EARMARKED FOR CONGRESSIONAL LEADERSHIP FUND (C00504530) | AI16: 44067 | AJ16: 5 | AK16: 970.76 | BK16: A | BL16: ADD | BM16: ITEMIZED RECEIPTS | BN16: 44252.579 | BR16: F3X | BS16: 4.0125202e+18 | BT16: t | BV16: 2020 | BW16: SA | BY16: 4.0224202e+18 | BZ16: https://docquery.fec.gov/cgi-bin/fecimg/?202101259407302643 | CA16: Contributions From Individuals/Persons Other Than Political Committees
A17: C00694323 | B17: WINRED | C17: 2020 | D17: Q3 | E17: 2.0210126e+17 | F17: 11AI | G17: AED598872614C4CC0AB1 | H17: 1490496 | J17: IND | K17: INDIVIDUAL | L17: C00716860 | N17: THORNTON, JOHN | O17: V | Q17: U | R17: JOHN | T17: THORNTON | V17: 5108 LEWELLYN RD | X17: LAKELAND | Y17: FL | Z17: 338100789 | AA17: RETIRED | AB17: RETIRED | AC17: C00716860 | AD17: 15E | AE17: EARMARKED CONTRIBUTION | AF17: EARMARKED FOR JASON LEWIS FOR SENATE (C00716860) | AI17: 44098 | AJ17: 10 | AK17: 1237.76 | AL17: S0MN00328 | BK17: A | BL17: ADD | BM17: ITEMIZED RECEIPTS | BN17: 44252.58 | BR17: F3X | BS17: 4.0125202e+18 | BT17: t | BV17: 2020 | BW17: SA | BY17: 4.0224202e+18 | BZ17: https://docquery.fec.gov/cgi-bin/fecimg/?202101259408783306 | CA17: Contributions From Individuals/Persons Other Than Political Committees
A18: C00694323 | B18: WINRED | C18: 2020 | D18: Q3 | E18: 2.0210126e+17 | F18: 11AI | G18: AADE5DD626A98460CA4E | H18: 1490496 | J18: IND | K18: INDIVIDUAL | L18: C00711689 | N18: THORNTON, JOHN | O18: V | Q18: U | R18: JOHN | T18: THORNTON | V18: 5108 LEWELLYN RD | X18: LAKELAND | Y18: FL | Z18: 338100789 | AA18: RETIRED | AB18: RETIRED | AC18: C00711689 | AD18: 15E | AE18: EARMARKED CONTRIBUTION | AF18: EARMARKED FOR LACY JOHNSON FOR CONGRESS (C00711689) | AI18: 44078 | AJ18: 5 | AK18: 1097.76 | AL18: H0MN05178 | BK18: A | BL18: ADD | BM18: ITEMIZED RECEIPTS | BN18: 44252.58 | BR18: F3X | BS18: 4.0125202e+18 | BT18: t | BV18: 2020 | BW18: SA | BY18: 4.0224202e+18 | BZ18: https://docquery.fec.gov/cgi-bin/fecimg/?202101259407877839 | CA18: Contributions From Individuals/Persons Other Than Political Committees
A19: C00694323 | B19: WINRED | C19: 2020 | D19: Q3 | E19: 2.0210126e+17 | F19: 11AI | G19: AEBD490F0598641188F7 | H19: 1490496 | J19: IND | K19: INDIVIDUAL | L19: C00725853 | N19: THORNTON, JOHN | O19: V | Q19: U | R19: JOHN | T19: THORNTON | V19: 5108 LEWELLYN RD | X19: LAKELAND | Y19: FL | Z19: 338100789 | AA19: RETIRED | AB19: RETIRED | AC19: C00725853 | AD19: 15E | AE19: EARMARKED CONTRIBUTION | AF19: EARMARKED FOR BURGESS 4 UTAH (C00725853) | AI19: 44067 | AJ19: 5 | AK19: 970.76 | AL19: H0UT04076 | BK19: A | BL19: ADD | BM19: ITEMIZED RECEIPTS | BN19: 44252.582 | BR19: F3X | BS19: 4.0125202e+18 | BT19: t | BV19: 2020 | BW19: SA | BY19: 4.0224202e+18 | BZ19: https://docquery.fec.gov/cgi-bin/fecimg/?202101259407297005 | CA19: Contributions From Individuals/Persons Other Than Political Committees
